Workbook

Sheet 0_Instrucciones
A1: Indicador de Operatividad I+D — Medición Quincenal
A3: OBJETIVO
A4: Medir la operatividad de cada responsable del departamento I+D (Innovación y Diseño) cada quincena,
A5: usando fechas de inicio/finalización y el nivel de prioridad de cada operación.
A7: CÓMO ACTUALIZAR (enfoque auto-renovable)
A8: 1) Abra la hoja 1_Datos.
A9: 2) Borre solo las filas de datos (no borre la fila 1 de encabezados).
A10: 3) Pegue las operaciones actuales desde KPIS I+D.xlsx (mismas columnas o mapee a estas).
A11: 4) En 2_Parametros elija Año, Mes y Quincena a evaluar (1 = días 1-15; 2 = días 16-fin).
A12: 5) Las hojas 3_Calc, 4_KPI_Responsables y 5_Ranking se actualizan solas con fórmulas Excel.
A14: COLUMNAS REQUERIDAS EN 1_Datos
A15: ID | Operacion | Responsable | Fecha_Inicio | Fecha_Finalizacion | Prioridad | Estado | Area | Observaciones
... A31: Cumple ≥ Meta IOI (default 85%) | Riesgo entre Umbral y Meta | Critico < Umbral (default 70%).

Sheet 1_Datos
A1: PEGUE AQUÍ LOS DATOS RENOVADOS DE KPIS I+D (no modifique los encabezados)
A2: ID | B2: Operacion | C2: Responsable | D2: Fecha_Inicio | E2: Fecha_Finalizacion | F2: Prioridad | G2: Estado | H2: Area | I2: Observaciones
A3: OP-001 | B3: Operación I+D #1 | C3: Ana Pérez | D3: 46204 | E3: 46217 | F3: Baja | G3: Completada | H3: Validación | I3: Dato demo — reemplazar con KPIS I+D.xlsx
A4: OP-002 | B4: Operación I+D #2 | C4: Luis Gómez | D4: 46206 | E4: 46214 | F4: Media | G4: Completada | H4: Prototipo | I4: Dato demo — reemplazar con KPIS I+D.xlsx
A5: OP-003 | B5: Operación I+D #3 | C5: María Ruiz | D5: 46208 | F5: Alta | G5: En proceso | H5: Innovación | I5: Dato demo — reemplazar con KPIS I+D.xlsx
A6: OP-004 | B6: Operación I+D #4 | C6: Carlos Díaz | D6: 46210 | F6: Baja | G6: Pendiente | H6: Diseño | I6: Dato demo — reemplazar con KPIS I+D.xlsx
A7: OP-005 | B7: Operación I+D #5 | C7: Sofía Vargas | D7: 46212 | E7: 46220 | F7: Media | G7: Completada | H7: Validación | I7: Dato demo — reemplazar con KPIS I+D.xlsx
A8: OP-006 | B8: Operación I+D #6 | C8: Ana Pérez | D8: 46214 | E8: 46218 | F8: Alta | G8: Completada | H8: Prototipo | I8: Dato demo — reemplazar con KPIS I+D.xlsx
A9: OP-007 | B9: Operación I+D #7 | C9: Luis Gómez | D9: 46216 | E9: 46229 | F9: Baja | G9: Completada | H9: Innovación | I9: Dato demo — reemplazar con KPIS I+D.xlsx
A10: OP-008 | B10: Operación I+D #8 | C10: María Ruiz | D10: 46218 | F10: Media | G10: En proceso | H10: Diseño | I10: Dato demo — reemplazar con KPIS I+D.xlsx
A11: OP-009 | B11: Operación I+D #9 | C11: Carlos Díaz | D11: 46220 | F11: Alta | G11: Pendiente | H11: Validación | I11: Dato demo — reemplazar con KPIS I+D.xlsx
A12: OP-010 | B12: Operación I+D #10 | C12: Sofía Vargas | D12: 46222 | E12: 46235 | F12: Baja | G12: Completada | H12: Prototipo | I12: Dato demo — reemplazar con KPIS I+D.xlsx
A13: OP-011 | B13: Operación I+D #11 | C13: Ana Pérez | D13: 46224 | E13: 46232 | F13: Media | G13: Completada | H13: Innovación | I13: Dato demo — reemplazar con KPIS I+D.xlsx
A14: OP-012 | B14: Operación I+D #12 | C14: Luis Gómez | D14: 46226 | E14: 46235 | F14: Alta | G14: Completada | H14: Diseño | I14: Dato demo — reemplazar con KPIS I+D.xlsx
A15: OP-013 | B15: Operación I+D #13 | C15: María Ruiz | D15: 46228 | F15: Baja | G15: En proceso | H15: Validación | I15: Dato demo — reemplazar con KPIS I+D.xlsx
A16: OP-014 | B16: Operación I+D #14 | C16: Carlos Díaz | D16: 46230 | F16: Media | G16: Pendiente | H16: Prototipo | I16: Dato demo — reemplazar con KPIS I+D.xlsx
A17: OP-015 | B17: Operación I+D #15 | C17: Sofía Vargas | D17: 46232 | E17: 46236 | F17: Alta | G17: Completada | H17: Innovación | I17: Dato demo — reemplazar con KPIS I+D.xlsx
A18: OP-016 | B18: Operación I+D #16 | C18: Ana Pérez | D18: 46234 | E18: 46249 | F18: Baja | G18: Completada | H18: Diseño | I18: Dato demo — reemplazar con KPIS I+D.xlsx
A19: OP-017 | B19: Operación I+D #17 | C19: Luis Gómez | D19: 46236 | E19: 46244 | F19: Media | G19: Completada | H19: Validación | I19: Dato demo — reemplazar con KPIS I+D.xlsx
A20: OP-018 | B20: Operación I+D #18 | C20: María Ruiz | D20: 46238 | F20: Alta | G20: En proceso | H20: Prototipo | I20: Dato demo — reemplazar con KPIS I+D.xlsx
A21: OP-019 | B21: Operación I+D #19 | C21: Carlos Díaz | D21: 46240 | F21: Baja | G21: Pendiente | H21: Innovación | I21: Dato demo — reemplazar con KPIS I+D.xlsx
A22: OP-020 | B22: Operación I+D #20 | C22: Sofía Vargas | D22: 46242 | E22: 46252 | F22: Media | G22: Completada | H22: Diseño | I22: Dato demo — reemplazar con KPIS I+D.xlsx
A23: OP-021 | B23: Operación I+D #21 | C23: Ana Pérez | D23: 46244 | E23: 46248 | F23: Alta | G23: Completada | H23: Validación | I23: Dato demo — reemplazar con KPIS I+D.xlsx
A24: OP-022 | B24: Operación I+D #22 | C24: Luis Gómez | D24: 46246 | E24: 46259 | F24: Baja | G24: Completada | H24: Prototipo | I24: Dato demo — reemplazar con KPIS I+D.xlsx
A25: OP-023 | B25: Operación I+D #23 | C25: María Ruiz | D25: 46248 | F25: Media | G25: En proceso | H25: Innovación | I25: Dato demo — reemplazar con KPIS I+D.xlsx
A26: OP-024 | B26: Operación I+D #24 | C26: Carlos Díaz | D26: 46250 | F26: Alta | G26: Pendiente | H26: Diseño | I26: Dato demo — reemplazar con KPIS I+D.xlsx
A27: OP-025 | B27: Operación I+D #25 | C27: Sofía Vargas | D27: 46252 | E27: 46265 | F27: Baja | G27: Completada | H27: Validación | I27: Dato demo — reemplazar con KPIS I+D.xlsx
A28: OP-026 | B28: Operación I+D #26 | C28: Ana Pérez | D28: 46204 | E28: 46212 | F28: Media | G28: Completada | H28: Prototipo | I28: Dato demo — reemplazar con KPIS I+D.xlsx
A29: OP-027 | B29: Operación I+D #27 | C29: Luis Gómez | D29: 46206 | E29: 46210 | F29: Alta | G29: Completada | H29: Innovación | I29: Dato demo — reemplazar con KPIS I+D.xlsx
A30: OP-028 | B30: Operación I+D #28 | C30: María Ruiz | D30: 46208 | F30: Baja | G30: En proceso | H30: Diseño | I30: Dato demo — reemplazar con KPIS I+D.xlsx
A31: OP-029 | B31: Operación I+D #29 | C31: Carlos Díaz | D31: 46210 | F31: Media | G31: Pendiente | H31: Validación | I31: Dato demo — reemplazar con KPIS I+D.xlsx
A32: OP-030 | B32: Operación I+D #30 | C32: Sofía Vargas | D32: 46212 | E32: 46216 | F32: Alta | G32: Completada | H32: Prototipo | I32: Dato demo — reemplazar con KPIS I+D.xlsx
A33: OP-031 | B33: Operación I+D #31 | C33: Ana Pérez | D33: 46214 | E33: 46227 | F33: Baja | G33: Completada | H33: Innovación | I33: Dato demo — reemplazar con KPIS I+D.xlsx
A34: OP-032 | B34: Operación I+D #32 | C34: Luis Gómez | D34: 46216 | E34: 46226 | F34: Media | G34: Completada | H34: Diseño | I34: Dato demo — reemplazar con KPIS I+D.xlsx
A35: OP-033 | B35: Operación I+D #33 | C35: María Ruiz | D35: 46218 | F35: Alta | G35: En proceso | H35: Validación | I35: Dato demo — reemplazar con KPIS I+D.xlsx
A36: OP-034 | B36: Operación I+D #34 | C36: Carlos Díaz | D36: 46220 | F36: Baja | G36: Pendiente | H36: Prototipo | I36: Dato demo — reemplazar con KPIS I+D.xlsx
A37: OP-035 | B37: Operación I+D #35 | C37: Sofía Vargas | D37: 46222 | E37: 46230 | F37: Media | G37: Completada | H37: Innovación | I37: Dato demo — reemplazar con KPIS I+D.xlsx
A38: OP-036 | B38: Operación I+D #36 | C38: Ana Pérez | D38: 46224 | E38: 46233 | F38: Alta | G38: Completada | H38: Diseño | I38: Dato demo — reemplazar con KPIS I+D.xlsx
A39: OP-037 | B39: Operación I+D #37 | C39: Luis Gómez | D39: 46226 | E39: 46239 | F39: Baja | G39: Completada | H39: Validación | I39: Dato demo — reemplazar con KPIS I+D.xlsx
A40: OP-038 | B40: Operación I+D #38 | C40: María Ruiz | D40: 46228 | F40: Media | G40: En proceso | H40: Prototipo | I40: Dato demo — reemplazar con KPIS I+D.xlsx
...

Sheet 2_Parametros
A1: Parámetros de medición (editables)
A3: Año evaluación | B3: 2026 | D3: Leyenda de actualización
A4: Mes evaluación (1-12) | B4: 8 | D4: Celdas amarillas = parámetros editables.
A5: Quincena (1 o 2) | B5: 1 | D5: Al cambiar Año/Mes/Quincena, todo el KPI se recalcula.
D6: Al pegar nuevos datos en 1_Datos, no hace falta tocar fórmulas.
A7: Peso prioridad Alta / P1 / 1 | B7: 3 | D7: Si su archivo usa otros nombres de columna, mapee a los encabezados de 1_Datos.
A8: Peso prioridad Media / P2 / 2 | B8: 2
A9: Peso prioridad Baja / P3 / 3 | B9: 1
A11: Meta días ciclo Alta | B11: 5
A12: Meta días ciclo Media | B12: 9
A13: Meta días ciclo Baja | B13: 14
A15: Peso IOI — Cumplimiento a tiempo | B15: 0.7
A16: Peso IOI — Eficiencia de ciclo | B16: 0.3
A18: Meta IOI (%) | B18: 0.85
A19: Umbral alerta IOI (%) | B19: 0.7
A21: Incluir abiertas atrasadas (1=Sí, 0=No) | B21: 1
A23: Inicio quincena | B23: =DATE(B3,B4,IF(B5=1,1,16))
A24: Fin quincena | B24: =IF(B5=1,DATE(B3,B4,15),EOMONTH(DATE(B3,B4,1),0))
A25: Etiqueta quincena | B25: ="Q"&B5&" "&TEXT(DATE(B3,B4,1),"MMM-YYYY")

Sheet 3_Calc
A1: ID | B1: Operacion | C1: Responsable | D1: Fecha_Inicio | E1: Fecha_Finalizacion | F1: Prioridad_Raw | G1: Prioridad_Norm | H1: Estado | I1: Peso | J1: Dias_Ciclo | K1: Meta_Dias | L1: A_Tiempo | M1: Eficiencia_Ciclo | N1: En_Quincena | O1: Es_Cerrada | P1: Es_Atraso_Abierto | Q1: Incluir_KPI | R1: Peso_x_A_Tiempo | S1: Peso_x_Eficiencia
A2: =IF('1_Datos'!A3="","",'1_Datos'!A3) | B2: =IF(A2="","",'1_Datos'!B3) | C2: =IF(A2="","",'1_Datos'!C3) | D2: =IF(A2="","",'1_Datos'!D3) | E2: =IF(A2="","",IF('1_Datos'!E3="","",'1_Datos'!E3)) | F2: =IF(A2="","",'1_Datos'!F3) | G2: =IF(A2="","",IF(OR(UPPER(F2)="ALTA",UPPER(F2)="P1",F2=1),"Alta",IF(OR(UPPER(F2)="MEDIA",UPPER(F2)="P2",F2=2),"Media",IF(OR(UPPER(F2)="BAJA",UPPER(F2)="P3",F2=3),"Baja","Media")))) | H2: =IF(A2="","",'1_Datos'!G3) | I2: =IF(A2="","",IF(G2="Alta",'2_Parametros'!$B$7,IF(G2="Media",'2_Parametros'!$B$8,'2_Parametros'!$B$9))) | J2: =IF(A2="","",IF(E2<>"",E2-D2+1,IF(D2="","",'2_Parametros'!$B$24-D2+1))) | K2: =IF(A2="","",IF(G2="Alta",'2_Parametros'!$B$11,IF(G2="Media",'2_Parametros'!$B$12,'2_Parametros'!$B$13))) | L2: =IF(A2="","",IF(AND(UPPER(H2)="COMPLETADA",E2<>"",J2<=K2),1,0)) | M2: =IF(A2="","",IF(OR(J2="",J2=0),0,MIN(1,K2/J2))) | N2: =IF(A2="","",IF(OR(AND(E2<>"",E2>='2_Parametros'!$B$23,E2<='2_Parametros'!$B$24),AND(D2<>"",D2>='2_Parametros'!$B$23,D2<='2_Parametros'!$B$24)),1,0)) | O2: =IF(A2="","",IF(AND(UPPER(H2)="COMPLETADA",E2<>""),1,0)) | P2: =IF(A2="","",IF(AND(UPPER(H2)<>"COMPLETADA",UPPER(H2)<>"CANCELADA",D2<>"",D2+K2-1<'2_Parametros'!$B$24),1,0)) | Q2: =IF(A2="","",IF(OR(AND(O2=1,E2>='2_Parametros'!$B$23,E2<='2_Parametros'!$B$24),AND('2_Parametros'!$B$21=1,P2=1,N2=1)),1,0)) | R2: =IF(A2="","",IF(Q2=1,I2*L2,0)) | S2: =IF(A2="","",IF(Q2=1,I2*M2,0))
A3: =IF('1_Datos'!A4="","",'1_Datos'!A4) | B3: =IF(A3="","",'1_Datos'!B4) | C3: =IF(A3="","",'1_Datos'!C4) | D3: =IF(A3="","",'1_Datos'!D4) | E3: =IF(A3="","",IF('1_Datos'!E4="","",'1_Datos'!E4)) | F3: =IF(A3="","",'1_Datos'!F4) | G3: =IF(A3="","",IF(OR(UPPER(F3)="ALTA",UPPER(F3)="P1",F3=1),"Alta",IF(OR(UPPER(F3)="MEDIA",UPPER(F3)="P2",F3=2),"Media",IF(OR(UPPER(F3)="BAJA",UPPER(F3)="P3",F3=3),"Baja","Media")))) | H3: =IF(A3="","",'1_Datos'!G4) | I3: =IF(A3="","",IF(G3="Alta",'2_Parametros'!$B$7,IF(G3="Media",'2_Parametros'!$B$8,'2_Parametros'!$B$9))) | J3: =IF(A3="","",IF(E3<>"",E3-D3+1,IF(D3="","",'2_Parametros'!$B$24-D3+1))) | K3: =IF(A3="","",IF(G3="Alta",'2_Parametros'!$B$11,IF(G3="Media",'2_Parametros'!$B$12,'2_Parametros'!$B$13))) | L3: =IF(A3="","",IF(AND(UPPER(H3)="COMPLETADA",E3<>"",J3<=K3),1,0)) | M3: =IF(A3="","",IF(OR(J3="",J3=0),0,MIN(1,K3/J3))) | N3: =IF(A3="","",IF(OR(AND(E3<>"",E3>='2_Parametros'!$B$23,E3<='2_Parametros'!$B$24),AND(D3<>"",D3>='2_Parametros'!$B$23,D3<='2_Parametros'!$B$24)),1,0)) | O3: =IF(A3="","",IF(AND(UPPER(H3)="COMPLETADA",E3<>""),1,0)) | P3: =IF(A3="","",IF(AND(UPPER(H3)<>"COMPLETADA",UPPER(H3)<>"CANCELADA",D3<>"",D3+K3-1<'2_Parametros'!$B$24),1,0)) | Q3: =IF(A3="","",IF(OR(AND(O3=1,E3>='2_Parametros'!$B$23,E3<='2_Parametros'!$B$24),AND('2_Parametros'!$B$21=1,P3=1,N3=1)),1,0)) | R3: =IF(A3="","",IF(Q3=1,I3*L3,0)) | S3: =IF(A3="","",IF(Q3=1,I3*M3,0))
A4: =IF('1_Datos'!A5="","",'1_Datos'!A5) | B4: =IF(A4="","",'1_Datos'!B5) | C4: =IF(A4="","",'1_Datos'!C5) | D4: =IF(A4="","",'1_Datos'!D5) | E4: =IF(A4="","",IF('1_Datos'!E5="","",'1_Datos'!E5)) | F4: =IF(A4="","",'1_Datos'!F5) | G4: =IF(A4="","",IF(OR(UPPER(F4)="ALTA",UPPER(F4)="P1",F4=1),"Alta",IF(OR(UPPER(F4)="MEDIA",UPPER(F4)="P2",F4=2),"Media",IF(OR(UPPER(F4)="BAJA",UPPER(F4)="P3",F4=3),"Baja","Media")))) | H4: =IF(A4="","",'1_Datos'!G5) | I4: =IF(A4="","",IF(G4="Alta",'2_Parametros'!$B$7,IF(G4="Media",'2_Parametros'!$B$8,'2_Parametros'!$B$9))) | J4: =IF(A4="","",IF(E4<>"",E4-D4+1,IF(D4="","",'2_Parametros'!$B$24-D4+1))) | K4: =IF(A4="","",IF(G4="Alta",'2_Parametros'!$B$11,IF(G4="Media",'2_Parametros'!$B$12,'2_Parametros'!$B$13))) | L4: =IF(A4="","",IF(AND(UPPER(H4)="COMPLETADA",E4<>"",J4<=K4),1,0)) | M4: =IF(A4="","",IF(OR(J4="",J4=0),0,MIN(1,K4/J4))) | N4: =IF(A4="","",IF(OR(AND(E4<>"",E4>='2_Parametros'!$B$23,E4<='2_Parametros'!$B$24),AND(D4<>"",D4>='2_Parametros'!$B$23,D4<='2_Parametros'!$B$24)),1,0)) | O4: =IF(A4="","",IF(AND(UPPER(H4)="COMPLETADA",E4<>""),1,0)) | P4: =IF(A4="","",IF(AND(UPPER(H4)<>"COMPLETADA",UPPER(H4)<>"CANCELADA",D4<>"",D4+K4-1<'2_Parametros'!$B$24),1,0)) | Q4: =IF(A4="","",IF(OR(AND(O4=1,E4>='2_Parametros'!$B$23,E4<='2_Parametros'!$B$24),AND('2_Parametros'!$B$21=1,P4=1,N4=1)),1,0)) | R4: =IF(A4="","",IF(Q4=1,I4*L4,0)) | S4: =IF(A4="","",IF(Q4=1,I4*M4,0))
A5: =IF('1_Datos'!A6="","",'1_Datos'!A6) | B5: =IF(A5="","",'1_Datos'!B6) | C5: =IF(A5="","",'1_Datos'!C6) | D5: =IF(A5="","",'1_Datos'!D6) | E5: =IF(A5="","",IF('1_Datos'!E6="","",'1_Datos'!E6)) | F5: =IF(A5="","",'1_Datos'!F6) | G5: =IF(A5="","",IF(OR(UPPER(F5)="ALTA",UPPER(F5)="P1",F5=1),"Alta",IF(OR(UPPER(F5)="MEDIA",UPPER(F5)="P2",F5=2),"Media",IF(OR(UPPER(F5)="BAJA",UPPER(F5)="P3",F5=3),"Baja","Media")))) | H5: =IF(A5="","",'1_Datos'!G6) | I5: =IF(A5="","",IF(G5="Alta",'2_Parametros'!$B$7,IF(G5="Media",'2_Parametros'!$B$8,'2_Parametros'!$B$9))) | J5: =IF(A5="","",IF(E5<>"",E5-D5+1,IF(D5="","",'2_Parametros'!$B$24-D5+1))) | K5: =IF(A5="","",IF(G5="Alta",'2_Parametros'!$B$11,IF(G5="Media",'2_Parametros'!$B$12,'2_Parametros'!$B$13))) | L5: =IF(A5="","",IF(AND(UPPER(H5)="COMPLETADA",E5<>"",J5<=K5),1,0)) | M5: =IF(A5="","",IF(OR(J5="",J5=0),0,MIN(1,K5/J5))) | N5: =IF(A5="","",IF(OR(AND(E5<>"",E5>='2_Parametros'!$B$23,E5<='2_Parametros'!$B$24),AND(D5<>"",D5>='2_Parametros'!$B$23,D5<='2_Parametros'!$B$24)),1,0)) | O5: =IF(A5="","",IF(AND(UPPER(H5)="COMPLETADA",E5<>""),1,0)) | P5: =IF(A5="","",IF(AND(UPPER(H5)<>"COMPLETADA",UPPER(H5)<>"CANCELADA",D5<>"",D5+K5-1<'2_Parametros'!$B$24),1,0)) | Q5: =IF(A5="","",IF(OR(AND(O5=1,E5>='2_Parametros'!$B$23,E5<='2_Parametros'!$B$24),AND('2_Parametros'!$B$21=1,P5=1,N5=1)),1,0)) | R5: =IF(A5="","",IF(Q5=1,I5*L5,0)) | S5: =IF(A5="","",IF(Q5=1,I5*M5,0))
A6: =IF('1_Datos'!A7="","",'1_Datos'!A7) | B6: =IF(A6="","",'1_Datos'!B7) | C6: =IF(A6="","",'1_Datos'!C7) | D6: =IF(A6="","",'1_Datos'!D7) | E6: =IF(A6="","",IF('1_Datos'!E7="","",'1_Datos'!E7)) | F6: =IF(A6="","",'1_Datos'!F7) | G6: =IF(A6="","",IF(OR(UPPER(F6)="ALTA",UPPER(F6)="P1",F6=1),"Alta",IF(OR(UPPER(F6)="MEDIA",UPPER(F6)="P2",F6=2),"Media",IF(OR(UPPER(F6)="BAJA",UPPER(F6)="P3",F6=3),"Baja","Media")))) | H6: =IF(A6="","",'1_Datos'!G7) | I6: =IF(A6="","",IF(G6="Alta",'2_Parametros'!$B$7,IF(G6="Media",'2_Parametros'!$B$8,'2_Parametros'!$B$9))) | J6: =IF(A6="","",IF(E6<>"",E6-D6+1,IF(D6="","",'2_Parametros'!$B$24-D6+1))) | K6: =IF(A6="","",IF(G6="Alta",'2_Parametros'!$B$11,IF(G6="Media",'2_Parametros'!$B$12,'2_Parametros'!$B$13))) | L6: =IF(A6="","",IF(AND(UPPER(H6)="COMPLETADA",E6<>"",J6<=K6),1,0)) | M6: =IF(A6="","",IF(OR(J6="",J6=0),0,MIN(1,K6/J6))) | N6: =IF(A6="","",IF(OR(AND(E6<>"",E6>='2_Parametros'!$B$23,E6<='2_Parametros'!$B$24),AND(D6<>"",D6>='2_Parametros'!$B$23,D6<='2_Parametros'!$B$24)),1,0)) | O6: =IF(A6="","",IF(AND(UPPER(H6)="COMPLETADA",E6<>""),1,0)) | P6: =IF(A6="","",IF(AND(UPPER(H6)<>"COMPLETADA",UPPER(H6)<>"CANCELADA",D6<>"",D6+K6-1<'2_Parametros'!$B$24),1,0)) | Q6: =IF(A6="","",IF(OR(AND(O6=1,E6>='2_Parametros'!$B$23,E6<='2_Parametros'!$B$24),AND('2_Parametros'!$B$21=1,P6=1,N6=1)),1,0)) | R6: =IF(A6="","",IF(Q6=1,I6*L6,0)) | S6: =IF(A6="","",IF(Q6=1,I6*M6,0))
A7: =IF('1_Datos'!A8="","",'1_Datos'!A8) | B7: =IF(A7="","",'1_Datos'!B8) | C7: =IF(A7="","",'1_Datos'!C8) | D7: =IF(A7="","",'1_Datos'!D8) | E7: =IF(A7="","",IF('1_Datos'!E8="","",'1_Datos'!E8)) | F7: =IF(A7="","",'1_Datos'!F8) | G7: =IF(A7="","",IF(OR(UPPER(F7)="ALTA",UPPER(F7)="P1",F7=1),"Alta",IF(OR(UPPER(F7)="MEDIA",UPPER(F7)="P2",F7=2),"Media",IF(OR(UPPER(F7)="BAJA",UPPER(F7)="P3",F7=3),"Baja","Media")))) | H7: =IF(A7="","",'1_Datos'!G8) | I7: =IF(A7="","",IF(G7="Alta",'2_Parametros'!$B$7,IF(G7="Media",'2_Parametros'!$B$8,'2_Parametros'!$B$9))) | J7: =IF(A7="","",IF(E7<>"",E7-D7+1,IF(D7="","",'2_Parametros'!$B$24-D7+1))) | K7: =IF(A7="","",IF(G7="Alta",'2_Parametros'!$B$11,IF(G7="Media",'2_Parametros'!$B$12,'2_Parametros'!$B$13))) | L7: =IF(A7="","",IF(AND(UPPER(H7)="COMPLETADA",E7<>"",J7<=K7),1,0)) | M7: =IF(A7="","",IF(OR(J7="",J7=0),0,MIN(1,K7/J7))) | N7: =IF(A7="","",IF(OR(AND(E7<>"",E7>='2_Parametros'!$B$23,E7<='2_Parametros'!$B$24),AND(D7<>"",D7>='2_Parametros'!$B$23,D7<='2_Parametros'!$B$24)),1,0)) | O7: =IF(A7="","",IF(AND(UPPER(H7)="COMPLETADA",E7<>""),1,0)) | P7: =IF(A7="","",IF(AND(UPPER(H7)<>"COMPLETADA",UPPER(H7)<>"CANCELADA",D7<>"",D7+K7-1<'2_Parametros'!$B$24),1,0)) | Q7: =IF(A7="","",IF(OR(AND(O7=1,E7>='2_Parametros'!$B$23,E7<='2_Parametros'!$B$24),AND('2_Parametros'!$B$21=1,P7=1,N7=1)),1,0)) | R7: =IF(A7="","",IF(Q7=1,I7*L7,0)) | S7: =IF(A7="","",IF(Q7=1,I7*M7,0))
A8: =IF('1_Datos'!A9="","",'1_Datos'!A9) | B8: =IF(A8="","",'1_Datos'!B9) | C8: =IF(A8="","",'1_Datos'!C9) | D8: =IF(A8="","",'1_Datos'!D9) | E8: =IF(A8="","",IF('1_Datos'!E9="","",'1_Datos'!E9)) | F8: =IF(A8="","",'1_Datos'!F9) | G8: =IF(A8="","",IF(OR(UPPER(F8)="ALTA",UPPER(F8)="P1",F8=1),"Alta",IF(OR(UPPER(F8)="MEDIA",UPPER(F8)="P2",F8=2),"Media",IF(OR(UPPER(F8)="BAJA",UPPER(F8)="P3",F8=3),"Baja","Media")))) | H8: =IF(A8="","",'1_Datos'!G9) | I8: =IF(A8="","",IF(G8="Alta",'2_Parametros'!$B$7,IF(G8="Media",'2_Parametros'!$B$8,'2_Parametros'!$B$9))) | J8: =IF(A8="","",IF(E8<>"",E8-D8+1,IF(D8="","",'2_Parametros'!$B$24-D8+1))) | K8: =IF(A8="","",IF(G8="Alta",'2_Parametros'!$B$11,IF(G8="Media",'2_Parametros'!$B$12,'2_Parametros'!$B$13))) | L8: =IF(A8="","",IF(AND(UPPER(H8)="COMPLETADA",E8<>"",J8<=K8),1,0)) | M8: =IF(A8="","",IF(OR(J8="",J8=0),0,MIN(1,K8/J8))) | N8: =IF(A8="","",IF(OR(AND(E8<>"",E8>='2_Parametros'!$B$23,E8<='2_Parametros'!$B$24),AND(D8<>"",D8>='2_Parametros'!$B$23,D8<='2_Parametros'!$B$24)),1,0)) | O8: =IF(A8="","",IF(AND(UPPER(H8)="COMPLETADA",E8<>""),1,0)) | P8: =IF(A8="","",IF(AND(UPPER(H8)<>"COMPLETADA",UPPER(H8)<>"CANCELADA",D8<>"",D8+K8-1<'2_Parametros'!$B$24),1,0)) | Q8: =IF(A8="","",IF(OR(AND(O8=1,E8>='2_Parametros'!$B$23,E8<='2_Parametros'!$B$24),AND('2_Parametros'!$B$21=1,P8=1,N8=1)),1,0)) | R8: =IF(A8="","",IF(Q8=1,I8*L8,0)) | S8: =IF(A8="","",IF(Q8=1,I8*M8,0))
A9: =IF('1_Datos'!A10="","",'1_Datos'!A10) | B9: =IF(A9="","",'1_Datos'!B10) | C9: =IF(A9="","",'1_Datos'!C10) | D9: =IF(A9="","",'1_Datos'!D10) | E9: =IF(A9="","",IF('1_Datos'!E10="","",'1_Datos'!E10)) | F9: =IF(A9="","",'1_Datos'!F10) | G9: =IF(A9="","",IF(OR(UPPER(F9)="ALTA",UPPER(F9)="P1",F9=1),"Alta",IF(OR(UPPER(F9)="MEDIA",UPPER(F9)="P2",F9=2),"Media",IF(OR(UPPER(F9)="BAJA",UPPER(F9)="P3",F9=3),"Baja","Media")))) | H9: =IF(A9="","",'1_Datos'!G10) | I9: =IF(A9="","",IF(G9="Alta",'2_Parametros'!$B$7,IF(G9="Media",'2_Parametros'!$B$8,'2_Parametros'!$B$9))) | J9: =IF(A9="","",IF(E9<>"",E9-D9+1,IF(D9="","",'2_Parametros'!$B$24-D9+1))) | K9: =IF(A9="","",IF(G9="Alta",'2_Parametros'!$B$11,IF(G9="Media",'2_Parametros'!$B$12,'2_Parametros'!$B$13))) | L9: =IF(A9="","",IF(AND(UPPER(H9)="COMPLETADA",E9<>"",J9<=K9),1,0)) | M9: =IF(A9="","",IF(OR(J9="",J9=0),0,MIN(1,K9/J9))) | N9: =IF(A9="","",IF(OR(AND(E9<>"",E9>='2_Parametros'!$B$23,E9<='2_Parametros'!$B$24),AND(D9<>"",D9>='2_Parametros'!$B$23,D9<='2_Parametros'!$B$24)),1,0)) | O9: =IF(A9="","",IF(AND(UPPER(H9)="COMPLETADA",E9<>""),1,0)) | P9: =IF(A9="","",IF(AND(UPPER(H9)<>"COMPLETADA",UPPER(H9)<>"CANCELADA",D9<>"",D9+K9-1<'2_Parametros'!$B$24),1,0)) | Q9: =IF(A9="","",IF(OR(AND(O9=1,E9>='2_Parametros'!$B$23,E9<='2_Parametros'!$B$24),AND('2_Parametros'!$B$21=1,P9=1,N9=1)),1,0)) | R9: =IF(A9="","",IF(Q9=1,I9*L9,0)) | S9: =IF(A9="","",IF(Q9=1,I9*M9,0))
A10: =IF('1_Datos'!A11="","",'1_Datos'!A11) | B10: =IF(A10="","",'1_Datos'!B11) | C10: =IF(A10="","",'1_Datos'!C11) | D10: =IF(A10="","",'1_Datos'!D11) | E10: =IF(A10="","",IF('1_Datos'!E11="","",'1_Datos'!E11)) | F10: =IF(A10="","",'1_Datos'!F11) | G10: =IF(A10="","",IF(OR(UPPER(F10)="ALTA",UPPER(F10)="P1",F10=1),"Alta",IF(OR(UPPER(F10)="MEDIA",UPPER(F10)="P2",F10=2),"Media",IF(OR(UPPER(F10)="BAJA",UPPER(F10)="P3",F10=3),"Baja","Media")))) | H10: =IF(A10="","",'1_Datos'!G11) | I10: =IF(A10="","",IF(G10="Alta",'2_Parametros'!$B$7,IF(G10="Media",'2_Parametros'!$B$8,'2_Parametros'!$B$9))) | J10: =IF(A10="","",IF(E10<>"",E10-D10+1,IF(D10="","",'2_Parametros'!$B$24-D10+1))) | K10: =IF(A10="","",IF(G10="Alta",'2_Parametros'!$B$11,IF(G10="Media",'2_Parametros'!$B$12,'2_Parametros'!$B$13))) | L10: =IF(A10="","",IF(AND(UPPER(H10)="COMPLETADA",E10<>"",J10<=K10),1,0)) | M10: =IF(A10="","",IF(OR(J10="",J10=0),0,MIN(1,K10/J10))) | N10: =IF(A10="","",IF(OR(AND(E10<>"",E10>='2_Parametros'!$B$23,E10<='2_Parametros'!$B$24),AND(D10<>"",D10>='2_Parametros'!$B$23,D10<='2_Parametros'!$B$24)),1,0)) | O10: =IF(A10="","",IF(AND(UPPER(H10)="COMPLETADA",E10<>""),1,0)) | P10: =IF(A10="","",IF(AND(UPPER(H10)<>"COMPLETADA",UPPER(H10)<>"CANCELADA",D10<>"",D10+K10-1<'2_Parametros'!$B$24),1,0)) | Q10: =IF(A10="","",IF(OR(AND(O10=1,E10>='2_Parametros'!$B$23,E10<='2_Parametros'!$B$24),AND('2_Parametros'!$B$21=1,P10=1,N10=1)),1,0)) | R10: =IF(A10="","",IF(Q10=1,I10*L10,0)) | S10: =IF(A10="","",IF(Q10=1,I10*M10,0))
A11: =IF('1_Datos'!A12="","",'1_Datos'!A12) | B11: =IF(A11="","",'1_Datos'!B12) | C11: =IF(A11="","",'1_Datos'!C12) | D11: =IF(A11="","",'1_Datos'!D12) | E11: =IF(A11="","",IF('1_Datos'!E12="","",'1_Datos'!E12)) | F11: =IF(A11="","",'1_Datos'!F12) | G11: =IF(A11="","",IF(OR(UPPER(F11)="ALTA",UPPER(F11)="P1",F11=1),"Alta",IF(OR(UPPER(F11)="MEDIA",UPPER(F11)="P2",F11=2),"Media",IF(OR(UPPER(F11)="BAJA",UPPER(F11)="P3",F11=3),"Baja","Media")))) | H11: =IF(A11="","",'1_Datos'!G12) | I11: =IF(A11="","",IF(G11="Alta",'2_Parametros'!$B$7,IF(G11="Media",'2_Parametros'!$B$8,'2_Parametros'!$B$9))) | J11: =IF(A11="","",IF(E11<>"",E11-D11+1,IF(D11="","",'2_Parametros'!$B$24-D11+1))) | K11: =IF(A11="","",IF(G11="Alta",'2_Parametros'!$B$11,IF(G11="Media",'2_Parametros'!$B$12,'2_Parametros'!$B$13))) | L11: =IF(A11="","",IF(AND(UPPER(H11)="COMPLETADA",E11<>"",J11<=K11),1,0)) | M11: =IF(A11="","",IF(OR(J11="",J11=0),0,MIN(1,K11/J11))) | N11: =IF(A11="","",IF(OR(AND(E11<>"",E11>='2_Parametros'!$B$23,E11<='2_Parametros'!$B$24),AND(D11<>"",D11>='2_Parametros'!$B$23,D11<='2_Parametros'!$B$24)),1,0)) | O11: =IF(A11="","",IF(AND(UPPER(H11)="COMPLETADA",E11<>""),1,0)) | P11: =IF(A11="","",IF(AND(UPPER(H11)<>"COMPLETADA",UPPER(H11)<>"CANCELADA",D11<>"",D11+K11-1<'2_Parametros'!$B$24),1,0)) | Q11: =IF(A11="","",IF(OR(AND(O11=1,E11>='2_Parametros'!$B$23,E11<='2_Parametros'!$B$24),AND('2_Parametros'!$B$21=1,P11=1,N11=1)),1,0)) | R11: =IF(A11="","",IF(Q11=1,I11*L11,0)) | S11: =IF(A11="","",IF(Q11=1,I11*M11,0))
A12: =IF('1_Datos'!A13="","",'1_Datos'!A13) | B12: =IF(A12="","",'1_Datos'!B13) | C12: =IF(A12="","",'1_Datos'!C13) | D12: =IF(A12="","",'1_Datos'!D13) | E12: =IF(A12="","",IF('1_Datos'!E13="","",'1_Datos'!E13)) | F12: =IF(A12="","",'1_Datos'!F13) | G12: =IF(A12="","",IF(OR(UPPER(F12)="ALTA",UPPER(F12)="P1",F12=1),"Alta",IF(OR(UPPER(F12)="MEDIA",UPPER(F12)="P2",F12=2),"Media",IF(OR(UPPER(F12)="BAJA",UPPER(F12)="P3",F12=3),"Baja","Media")))) | H12: =IF(A12="","",'1_Datos'!G13) | I12: =IF(A12="","",IF(G12="Alta",'2_Parametros'!$B$7,IF(G12="Media",'2_Parametros'!$B$8,'2_Parametros'!$B$9))) | J12: =IF(A12="","",IF(E12<>"",E12-D12+1,IF(D12="","",'2_Parametros'!$B$24-D12+1))) | K12: =IF(A12="","",IF(G12="Alta",'2_Parametros'!$B$11,IF(G12="Media",'2_Parametros'!$B$12,'2_Parametros'!$B$13))) | L12: =IF(A12="","",IF(AND(UPPER(H12)="COMPLETADA",E12<>"",J12<=K12),1,0)) | M12: =IF(A12="","",IF(OR(J12="",J12=0),0,MIN(1,K12/J12))) | N12: =IF(A12="","",IF(OR(AND(E12<>"",E12>='2_Parametros'!$B$23,E12<='2_Parametros'!$B$24),AND(D12<>"",D12>='2_Parametros'!$B$23,D12<='2_Parametros'!$B$24)),1,0)) | O12: =IF(A12="","",IF(AND(UPPER(H12)="COMPLETADA",E12<>""),1,0)) | P12: =IF(A12="","",IF(AND(UPPER(H12)<>"COMPLETADA",UPPER(H12)<>"CANCELADA",D12<>"",D12+K12-1<'2_Parametros'!$B$24),1,0)) | Q12: =IF(A12="","",IF(OR(AND(O12=1,E12>='2_Parametros'!$B$23,E12<='2_Parametros'!$B$24),AND('2_Parametros'!$B$21=1,P12=1,N12=1)),1,0)) | R12: =IF(A12="","",IF(Q12=1,I12*L12,0)) | S12: =IF(A12="","",IF(Q12=1,I12*M12,0))
A13: =IF('1_Datos'!A14="","",'1_Datos'!A14) | B13: =IF(A13="","",'1_Datos'!B14) | C13: =IF(A13="","",'1_Datos'!C14) | D13: =IF(A13="","",'1_Datos'!D14) | E13: =IF(A13="","",IF('1_Datos'!E14="","",'1_Datos'!E14)) | F13: =IF(A13="","",'1_Datos'!F14) | G13: =IF(A13="","",IF(OR(UPPER(F13)="ALTA",UPPER(F13)="P1",F13=1),"Alta",IF(OR(UPPER(F13)="MEDIA",UPPER(F13)="P2",F13=2),"Media",IF(OR(UPPER(F13)="BAJA",UPPER(F13)="P3",F13=3),"Baja","Media")))) | H13: =IF(A13="","",'1_Datos'!G14) | I13: =IF(A13="","",IF(G13="Alta",'2_Parametros'!$B$7,IF(G13="Media",'2_Parametros'!$B$8,'2_Parametros'!$B$9))) | J13: =IF(A13="","",IF(E13<>"",E13-D13+1,IF(D13="","",'2_Parametros'!$B$24-D13+1))) | K13: =IF(A13="","",IF(G13="Alta",'2_Parametros'!$B$11,IF(G13="Media",'2_Parametros'!$B$12,'2_Parametros'!$B$13))) | L13: =IF(A13="","",IF(AND(UPPER(H13)="COMPLETADA",E13<>"",J13<=K13),1,0)) | M13: =IF(A13="","",IF(OR(J13="",J13=0),0,MIN(1,K13/J13))) | N13: =IF(A13="","",IF(OR(AND(E13<>"",E13>='2_Parametros'!$B$23,E13<='2_Parametros'!$B$24),AND(D13<>"",D13>='2_Parametros'!$B$23,D13<='2_Parametros'!$B$24)),1,0)) | O13: =IF(A13="","",IF(AND(UPPER(H13)="COMPLETADA",E13<>""),1,0)) | P13: =IF(A13="","",IF(AND(UPPER(H13)<>"COMPLETADA",UPPER(H13)<>"CANCELADA",D13<>"",D13+K13-1<'2_Parametros'!$B$24),1,0)) | Q13: =IF(A13="","",IF(OR(AND(O13=1,E13>='2_Parametros'!$B$23,E13<='2_Parametros'!$B$24),AND('2_Parametros'!$B$21=1,P13=1,N13=1)),1,0)) | R13: =IF(A13="","",IF(Q13=1,I13*L13,0)) | S13: =IF(A13="","",IF(Q13=1,I13*M13,0))
... A121: =IF('1_Datos'!A122="","",'1_Datos'!A122) | B121: =IF(A121="","",'1_Datos'!B122) | C121: =IF(A121="","",'1_Datos'!C122) | D121: =IF(A121="","",'1_Datos'!D122) | E121: =IF(A121="","",IF('1_Datos'!E122="","",'1_Datos'!E122)) | F121: =IF(A121="","",'1_Datos'!F122) | G121: =IF(A121="","",IF(OR(UPPER(F121)="ALTA",UPPER(F121)="P1",F121=1),"Alta",IF(OR(UPPER(F121)="MEDIA",UPPER(F121)="P2",F121=2),"Media",IF(OR(UPPER(F121)="BAJA",UPPER(F121)="P3",F121=3),"Baja","Media")))) | H121: =IF(A121="","",'1_Datos'!G122) | I121: =IF(A121="","",IF(G121="Alta",'2_Parametros'!$B$7,IF(G121="Media",'2_Parametros'!$B$8,'2_Parametros'!$B$9))) | J121: =IF(A121="","",IF(E121<>"",E121-D121+1,IF(D121="","",'2_Parametros'!$B$24-D121+1))) | K121: =IF(A121="","",IF(G121="Alta",'2_Parametros'!$B$11,IF(G121="Media",'2_Parametros'!$B$12,'2_Parametros'!$B$13))) | L121: =IF(A121="","",IF(AND(UPPER(H121)="COMPLETADA",E121<>"",J121<=K121),1,0)) | M121: =IF(A121="","",IF(OR(J121="",J121=0),0,MIN(1,K121/J121))) | N121: =IF(A121="","",IF(OR(AND(E121<>"",E121>='2_Parametros'!$B$23,E121<='2_Parametros'!$B$24),AND(D121<>"",D121>='2_Parametros'!$B$23,D121<='2_Parametros'!$B$24)),1,0)) | O121: =IF(A121="","",IF(AND(UPPER(H121)="COMPLETADA",E121<>""),1,0)) | P121: =IF(A121="","",IF(AND(UPPER(H121)<>"COMPLETADA",UPPER(H121)<>"CANCELADA",D121<>"",D121+K121-1<'2_Parametros'!$B$24),1,0)) | Q121: =IF(A121="","",IF(OR(AND(O121=1,E121>='2_Parametros'!$B$23,E121<='2_Parametros'!$B$24),AND('2_Parametros'!$B$21=1,P121=1,N121=1)),1,0)) | R121: =IF(A121="","",IF(Q121=1,I121*L121,0)) | S121: =IF(A121="","",IF(Q121=1,I121*M121,0))

Sheet 4_KPI_Responsables
A1: KPI de Operatividad por Responsable
A2: ="Quincena activa: "&'2_Parametros'!B25&" | Periodo: "&TEXT('2_Parametros'!B23,"DD/MM/YYYY")&" - "&TEXT('2_Parametros'!B24,"DD/MM/YYYY")
A4: Responsable | B4: Ops_Evaluadas | C4: Ops_Completadas | D4: Ops_A_Tiempo | E4: Peso_Total | F4: Cumplimiento_Ponderado | G4: Eficiencia_Ciclo_Ponderada | H4: IOI | I4: Semaforo | J4: Dias_Ciclo_Promedio | K4: Ops_Alta_Prioridad | L4: Brecha_vs_Meta
A5: Ana Pérez | B5: =COUNTIFS('3_Calc'!$C:$C,$A5,'3_Calc'!$Q:$Q,1) | C5: =COUNTIFS('3_Calc'!$C:$C,$A5,'3_Calc'!$Q:$Q,1,'3_Calc'!$O:$O,1) | D5: =SUMIFS('3_Calc'!$L:$L,'3_Calc'!$C:$C,$A5,'3_Calc'!$Q:$Q,1) | E5: =SUMIFS('3_Calc'!$I:$I,'3_Calc'!$C:$C,$A5,'3_Calc'!$Q:$Q,1) | F5: =IF(E5=0,"",SUMIFS('3_Calc'!$R:$R,'3_Calc'!$C:$C,$A5,'3_Calc'!$Q:$Q,1)/E5) | G5: =IF(E5=0,"",SUMIFS('3_Calc'!$S:$S,'3_Calc'!$C:$C,$A5,'3_Calc'!$Q:$Q,1)/E5) | H5: =IF(E5=0,"",F5*'2_Parametros'!$B$15+G5*'2_Parametros'!$B$16) | I5: =IF(H5="","",IF(H5>='2_Parametros'!$B$18,"Cumple",IF(H5>='2_Parametros'!$B$19,"Riesgo","Critico"))) | J5: =IFERROR(AVERAGEIFS('3_Calc'!$J:$J,'3_Calc'!$C:$C,$A5,'3_Calc'!$Q:$Q,1,'3_Calc'!$O:$O,1),"") | K5: =COUNTIFS('3_Calc'!$C:$C,$A5,'3_Calc'!$Q:$Q,1,'3_Calc'!$G:$G,"Alta") | L5: =IF(H5="","",H5-'2_Parametros'!$B$18)
A6: Carlos Díaz | B6: =COUNTIFS('3_Calc'!$C:$C,$A6,'3_Calc'!$Q:$Q,1) | C6: =COUNTIFS('3_Calc'!$C:$C,$A6,'3_Calc'!$Q:$Q,1,'3_Calc'!$O:$O,1) | D6: =SUMIFS('3_Calc'!$L:$L,'3_Calc'!$C:$C,$A6,'3_Calc'!$Q:$Q,1) | E6: =SUMIFS('3_Calc'!$I:$I,'3_Calc'!$C:$C,$A6,'3_Calc'!$Q:$Q,1) | F6: =IF(E6=0,"",SUMIFS('3_Calc'!$R:$R,'3_Calc'!$C:$C,$A6,'3_Calc'!$Q:$Q,1)/E6) | G6: =IF(E6=0,"",SUMIFS('3_Calc'!$S:$S,'3_Calc'!$C:$C,$A6,'3_Calc'!$Q:$Q,1)/E6) | H6: =IF(E6=0,"",F6*'2_Parametros'!$B$15+G6*'2_Parametros'!$B$16) | I6: =IF(H6="","",IF(H6>='2_Parametros'!$B$18,"Cumple",IF(H6>='2_Parametros'!$B$19,"Riesgo","Critico"))) | J6: =IFERROR(AVERAGEIFS('3_Calc'!$J:$J,'3_Calc'!$C:$C,$A6,'3_Calc'!$Q:$Q,1,'3_Calc'!$O:$O,1),"") | K6: =COUNTIFS('3_Calc'!$C:$C,$A6,'3_Calc'!$Q:$Q,1,'3_Calc'!$G:$G,"Alta") | L6: =IF(H6="","",H6-'2_Parametros'!$B$18)
A7: Luis Gómez | B7: =COUNTIFS('3_Calc'!$C:$C,$A7,'3_Calc'!$Q:$Q,1) | C7: =COUNTIFS('3_Calc'!$C:$C,$A7,'3_Calc'!$Q:$Q,1,'3_Calc'!$O:$O,1) | D7: =SUMIFS('3_Calc'!$L:$L,'3_Calc'!$C:$C,$A7,'3_Calc'!$Q:$Q,1) | E7: =SUMIFS('3_Calc'!$I:$I,'3_Calc'!$C:$C,$A7,'3_Calc'!$Q:$Q,1) | F7: =IF(E7=0,"",SUMIFS('3_Calc'!$R:$R,'3_Calc'!$C:$C,$A7,'3_Calc'!$Q:$Q,1)/E7) | G7: =IF(E7=0,"",SUMIFS('3_Calc'!$S:$S,'3_Calc'!$C:$C,$A7,'3_Calc'!$Q:$Q,1)/E7) | H7: =IF(E7=0,"",F7*'2_Parametros'!$B$15+G7*'2_Parametros'!$B$16) | I7: =IF(H7="","",IF(H7>='2_Parametros'!$B$18,"Cumple",IF(H7>='2_Parametros'!$B$19,"Riesgo","Critico"))) | J7: =IFERROR(AVERAGEIFS('3_Calc'!$J:$J,'3_Calc'!$C:$C,$A7,'3_Calc'!$Q:$Q,1,'3_Calc'!$O:$O,1),"") | K7: =COUNTIFS('3_Calc'!$C:$C,$A7,'3_Calc'!$Q:$Q,1,'3_Calc'!$G:$G,"Alta") | L7: =IF(H7="","",H7-'2_Parametros'!$B$18)
A8: María Ruiz | B8: =COUNTIFS('3_Calc'!$C:$C,$A8,'3_Calc'!$Q:$Q,1) | C8: =COUNTIFS('3_Calc'!$C:$C,$A8,'3_Calc'!$Q:$Q,1,'3_Calc'!$O:$O,1) | D8: =SUMIFS('3_Calc'!$L:$L,'3_Calc'!$C:$C,$A8,'3_Calc'!$Q:$Q,1) | E8: =SUMIFS('3_Calc'!$I:$I,'3_Calc'!$C:$C,$A8,'3_Calc'!$Q:$Q,1) | F8: =IF(E8=0,"",SUMIFS('3_Calc'!$R:$R,'3_Calc'!$C:$C,$A8,'3_Calc'!$Q:$Q,1)/E8) | G8: =IF(E8=0,"",SUMIFS('3_Calc'!$S:$S,'3_Calc'!$C:$C,$A8,'3_Calc'!$Q:$Q,1)/E8) | H8: =IF(E8=0,"",F8*'2_Parametros'!$B$15+G8*'2_Parametros'!$B$16) | I8: =IF(H8="","",IF(H8>='2_Parametros'!$B$18,"Cumple",IF(H8>='2_Parametros'!$B$19,"Riesgo","Critico"))) | J8: =IFERROR(AVERAGEIFS('3_Calc'!$J:$J,'3_Calc'!$C:$C,$A8,'3_Calc'!$Q:$Q,1,'3_Calc'!$O:$O,1),"") | K8: =COUNTIFS('3_Calc'!$C:$C,$A8,'3_Calc'!$Q:$Q,1,'3_Calc'!$G:$G,"Alta") | L8: =IF(H8="","",H8-'2_Parametros'!$B$18)
A9: Sofía Vargas | B9: =COUNTIFS('3_Calc'!$C:$C,$A9,'3_Calc'!$Q:$Q,1) | C9: =COUNTIFS('3_Calc'!$C:$C,$A9,'3_Calc'!$Q:$Q,1,'3_Calc'!$O:$O,1) | D9: =SUMIFS('3_Calc'!$L:$L,'3_Calc'!$C:$C,$A9,'3_Calc'!$Q:$Q,1) | E9: =SUMIFS('3_Calc'!$I:$I,'3_Calc'!$C:$C,$A9,'3_Calc'!$Q:$Q,1) | F9: =IF(E9=0,"",SUMIFS('3_Calc'!$R:$R,'3_Calc'!$C:$C,$A9,'3_Calc'!$Q:$Q,1)/E9) | G9: =IF(E9=0,"",SUMIFS('3_Calc'!$S:$S,'3_Calc'!$C:$C,$A9,'3_Calc'!$Q:$Q,1)/E9) | H9: =IF(E9=0,"",F9*'2_Parametros'!$B$15+G9*'2_Parametros'!$B$16) | I9: =IF(H9="","",IF(H9>='2_Parametros'!$B$18,"Cumple",IF(H9>='2_Parametros'!$B$19,"Riesgo","Critico"))) | J9: =IFERROR(AVERAGEIFS('3_Calc'!$J:$J,'3_Calc'!$C:$C,$A9,'3_Calc'!$Q:$Q,1,'3_Calc'!$O:$O,1),"") | K9: =COUNTIFS('3_Calc'!$C:$C,$A9,'3_Calc'!$Q:$Q,1,'3_Calc'!$G:$G,"Alta") | L9: =IF(H9="","",H9-'2_Parametros'!$B$18)
B10: =IF(A10="","",COUNTIFS('3_Calc'!$C:$C,$A10,'3_Calc'!$Q:$Q,1)) | C10: =IF(A10="","",COUNTIFS('3_Calc'!$C:$C,$A10,'3_Calc'!$Q:$Q,1,'3_Calc'!$O:$O,1)) | D10: =IF(A10="","",SUMIFS('3_Calc'!$L:$L,'3_Calc'!$C:$C,$A10,'3_Calc'!$Q:$Q,1)) | E10: =IF(A10="","",SUMIFS('3_Calc'!$I:$I,'3_Calc'!$C:$C,$A10,'3_Calc'!$Q:$Q,1)) | F10: =IF(OR(A10="",E10=0),"",SUMIFS('3_Calc'!$R:$R,'3_Calc'!$C:$C,$A10,'3_Calc'!$Q:$Q,1)/E10) | G10: =IF(OR(A10="",E10=0),"",SUMIFS('3_Calc'!$S:$S,'3_Calc'!$C:$C,$A10,'3_Calc'!$Q:$Q,1)/E10) | H10: =IF(OR(A10="",E10=0),"",F10*'2_Parametros'!$B$15+G10*'2_Parametros'!$B$16) | I10: =IF(H10="","",IF(H10>='2_Parametros'!$B$18,"Cumple",IF(H10>='2_Parametros'!$B$19,"Riesgo","Critico"))) | J10: =IF(A10="","",IFERROR(AVERAGEIFS('3_Calc'!$J:$J,'3_Calc'!$C:$C,$A10,'3_Calc'!$Q:$Q,1,'3_Calc'!$O:$O,1),"")) | K10: =IF(A10="","",COUNTIFS('3_Calc'!$C:$C,$A10,'3_Calc'!$Q:$Q,1,'3_Calc'!$G:$G,"Alta")) | L10: =IF(H10="","",H10-'2_Parametros'!$B$18)
B11: =IF(A11="","",COUNTIFS('3_Calc'!$C:$C,$A11,'3_Calc'!$Q:$Q,1)) | C11: =IF(A11="","",COUNTIFS('3_Calc'!$C:$C,$A11,'3_Calc'!$Q:$Q,1,'3_Calc'!$O:$O,1)) | D11: =IF(A11="","",SUMIFS('3_Calc'!$L:$L,'3_Calc'!$C:$C,$A11,'3_Calc'!$Q:$Q,1)) | E11: =IF(A11="","",SUMIFS('3_Calc'!$I:$I,'3_Calc'!$C:$C,$A11,'3_Calc'!$Q:$Q,1)) | F11: =IF(OR(A11="",E11=0),"",SUMIFS('3_Calc'!$R:$R,'3_Calc'!$C:$C,$A11,'3_Calc'!$Q:$Q,1)/E11) | G11: =IF(OR(A11="",E11=0),"",SUMIFS('3_Calc'!$S:$S,'3_Calc'!$C:$C,$A11,'3_Calc'!$Q:$Q,1)/E11) | H11: =IF(OR(A11="",E11=0),"",F11*'2_Parametros'!$B$15+G11*'2_Parametros'!$B$16) | I11: =IF(H11="","",IF(H11>='2_Parametros'!$B$18,"Cumple",IF(H11>='2_Parametros'!$B$19,"Riesgo","Critico"))) | J11: =IF(A11="","",IFERROR(AVERAGEIFS('3_Calc'!$J:$J,'3_Calc'!$C:$C,$A11,'3_Calc'!$Q:$Q,1,'3_Calc'!$O:$O,1),"")) | K11: =IF(A11="","",COUNTIFS('3_Calc'!$C:$C,$A11,'3_Calc'!$Q:$Q,1,'3_Calc'!$G:$G,"Alta")) | L11: =IF(H11="","",H11-'2_Parametros'!$B$18)
B12: =IF(A12="","",COUNTIFS('3_Calc'!$C:$C,$A12,'3_Calc'!$Q:$Q,1)) | C12: =IF(A12="","",COUNTIFS('3_Calc'!$C:$C,$A12,'3_Calc'!$Q:$Q,1,'3_Calc'!$O:$O,1)) | D12: =IF(A12="","",SUMIFS('3_Calc'!$L:$L,'3_Calc'!$C:$C,$A12,'3_Calc'!$Q:$Q,1)) | E12: =IF(A12="","",SUMIFS('3_Calc'!$I:$I,'3_Calc'!$C:$C,$A12,'3_Calc'!$Q:$Q,1)) | F12: =IF(OR(A12="",E12=0),"",SUMIFS('3_Calc'!$R:$R,'3_Calc'!$C:$C,$A12,'3_Calc'!$Q:$Q,1)/E12) | G12: =IF(OR(A12="",E12=0),"",SUMIFS('3_Calc'!$S:$S,'3_Calc'!$C:$C,$A12,'3_Calc'!$Q:$Q,1)/E12) | H12: =IF(OR(A12="",E12=0),"",F12*'2_Parametros'!$B$15+G12*'2_Parametros'!$B$16) | I12: =IF(H12="","",IF(H12>='2_Parametros'!$B$18,"Cumple",IF(H12>='2_Parametros'!$B$19,"Riesgo","Critico"))) | J12: =IF(A12="","",IFERROR(AVERAGEIFS('3_Calc'!$J:$J,'3_Calc'!$C:$C,$A12,'3_Calc'!$Q:$Q,1,'3_Calc'!$O:$O,1),"")) | K12: =IF(A12="","",COUNTIFS('3_Calc'!$C:$C,$A12,'3_Calc'!$Q:$Q,1,'3_Calc'!$G:$G,"Alta")) | L12: =IF(H12="","",H12-'2_Parametros'!$B$18)
B13: =IF(A13="","",COUNTIFS('3_Calc'!$C:$C,$A13,'3_Calc'!$Q:$Q,1)) | C13: =IF(A13="","",COUNTIFS('3_Calc'!$C:$C,$A13,'3_Calc'!$Q:$Q,1,'3_Calc'!$O:$O,1)) | D13: =IF(A13="","",SUMIFS('3_Calc'!$L:$L,'3_Calc'!$C:$C,$A13,'3_Calc'!$Q:$Q,1)) | E13: =IF(A13="","",SUMIFS('3_Calc'!$I:$I,'3_Calc'!$C:$C,$A13,'3_Calc'!$Q:$Q,1)) | F13: =IF(OR(A13="",E13=0),"",SUMIFS('3_Calc'!$R:$R,'3_Calc'!$C:$C,$A13,'3_Calc'!$Q:$Q,1)/E13) | G13: =IF(OR(A13="",E13=0),"",SUMIFS('3_Calc'!$S:$S,'3_Calc'!$C:$C,$A13,'3_Calc'!$Q:$Q,1)/E13) | H13: =IF(OR(A13="",E13=0),"",F13*'2_Parametros'!$B$15+G13*'2_Parametros'!$B$16) | I13: =IF(H13="","",IF(H13>='2_Parametros'!$B$18,"Cumple",IF(H13>='2_Parametros'!$B$19,"Riesgo","Critico"))) | J13: =IF(A13="","",IFERROR(AVERAGEIFS('3_Calc'!$J:$J,'3_Calc'!$C:$C,$A13,'3_Calc'!$Q:$Q,1,'3_Calc'!$O:$O,1),"")) | K13: =IF(A13="","",COUNTIFS('3_Calc'!$C:$C,$A13,'3_Calc'!$Q:$Q,1,'3_Calc'!$G:$G,"Alta")) | L13: =IF(H13="","",H13-'2_Parametros'!$B$18)
B14: =IF(A14="","",COUNTIFS('3_Calc'!$C:$C,$A14,'3_Calc'!$Q:$Q,1)) | C14: =IF(A14="","",COUNTIFS('3_Calc'!$C:$C,$A14,'3_Calc'!$Q:$Q,1,'3_Calc'!$O:$O,1)) | D14: =IF(A14="","",SUMIFS('3_Calc'!$L:$L,'3_Calc'!$C:$C,$A14,'3_Calc'!$Q:$Q,1)) | E14: =IF(A14="","",SUMIFS('3_Calc'!$I:$I,'3_Calc'!$C:$C,$A14,'3_Calc'!$Q:$Q,1)) | F14: =IF(OR(A14="",E14=0),"",SUMIFS('3_Calc'!$R:$R,'3_Calc'!$C:$C,$A14,'3_Calc'!$Q:$Q,1)/E14) | G14: =IF(OR(A14="",E14=0),"",SUMIFS('3_Calc'!$S:$S,'3_Calc'!$C:$C,$A14,'3_Calc'!$Q:$Q,1)/E14) | H14: =IF(OR(A14="",E14=0),"",F14*'2_Parametros'!$B$15+G14*'2_Parametros'!$B$16) | I14: =IF(H14="","",IF(H14>='2_Parametros'!$B$18,"Cumple",IF(H14>='2_Parametros'!$B$19,"Riesgo","Critico"))) | J14: =IF(A14="","",IFERROR(AVERAGEIFS('3_Calc'!$J:$J,'3_Calc'!$C:$C,$A14,'3_Calc'!$Q:$Q,1,'3_Calc'!$O:$O,1),"")) | K14: =IF(A14="","",COUNTIFS('3_Calc'!$C:$C,$A14,'3_Calc'!$Q:$Q,1,'3_Calc'!$G:$G,"Alta")) | L14: =IF(H14="","",H14-'2_Parametros'!$B$18)
B15: =IF(A15="","",COUNTIFS('3_Calc'!$C:$C,$A15,'3_Calc'!$Q:$Q,1)) | C15: =IF(A15="","",COUNTIFS('3_Calc'!$C:$C,$A15,'3_Calc'!$Q:$Q,1,'3_Calc'!$O:$O,1)) | D15: =IF(A15="","",SUMIFS('3_Calc'!$L:$L,'3_Calc'!$C:$C,$A15,'3_Calc'!$Q:$Q,1)) | E15: =IF(A15="","",SUMIFS('3_Calc'!$I:$I,'3_Calc'!$C:$C,$A15,'3_Calc'!$Q:$Q,1)) | F15: =IF(OR(A15="",E15=0),"",SUMIFS('3_Calc'!$R:$R,'3_Calc'!$C:$C,$A15,'3_Calc'!$Q:$Q,1)/E15) | G15: =IF(OR(A15="",E15=0),"",SUMIFS('3_Calc'!$S:$S,'3_Calc'!$C:$C,$A15,'3_Calc'!$Q:$Q,1)/E15) | H15: =IF(OR(A15="",E15=0),"",F15*'2_Parametros'!$B$15+G15*'2_Parametros'!$B$16) | I15: =IF(H15="","",IF(H15>='2_Parametros'!$B$18,"Cumple",IF(H15>='2_Parametros'!$B$19,"Riesgo","Critico"))) | J15: =IF(A15="","",IFERROR(AVERAGEIFS('3_Calc'!$J:$J,'3_Calc'!$C:$C,$A15,'3_Calc'!$Q:$Q,1,'3_Calc'!$O:$O,1),"")) | K15: =IF(A15="","",COUNTIFS('3_Calc'!$C:$C,$A15,'3_Calc'!$Q:$Q,1,'3_Calc'!$G:$G,"Alta")) | L15: =IF(H15="","",H15-'2_Parametros'!$B$18)
B16: =IF(A16="","",COUNTIFS('3_Calc'!$C:$C,$A16,'3_Calc'!$Q:$Q,1)) | C16: =IF(A16="","",COUNTIFS('3_Calc'!$C:$C,$A16,'3_Calc'!$Q:$Q,1,'3_Calc'!$O:$O,1)) | D16: =IF(A16="","",SUMIFS('3_Calc'!$L:$L,'3_Calc'!$C:$C,$A16,'3_Calc'!$Q:$Q,1)) | E16: =IF(A16="","",SUMIFS('3_Calc'!$I:$I,'3_Calc'!$C:$C,$A16,'3_Calc'!$Q:$Q,1)) | F16: =IF(OR(A16="",E16=0),"",SUMIFS('3_Calc'!$R:$R,'3_Calc'!$C:$C,$A16,'3_Calc'!$Q:$Q,1)/E16) | G16: =IF(OR(A16="",E16=0),"",SUMIFS('3_Calc'!$S:$S,'3_Calc'!$C:$C,$A16,'3_Calc'!$Q:$Q,1)/E16) | H16: =IF(OR(A16="",E16=0),"",F16*'2_Parametros'!$B$15+G16*'2_Parametros'!$B$16) | I16: =IF(H16="","",IF(H16>='2_Parametros'!$B$18,"Cumple",IF(H16>='2_Parametros'!$B$19,"Riesgo","Critico"))) | J16: =IF(A16="","",IFERROR(AVERAGEIFS('3_Calc'!$J:$J,'3_Calc'!$C:$C,$A16,'3_Calc'!$Q:$Q,1,'3_Calc'!$O:$O,1),"")) | K16: =IF(A16="","",COUNTIFS('3_Calc'!$C:$C,$A16,'3_Calc'!$Q:$Q,1,'3_Calc'!$G:$G,"Alta")) | L16: =IF(H16="","",H16-'2_Parametros'!$B$18)
B17: =IF(A17="","",COUNTIFS('3_Calc'!$C:$C,$A17,'3_Calc'!$Q:$Q,1)) | C17: =IF(A17="","",COUNTIFS('3_Calc'!$C:$C,$A17,'3_Calc'!$Q:$Q,1,'3_Calc'!$O:$O,1)) | D17: =IF(A17="","",SUMIFS('3_Calc'!$L:$L,'3_Calc'!$C:$C,$A17,'3_Calc'!$Q:$Q,1)) | E17: =IF(A17="","",SUMIFS('3_Calc'!$I:$I,'3_Calc'!$C:$C,$A17,'3_Calc'!$Q:$Q,1)) | F17: =IF(OR(A17="",E17=0),"",SUMIFS('3_Calc'!$R:$R,'3_Calc'!$C:$C,$A17,'3_Calc'!$Q:$Q,1)/E17) | G17: =IF(OR(A17="",E17=0),"",SUMIFS('3_Calc'!$S:$S,'3_Calc'!$C:$C,$A17,'3_Calc'!$Q:$Q,1)/E17) | H17: =IF(OR(A17="",E17=0),"",F17*'2_Parametros'!$B$15+G17*'2_Parametros'!$B$16) | I17: =IF(H17="","",IF(H17>='2_Parametros'!$B$18,"Cumple",IF(H17>='2_Parametros'!$B$19,"Riesgo","Critico"))) | J17: =IF(A17="","",IFERROR(AVERAGEIFS('3_Calc'!$J:$J,'3_Calc'!$C:$C,$A17,'3_Calc'!$Q:$Q,1,'3_Calc'!$O:$O,1),"")) | K17: =IF(A17="","",COUNTIFS('3_Calc'!$C:$C,$A17,'3_Calc'!$Q:$Q,1,'3_Calc'!$G:$G,"Alta")) | L17: =IF(H17="","",H17-'2_Parametros'!$B$18)
B18: =IF(A18="","",COUNTIFS('3_Calc'!$C:$C,$A18,'3_Calc'!$Q:$Q,1)) | C18: =IF(A18="","",COUNTIFS('3_Calc'!$C:$C,$A18,'3_Calc'!$Q:$Q,1,'3_Calc'!$O:$O,1)) | D18: =IF(A18="","",SUMIFS('3_Calc'!$L:$L,'3_Calc'!$C:$C,$A18,'3_Calc'!$Q:$Q,1)) | E18: =IF(A18="","",SUMIFS('3_Calc'!$I:$I,'3_Calc'!$C:$C,$A18,'3_Calc'!$Q:$Q,1)) | F18: =IF(OR(A18="",E18=0),"",SUMIFS('3_Calc'!$R:$R,'3_Calc'!$C:$C,$A18,'3_Calc'!$Q:$Q,1)/E18) | G18: =IF(OR(A18="",E18=0),"",SUMIFS('3_Calc'!$S:$S,'3_Calc'!$C:$C,$A18,'3_Calc'!$Q:$Q,1)/E18) | H18: =IF(OR(A18="",E18=0),"",F18*'2_Parametros'!$B$15+G18*'2_Parametros'!$B$16) | I18: =IF(H18="","",IF(H18>='2_Parametros'!$B$18,"Cumple",IF(H18>='2_Parametros'!$B$19,"Riesgo","Critico"))) | J18: =IF(A18="","",IFERROR(AVERAGEIFS('3_Calc'!$J:$J,'3_Calc'!$C:$C,$A18,'3_Calc'!$Q:$Q,1,'3_Calc'!$O:$O,1),"")) | K18: =IF(A18="","",COUNTIFS('3_Calc'!$C:$C,$A18,'3_Calc'!$Q:$Q,1,'3_Calc'!$G:$G,"Alta")) | L18: =IF(H18="","",H18-'2_Parametros'!$B$18)
B19: =IF(A19="","",COUNTIFS('3_Calc'!$C:$C,$A19,'3_Calc'!$Q:$Q,1)) | C19: =IF(A19="","",COUNTIFS('3_Calc'!$C:$C,$A19,'3_Calc'!$Q:$Q,1,'3_Calc'!$O:$O,1)) | D19: =IF(A19="","",SUMIFS('3_Calc'!$L:$L,'3_Calc'!$C:$C,$A19,'3_Calc'!$Q:$Q,1)) | E19: =IF(A19="","",SUMIFS('3_Calc'!$I:$I,'3_Calc'!$C:$C,$A19,'3_Calc'!$Q:$Q,1)) | F19: =IF(OR(A19="",E19=0),"",SUMIFS('3_Calc'!$R:$R,'3_Calc'!$C:$C,$A19,'3_Calc'!$Q:$Q,1)/E19) | G19: =IF(OR(A19="",E19=0),"",SUMIFS('3_Calc'!$S:$S,'3_Calc'!$C:$C,$A19,'3_Calc'!$Q:$Q,1)/E19) | H19: =IF(OR(A19="",E19=0),"",F19*'2_Parametros'!$B$15+G19*'2_Parametros'!$B$16) | I19: =IF(H19="","",IF(H19>='2_Parametros'!$B$18,"Cumple",IF(H19>='2_Parametros'!$B$19,"Riesgo","Critico"))) | J19: =IF(A19="","",IFERROR(AVERAGEIFS('3_Calc'!$J:$J,'3_Calc'!$C:$C,$A19,'3_Calc'!$Q:$Q,1,'3_Calc'!$O:$O,1),"")) | K19: =IF(A19="","",COUNTIFS('3_Calc'!$C:$C,$A19,'3_Calc'!$Q:$Q,1,'3_Calc'!$G:$G,"Alta")) | L19: =IF(H19="","",H19-'2_Parametros'!$B$18)
A21: TOTAL DEPARTAMENTO I+D | B21: =SUM(B5:B19) | C21: =SUM(C5:C19) | D21: =SUM(D5:D19) | E21: =SUM(E5:E19) | F21: =IF(E21=0,"",SUMPRODUCT((E5:E19)*(F5:F19))/E21) | G21: =IF(E21=0,"",SUMPRODUCT((E5:E19)*(G5:G19))/E21) | H21: =IF(E21=0,"",F21*'2_Parametros'!$B$15+G21*'2_Parametros'!$B$16) | I21: =IF(H21="","",IF(H21>='2_Parametros'!$B$18,"Cumple",IF(H21>='2_Parametros'!$B$19,"Riesgo","Critico"))) | K21: =SUM(K5:K19) | L21: =IF(H21="","",H21-'2_Parametros'!$B$18)
A23: Fórmulas vivas: al renovar 1_Datos o cambiar 2_Parametros, esta hoja se actualiza sola.

Sheet 5_Ranking
A1: Ranking de Operatividad I+D (quincena activa)
A3: Posición | B3: Responsable | C3: IOI | D3: Interpretación
A4: 1 | B4: =IFERROR(INDEX('4_KPI_Responsables'!$A$5:$A$9,MATCH(LARGE('4_KPI_Responsables'!$H$5:$H$9,1),'4_KPI_Responsables'!$H$5:$H$9,0)),"") | C4: =IFERROR(LARGE('4_KPI_Responsables'!$H$5:$H$9,1),"") | D4: =IF(C4="","",IF(C4>='2_Parametros'!$B$18,"Operatividad alta",IF(C4>='2_Parametros'!$B$19,"Operatividad media — revisar atrasos","Operatividad baja — priorizar cierres Alta")))
A5: 2 | B5: =IFERROR(INDEX('4_KPI_Responsables'!$A$5:$A$9,MATCH(LARGE('4_KPI_Responsables'!$H$5:$H$9,2),'4_KPI_Responsables'!$H$5:$H$9,0)),"") | C5: =IFERROR(LARGE('4_KPI_Responsables'!$H$5:$H$9,2),"") | D5: =IF(C5="","",IF(C5>='2_Parametros'!$B$18,"Operatividad alta",IF(C5>='2_Parametros'!$B$19,"Operatividad media — revisar atrasos","Operatividad baja — priorizar cierres Alta")))
A6: 3 | B6: =IFERROR(INDEX('4_KPI_Responsables'!$A$5:$A$9,MATCH(LARGE('4_KPI_Responsables'!$H$5:$H$9,3),'4_KPI_Responsables'!$H$5:$H$9,0)),"") | C6: =IFERROR(LARGE('4_KPI_Responsables'!$H$5:$H$9,3),"") | D6: =IF(C6="","",IF(C6>='2_Parametros'!$B$18,"Operatividad alta",IF(C6>='2_Parametros'!$B$19,"Operatividad media — revisar atrasos","Operatividad baja — priorizar cierres Alta")))
A7: 4 | B7: =IFERROR(INDEX('4_KPI_Responsables'!$A$5:$A$9,MATCH(LARGE('4_KPI_Responsables'!$H$5:$H$9,4),'4_KPI_Responsables'!$H$5:$H$9,0)),"") | C7: =IFERROR(LARGE('4_KPI_Responsables'!$H$5:$H$9,4),"") | D7: =IF(C7="","",IF(C7>='2_Parametros'!$B$18,"Operatividad alta",IF(C7>='2_Parametros'!$B$19,"Operatividad media — revisar atrasos","Operatividad baja — priorizar cierres Alta")))
A8: 5 | B8: =IFERROR(INDEX('4_KPI_Responsables'!$A$5:$A$9,MATCH(LARGE('4_KPI_Responsables'!$H$5:$H$9,5),'4_KPI_Responsables'!$H$5:$H$9,0)),"") | C8: =IFERROR(LARGE('4_KPI_Responsables'!$H$5:$H$9,5),"") | D8: =IF(C8="","",IF(C8>='2_Parametros'!$B$18,"Operatividad alta",IF(C8>='2_Parametros'!$B$19,"Operatividad media — revisar atrasos","Operatividad baja — priorizar cierres Alta")))

Sheet 6_Metodologia
A1: Propuesta metodológica — Indicador de Operatividad de Responsables I+D
A3: Concepto | B3: Definición
A4: Nombre del indicador | B4: IOI — Índice de Operatividad I+D
A5: Unidad | B5: Porcentaje (0%–100%)
A6: Frecuencia | B6: Quincenal (Q1: días 1–15; Q2: días 16–fin de mes)
A7: Alcance | B7: Todos los responsables con operaciones en el departamento I+D
A8: Insumos | B8: Fecha_Inicio, Fecha_Finalizacion, Prioridad, Responsable, Estado (desde KPIS I+D.xlsx)
A9: Fórmula IOI | B9: IOI = 70% × Cumplimiento_Ponderado + 30% × Eficiencia_Ciclo_Ponderada
A10: Cumplimiento_Ponderado | B10: Σ(Peso_prioridad × A_Tiempo) / Σ(Peso_prioridad) sobre ops evaluadas en la quincena
A11: A_Tiempo | B11: 1 si Estado=Completada y (Fecha_Finalizacion − Fecha_Inicio + 1) ≤ Meta_días(prioridad); si no, 0
A12: Eficiencia_Ciclo_Ponderada | B12: Σ(Peso × min(1, Meta_días / Días_ciclo)) / Σ(Peso)
A13: Pesos de prioridad (default) | B13: Alta=3, Media=2, Baja=1 — refleja que un atraso en Alta impacta más la operatividad
A14: Metas de ciclo (default) | B14: Alta=5 días, Media=9 días, Baja=14 días — ajustables en 2_Parametros
... A19: Limitación / nota | B19: Si KPIS I+D.xlsx trae columnas con otros nombres, mapear al encabezado de 1_Datos. Los datos demo son ilustrativos.

Sheet 7_Snapshot_Resultados
A1: Snapshot calculado (datos demo / última generación del script)
A2: Esta hoja muestra valores ya calculados en Python. Para operación diaria use 4_KPI_Responsables (fórmulas Excel). Al renovar 1_Datos, vuelva a ejecutar el script o confíe en las fórmulas.
A3: Periodo snapshot: Q1 08/2026 (2026-08-01 a 2026-08-15)
A4: Responsable | B4: Ops_Evaluadas | C4: Ops_Completadas | D4: Ops_A_Tiempo | E4: Cumplimiento_Ponderado | F4: Eficiencia_Ciclo_Ponderada | G4: IOI | H4: Semaforo
A5: Ana Pérez | B5: 3 | C5: 3 | D5: 2 | E5: 0.83333333 | F5: 0.97916667 | G5: 0.87708333 | H5: Cumple
A6: Carlos Díaz | B6: 1 | C6: 0 | D6: 0 | E6: 0 | F6: 0.9 | G6: 0.27 | H6: Critico
A7: Luis Gómez | B7: 4 | C7: 4 | D7: 3 | E7: 0.66666667 | F7: 0.83333333 | G7: 0.71666667 | H7: Riesgo
A8: María Ruiz | B8: 1 | C8: 0 | D8: 0 | E8: 0 | F8: 0.41666667 | G8: 0.125 | H8: Critico
A9: Sofía Vargas | B9: 4 | C9: 4 | D9: 3 | E9: 0.875 | F9: 0.984375 | G9: 0.9078125 | H9: Cumple
A10: TOTAL I+D | B10: 13 | C10: 11 | D10: 8 | E10: 0.64285714 | F10: 0.86785714 | G10: 0.71035714 | H10: Riesgo
