Workbook

Sheet INSTRUCCIONES
A1: PLAN DE PRODUCCIÓN MAR / RIO — Guía rápida
A3: 1. Edita celdas AMARILLAS en PARAMETROS (% objetivo, inventario kg, und ya cortadas).
A4: 2. PLAN COLORES recalcula solo con fórmulas (pendiente, objetivo, und final, kg).
A5: 3. Prioridad de tela: P1 Rio KIDS → P2 Mar KIDS → P3-P6 adultos (50% meta).
A6: 4. Lote Mar Kids ya cortado = UND de producción WIP — NO resta kg del inventario.
A7: 5. Detalle por talla en pestañas: RIO KIDS, MAR KIDS, MAR CAB-DAMA, RIO CAB-DAMA.
A9: Orden prioridad:
A10: P1 — RIO KIDS (primero — Mar ya tiene lote en corte)
A11: P2 — MAR KIDS
A12: P3 — MAR CAB | P4 — MAR DAMA | P5 — RIO CAB | P6 — RIO DAMA (50% meta máx)

Sheet PARAMETROS
A1: PARÁMETROS EDITABLES (celdas amarillas)
A3: % Objetivo KIDS | B3: 0.5
A4: % Objetivo CAB/DAMA | B4: 0.5
A6: Inventario tela Jabón (kg) — foto actual
A8: Color | B8: Inventario kg
A9: Azul Marino | B9: 689.9
A10: Negro | B10: 657.16
A11: Aguamarina | B11: 348.34
A12: Azul Rey | B12: 271.46
A13: Azul Lavanda | B13: 221
A14: Lila | B14: 188.44
A15: Vinotinto | B15: 175.38
A16: Blanco | B16: 162.04
A17: Morado | B17: 94.2
A18: Amarillo Neón | B18: 57.94
A19: Gris Claro | B19: 47.68
A20: Verde Militar | B20: 46.02
... A22: Rojo | B22: 0.18
A24: Und ya cortadas Mar KIDS (lote producción — solo descuenta meta)
A26: Color meta Mar KIDS | B26: Und cortadas
A27: Blanco | B27: 0
A28: Azul Marino | B28: 118.2
A29: Negro | B29: 118.2
A30: Lila | B30: 118.2
A31: Aguamarina | B31: 118.2
A32: Rojo | B32: 118.2
A33: Azul Rey | B33: 118.2
A34: Verde Militar | B34: 118.2
A35: Rosado Pastel | B35: 118.2
A36: Púrpura | B36: 0
A37: Azul Lavanda | B37: 118.2
A38: Amarillo Neón | B38: 0

Sheet METAS
A1: Modelo | B1: Género | C1: Color | D1: Meta máx Excel
A2: MAR | B2: KIDS | C2: Blanco | D2: 460
A3: MAR | B3: KIDS | C3: Azul Marino | D3: 409
A4: MAR | B4: KIDS | C4: Negro | D4: 379
A5: MAR | B5: KIDS | C5: Lila | D5: 254
A6: MAR | B6: KIDS | C6: Aguamarina | D6: 243
A7: MAR | B7: KIDS | C7: Rojo | D7: 239
A8: MAR | B8: KIDS | C8: Azul Rey | D8: 232
A9: MAR | B9: KIDS | C9: Verde Militar | D9: 224
A10: MAR | B10: KIDS | C10: Rosado Pastel | D10: 214
A11: MAR | B11: KIDS | C11: Púrpura | D11: 180
A12: MAR | B12: KIDS | C12: Azul Lavanda | D12: 153
A13: MAR | B13: KIDS | C13: Amarillo Neón | D13: 114
... A71: RIO | B71: DAMA | C71: Amarillo Neón | D71: 62

Sheet MIX TALLAS
A1: Modelo | B1: Género | C1: Color | D1: Talla | E1: Und máx Excel | F1: Total color
A2: MAR | B2: CAB | C2: Negro | D2: S | E2: 90 | F2: 555
A3: MAR | B3: CAB | C3: Negro | D3: M | E3: 169 | F3: 555
A4: MAR | B4: CAB | C4: Negro | D4: L | E4: 162 | F4: 555
A5: MAR | B5: CAB | C5: Negro | D5: XL | E5: 88 | F5: 555
A6: MAR | B6: CAB | C6: Negro | D6: 2XL | E6: 46 | F6: 555
A7: MAR | B7: CAB | C7: Azul Marino | D7: S | E7: 77 | F7: 473
A8: MAR | B8: CAB | C8: Azul Marino | D8: M | E8: 144 | F8: 473
A9: MAR | B9: CAB | C9: Azul Marino | D9: L | E9: 138 | F9: 473
A10: MAR | B10: CAB | C10: Azul Marino | D10: XL | E10: 75 | F10: 473
A11: MAR | B11: CAB | C11: Azul Marino | D11: 2XL | E11: 39 | F11: 473
A12: MAR | B12: CAB | C12: Blanco | D12: S | E12: 63 | F12: 390
A13: MAR | B13: CAB | C13: Blanco | D13: M | E13: 119 | F13: 390
... A399: RIO | B399: KIDS | C399: Amarillo Neón | D399: 14 | E399: 17 | F399: 130

Sheet PLAN COLORES
A1: P | B1: Línea | C1: Modelo | D1: Género | E1: Color | F1: Meta máx | G1: Ya cortado | H1: Pendiente | I1: % Obj | J1: Und objetivo | K1: Consumo kg/und | L1: Inventario kg | M1: Kg usado antes | N1: Saldo kg | O1: Und max tela | P1: Und FINAL | Q1: Kg usar | R1: Estado
A2: 1 | B2: RIO KIDS | C2: RIO | D2: KIDS | E2: Azul Marino | F2: 361 | G2: =IF(AND(C2="MAR",D2="KIDS"),IFERROR(INDEX(PARAMETROS!$B$27:$B$38,MATCH(E2,PARAMETROS!$A$27:$A$38,0)),0),0) | H2: =MAX(0,F2-G2) | I2: =IF(D2="KIDS",PARAMETROS!$B$3,PARAMETROS!$B$4) | J2: =ROUND(H2*I2,0) | K2: 0.32 | L2: =IFERROR(INDEX(PARAMETROS!$B$9:$B$22,MATCH(E2,PARAMETROS!$A$9:$A$22,0)),IFERROR(INDEX(PARAMETROS!$B$9:$B$22,MATCH("Morado",PARAMETROS!$A$9:$A$22,0)),0)) | M2: 0 | N2: =MAX(0,L2-M2) | O2: =IF(N2<5.0,0,FLOOR(N2/K2,1)) | P2: =MIN(J2,O2) | Q2: =P2*K2 | R2: =IF(P2=0,"SIN TELA",IF(P2<J2,"PARCIAL","OK"))
A3: 1 | B3: RIO KIDS | C3: RIO | D3: KIDS | E3: Azul Lavanda | F3: 351 | G3: =IF(AND(C3="MAR",D3="KIDS"),IFERROR(INDEX(PARAMETROS!$B$27:$B$38,MATCH(E3,PARAMETROS!$A$27:$A$38,0)),0),0) | H3: =MAX(0,F3-G3) | I3: =IF(D3="KIDS",PARAMETROS!$B$3,PARAMETROS!$B$4) | J3: =ROUND(H3*I3,0) | K3: 0.32 | L3: =IFERROR(INDEX(PARAMETROS!$B$9:$B$22,MATCH(E3,PARAMETROS!$A$9:$A$22,0)),IFERROR(INDEX(PARAMETROS!$B$9:$B$22,MATCH("Morado",PARAMETROS!$A$9:$A$22,0)),0)) | M3: =SUMIFS($Q$2:Q2,$E$2:$E2,E3) | N3: =MAX(0,L3-M3) | O3: =IF(N3<5.0,0,FLOOR(N3/K3,1)) | P3: =MIN(J3,O3) | Q3: =P3*K3 | R3: =IF(P3=0,"SIN TELA",IF(P3<J3,"PARCIAL","OK"))
A4: 1 | B4: RIO KIDS | C4: RIO | D4: KIDS | E4: Negro | F4: 317 | G4: =IF(AND(C4="MAR",D4="KIDS"),IFERROR(INDEX(PARAMETROS!$B$27:$B$38,MATCH(E4,PARAMETROS!$A$27:$A$38,0)),0),0) | H4: =MAX(0,F4-G4) | I4: =IF(D4="KIDS",PARAMETROS!$B$3,PARAMETROS!$B$4) | J4: =ROUND(H4*I4,0) | K4: 0.32 | L4: =IFERROR(INDEX(PARAMETROS!$B$9:$B$22,MATCH(E4,PARAMETROS!$A$9:$A$22,0)),IFERROR(INDEX(PARAMETROS!$B$9:$B$22,MATCH("Morado",PARAMETROS!$A$9:$A$22,0)),0)) | M4: =SUMIFS($Q$2:Q3,$E$2:$E3,E4) | N4: =MAX(0,L4-M4) | O4: =IF(N4<5.0,0,FLOOR(N4/K4,1)) | P4: =MIN(J4,O4) | Q4: =P4*K4 | R4: =IF(P4=0,"SIN TELA",IF(P4<J4,"PARCIAL","OK"))
A5: 1 | B5: RIO KIDS | C5: RIO | D5: KIDS | E5: Lila | F5: 294 | G5: =IF(AND(C5="MAR",D5="KIDS"),IFERROR(INDEX(PARAMETROS!$B$27:$B$38,MATCH(E5,PARAMETROS!$A$27:$A$38,0)),0),0) | H5: =MAX(0,F5-G5) | I5: =IF(D5="KIDS",PARAMETROS!$B$3,PARAMETROS!$B$4) | J5: =ROUND(H5*I5,0) | K5: 0.32 | L5: =IFERROR(INDEX(PARAMETROS!$B$9:$B$22,MATCH(E5,PARAMETROS!$A$9:$A$22,0)),IFERROR(INDEX(PARAMETROS!$B$9:$B$22,MATCH("Morado",PARAMETROS!$A$9:$A$22,0)),0)) | M5: =SUMIFS($Q$2:Q4,$E$2:$E4,E5) | N5: =MAX(0,L5-M5) | O5: =IF(N5<5.0,0,FLOOR(N5/K5,1)) | P5: =MIN(J5,O5) | Q5: =P5*K5 | R5: =IF(P5=0,"SIN TELA",IF(P5<J5,"PARCIAL","OK"))
A6: 1 | B6: RIO KIDS | C6: RIO | D6: KIDS | E6: Azul Rey | F6: 284 | G6: =IF(AND(C6="MAR",D6="KIDS"),IFERROR(INDEX(PARAMETROS!$B$27:$B$38,MATCH(E6,PARAMETROS!$A$27:$A$38,0)),0),0) | H6: =MAX(0,F6-G6) | I6: =IF(D6="KIDS",PARAMETROS!$B$3,PARAMETROS!$B$4) | J6: =ROUND(H6*I6,0) | K6: 0.32 | L6: =IFERROR(INDEX(PARAMETROS!$B$9:$B$22,MATCH(E6,PARAMETROS!$A$9:$A$22,0)),IFERROR(INDEX(PARAMETROS!$B$9:$B$22,MATCH("Morado",PARAMETROS!$A$9:$A$22,0)),0)) | M6: =SUMIFS($Q$2:Q5,$E$2:$E5,E6) | N6: =MAX(0,L6-M6) | O6: =IF(N6<5.0,0,FLOOR(N6/K6,1)) | P6: =MIN(J6,O6) | Q6: =P6*K6 | R6: =IF(P6=0,"SIN TELA",IF(P6<J6,"PARCIAL","OK"))
A7: 1 | B7: RIO KIDS | C7: RIO | D7: KIDS | E7: Rojo | F7: 260 | G7: =IF(AND(C7="MAR",D7="KIDS"),IFERROR(INDEX(PARAMETROS!$B$27:$B$38,MATCH(E7,PARAMETROS!$A$27:$A$38,0)),0),0) | H7: =MAX(0,F7-G7) | I7: =IF(D7="KIDS",PARAMETROS!$B$3,PARAMETROS!$B$4) | J7: =ROUND(H7*I7,0) | K7: 0.32 | L7: =IFERROR(INDEX(PARAMETROS!$B$9:$B$22,MATCH(E7,PARAMETROS!$A$9:$A$22,0)),IFERROR(INDEX(PARAMETROS!$B$9:$B$22,MATCH("Morado",PARAMETROS!$A$9:$A$22,0)),0)) | M7: =SUMIFS($Q$2:Q6,$E$2:$E6,E7) | N7: =MAX(0,L7-M7) | O7: =IF(N7<5.0,0,FLOOR(N7/K7,1)) | P7: =MIN(J7,O7) | Q7: =P7*K7 | R7: =IF(P7=0,"SIN TELA",IF(P7<J7,"PARCIAL","OK"))
A8: 1 | B8: RIO KIDS | C8: RIO | D8: KIDS | E8: Blanco | F8: 224 | G8: =IF(AND(C8="MAR",D8="KIDS"),IFERROR(INDEX(PARAMETROS!$B$27:$B$38,MATCH(E8,PARAMETROS!$A$27:$A$38,0)),0),0) | H8: =MAX(0,F8-G8) | I8: =IF(D8="KIDS",PARAMETROS!$B$3,PARAMETROS!$B$4) | J8: =ROUND(H8*I8,0) | K8: 0.32 | L8: =IFERROR(INDEX(PARAMETROS!$B$9:$B$22,MATCH(E8,PARAMETROS!$A$9:$A$22,0)),IFERROR(INDEX(PARAMETROS!$B$9:$B$22,MATCH("Morado",PARAMETROS!$A$9:$A$22,0)),0)) | M8: =SUMIFS($Q$2:Q7,$E$2:$E7,E8) | N8: =MAX(0,L8-M8) | O8: =IF(N8<5.0,0,FLOOR(N8/K8,1)) | P8: =MIN(J8,O8) | Q8: =P8*K8 | R8: =IF(P8=0,"SIN TELA",IF(P8<J8,"PARCIAL","OK"))
A9: 1 | B9: RIO KIDS | C9: RIO | D9: KIDS | E9: Púrpura | F9: 212 | G9: =IF(AND(C9="MAR",D9="KIDS"),IFERROR(INDEX(PARAMETROS!$B$27:$B$38,MATCH(E9,PARAMETROS!$A$27:$A$38,0)),0),0) | H9: =MAX(0,F9-G9) | I9: =IF(D9="KIDS",PARAMETROS!$B$3,PARAMETROS!$B$4) | J9: =ROUND(H9*I9,0) | K9: 0.32 | L9: =IFERROR(INDEX(PARAMETROS!$B$9:$B$22,MATCH(E9,PARAMETROS!$A$9:$A$22,0)),IFERROR(INDEX(PARAMETROS!$B$9:$B$22,MATCH("Morado",PARAMETROS!$A$9:$A$22,0)),0)) | M9: =SUMIFS($Q$2:Q8,$E$2:$E8,E9) | N9: =MAX(0,L9-M9) | O9: =IF(N9<5.0,0,FLOOR(N9/K9,1)) | P9: =MIN(J9,O9) | Q9: =P9*K9 | R9: =IF(P9=0,"SIN TELA",IF(P9<J9,"PARCIAL","OK"))
A10: 1 | B10: RIO KIDS | C10: RIO | D10: KIDS | E10: Aguamarina | F10: 215 | G10: =IF(AND(C10="MAR",D10="KIDS"),IFERROR(INDEX(PARAMETROS!$B$27:$B$38,MATCH(E10,PARAMETROS!$A$27:$A$38,0)),0),0) | H10: =MAX(0,F10-G10) | I10: =IF(D10="KIDS",PARAMETROS!$B$3,PARAMETROS!$B$4) | J10: =ROUND(H10*I10,0) | K10: 0.32 | L10: =IFERROR(INDEX(PARAMETROS!$B$9:$B$22,MATCH(E10,PARAMETROS!$A$9:$A$22,0)),IFERROR(INDEX(PARAMETROS!$B$9:$B$22,MATCH("Morado",PARAMETROS!$A$9:$A$22,0)),0)) | M10: =SUMIFS($Q$2:Q9,$E$2:$E9,E10) | N10: =MAX(0,L10-M10) | O10: =IF(N10<5.0,0,FLOOR(N10/K10,1)) | P10: =MIN(J10,O10) | Q10: =P10*K10 | R10: =IF(P10=0,"SIN TELA",IF(P10<J10,"PARCIAL","OK"))
A11: 1 | B11: RIO KIDS | C11: RIO | D11: KIDS | E11: Verde Militar | F11: 162 | G11: =IF(AND(C11="MAR",D11="KIDS"),IFERROR(INDEX(PARAMETROS!$B$27:$B$38,MATCH(E11,PARAMETROS!$A$27:$A$38,0)),0),0) | H11: =MAX(0,F11-G11) | I11: =IF(D11="KIDS",PARAMETROS!$B$3,PARAMETROS!$B$4) | J11: =ROUND(H11*I11,0) | K11: 0.32 | L11: =IFERROR(INDEX(PARAMETROS!$B$9:$B$22,MATCH(E11,PARAMETROS!$A$9:$A$22,0)),IFERROR(INDEX(PARAMETROS!$B$9:$B$22,MATCH("Morado",PARAMETROS!$A$9:$A$22,0)),0)) | M11: =SUMIFS($Q$2:Q10,$E$2:$E10,E11) | N11: =MAX(0,L11-M11) | O11: =IF(N11<5.0,0,FLOOR(N11/K11,1)) | P11: =MIN(J11,O11) | Q11: =P11*K11 | R11: =IF(P11=0,"SIN TELA",IF(P11<J11,"PARCIAL","OK"))
A12: 1 | B12: RIO KIDS | C12: RIO | D12: KIDS | E12: Rosado Pastel | F12: 142 | G12: =IF(AND(C12="MAR",D12="KIDS"),IFERROR(INDEX(PARAMETROS!$B$27:$B$38,MATCH(E12,PARAMETROS!$A$27:$A$38,0)),0),0) | H12: =MAX(0,F12-G12) | I12: =IF(D12="KIDS",PARAMETROS!$B$3,PARAMETROS!$B$4) | J12: =ROUND(H12*I12,0) | K12: 0.32 | L12: =IFERROR(INDEX(PARAMETROS!$B$9:$B$22,MATCH(E12,PARAMETROS!$A$9:$A$22,0)),IFERROR(INDEX(PARAMETROS!$B$9:$B$22,MATCH("Morado",PARAMETROS!$A$9:$A$22,0)),0)) | M12: =SUMIFS($Q$2:Q11,$E$2:$E11,E12) | N12: =MAX(0,L12-M12) | O12: =IF(N12<5.0,0,FLOOR(N12/K12,1)) | P12: =MIN(J12,O12) | Q12: =P12*K12 | R12: =IF(P12=0,"SIN TELA",IF(P12<J12,"PARCIAL","OK"))
A13: 1 | B13: RIO KIDS | C13: RIO | D13: KIDS | E13: Amarillo Neón | F13: 130 | G13: =IF(AND(C13="MAR",D13="KIDS"),IFERROR(INDEX(PARAMETROS!$B$27:$B$38,MATCH(E13,PARAMETROS!$A$27:$A$38,0)),0),0) | H13: =MAX(0,F13-G13) | I13: =IF(D13="KIDS",PARAMETROS!$B$3,PARAMETROS!$B$4) | J13: =ROUND(H13*I13,0) | K13: 0.32 | L13: =IFERROR(INDEX(PARAMETROS!$B$9:$B$22,MATCH(E13,PARAMETROS!$A$9:$A$22,0)),IFERROR(INDEX(PARAMETROS!$B$9:$B$22,MATCH("Morado",PARAMETROS!$A$9:$A$22,0)),0)) | M13: =SUMIFS($Q$2:Q12,$E$2:$E12,E13) | N13: =MAX(0,L13-M13) | O13: =IF(N13<5.0,0,FLOOR(N13/K13,1)) | P13: =MIN(J13,O13) | Q13: =P13*K13 | R13: =IF(P13=0,"SIN TELA",IF(P13<J13,"PARCIAL","OK"))
A14: 2 | B14: MAR KIDS | C14: MAR | D14: KIDS | E14: Blanco | F14: 460 | G14: =IF(AND(C14="MAR",D14="KIDS"),IFERROR(INDEX(PARAMETROS!$B$27:$B$38,MATCH(E14,PARAMETROS!$A$27:$A$38,0)),0),0) | H14: =MAX(0,F14-G14) | I14: =IF(D14="KIDS",PARAMETROS!$B$3,PARAMETROS!$B$4) | J14: =ROUND(H14*I14,0) | K14: 0.26 | L14: =IFERROR(INDEX(PARAMETROS!$B$9:$B$22,MATCH(E14,PARAMETROS!$A$9:$A$22,0)),IFERROR(INDEX(PARAMETROS!$B$9:$B$22,MATCH("Morado",PARAMETROS!$A$9:$A$22,0)),0)) | M14: =SUMIFS($Q$2:Q13,$E$2:$E13,E14) | N14: =MAX(0,L14-M14) | O14: =IF(N14<5.0,0,FLOOR(N14/K14,1)) | P14: =MIN(J14,O14) | Q14: =P14*K14 | R14: =IF(P14=0,"SIN TELA",IF(P14<J14,"PARCIAL","OK"))
... A71: 6 | B71: RIO DAMA | C71: RIO | D71: DAMA | E71: Amarillo Neón | F71: 62 | G71: =IF(AND(C71="MAR",D71="KIDS"),IFERROR(INDEX(PARAMETROS!$B$27:$B$38,MATCH(E71,PARAMETROS!$A$27:$A$38,0)),0),0) | H71: =MAX(0,F71-G71) | I71: =IF(D71="KIDS",PARAMETROS!$B$3,PARAMETROS!$B$4) | J71: =ROUND(H71*I71,0) | K71: 0.52 | L71: =IFERROR(INDEX(PARAMETROS!$B$9:$B$22,MATCH(E71,PARAMETROS!$A$9:$A$22,0)),IFERROR(INDEX(PARAMETROS!$B$9:$B$22,MATCH("Morado",PARAMETROS!$A$9:$A$22,0)),0)) | M71: =SUMIFS($Q$2:Q70,$E$2:$E70,E71) | N71: =MAX(0,L71-M71) | O71: =IF(N71<5.0,0,FLOOR(N71/K71,1)) | P71: =MIN(J71,O71) | Q71: =P71*K71 | R71: =IF(P71=0,"SIN TELA",IF(P71<J71,"PARCIAL","OK"))
B73: TOTALES | P73: =SUM(P2:P71) | Q73: =SUM(Q2:Q71)

Sheet RIO KIDS
A1: Modelo | B1: Género | C1: Color | D1: Talla | E1: Und máx Excel (mix) | F1: Total color Excel | G1: Und FINAL color | H1: Und talla A PRODUCIR
A2: RIO | B2: KIDS | C2: Azul Marino | D2: 10 | E2: 35 | F2: 361 | G2: ='PLAN COLORES'!P2 | H2: =IF(G2=0,0,IF(F2=0,0,ROUND(G2*E2/F2,0)))
A3: RIO | B3: KIDS | C3: Azul Marino | D3: 12 | E3: 48 | F3: 361 | G3: ='PLAN COLORES'!P2 | H3: =IF(G3=0,0,IF(F3=0,0,ROUND(G3*E3/F3,0)))
A4: RIO | B4: KIDS | C4: Azul Marino | D4: 14 | E4: 60 | F4: 361 | G4: ='PLAN COLORES'!P2 | H4: =IF(G4=0,0,IF(F4=0,0,ROUND(G4*E4/F4,0)))
A5: RIO | B5: KIDS | C5: Azul Marino | D5: 2 | E5: 49 | F5: 361 | G5: ='PLAN COLORES'!P2 | H5: =IF(G5=0,0,IF(F5=0,0,ROUND(G5*E5/F5,0)))
A6: RIO | B6: KIDS | C6: Azul Marino | D6: 4 | E6: 65 | F6: 361 | G6: ='PLAN COLORES'!P2 | H6: =IF(G6=0,0,IF(F6=0,0,ROUND(G6*E6/F6,0)))
A7: RIO | B7: KIDS | C7: Azul Marino | D7: 6 | E7: 55 | F7: 361 | G7: ='PLAN COLORES'!P2 | H7: =IF(G7=0,0,IF(F7=0,0,ROUND(G7*E7/F7,0)))
A8: RIO | B8: KIDS | C8: Azul Marino | D8: 8 | E8: 49 | F8: 361 | G8: ='PLAN COLORES'!P2 | H8: =IF(G8=0,0,IF(F8=0,0,ROUND(G8*E8/F8,0)))
A9: RIO | B9: KIDS | C9: Azul Lavanda | D9: 10 | E9: 50 | F9: 351 | G9: ='PLAN COLORES'!P3 | H9: =IF(G9=0,0,IF(F9=0,0,ROUND(G9*E9/F9,0)))
A10: RIO | B10: KIDS | C10: Azul Lavanda | D10: 12 | E10: 67 | F10: 351 | G10: ='PLAN COLORES'!P3 | H10: =IF(G10=0,0,IF(F10=0,0,ROUND(G10*E10/F10,0)))
A11: RIO | B11: KIDS | C11: Azul Lavanda | D11: 14 | E11: 14 | F11: 351 | G11: ='PLAN COLORES'!P3 | H11: =IF(G11=0,0,IF(F11=0,0,ROUND(G11*E11/F11,0)))
A12: RIO | B12: KIDS | C12: Azul Lavanda | D12: 2 | E12: 64 | F12: 351 | G12: ='PLAN COLORES'!P3 | H12: =IF(G12=0,0,IF(F12=0,0,ROUND(G12*E12/F12,0)))
A13: RIO | B13: KIDS | C13: Azul Lavanda | D13: 4 | E13: 48 | F13: 351 | G13: ='PLAN COLORES'!P3 | H13: =IF(G13=0,0,IF(F13=0,0,ROUND(G13*E13/F13,0)))
A14: RIO | B14: KIDS | C14: Azul Lavanda | D14: 6 | E14: 48 | F14: 351 | G14: ='PLAN COLORES'!P3 | H14: =IF(G14=0,0,IF(F14=0,0,ROUND(G14*E14/F14,0)))
A15: RIO | B15: KIDS | C15: Azul Lavanda | D15: 8 | E15: 60 | F15: 351 | G15: ='PLAN COLORES'!P3 | H15: =IF(G15=0,0,IF(F15=0,0,ROUND(G15*E15/F15,0)))
A16: RIO | B16: KIDS | C16: Negro | D16: 10 | E16: 52 | F16: 317 | G16: ='PLAN COLORES'!P4 | H16: =IF(G16=0,0,IF(F16=0,0,ROUND(G16*E16/F16,0)))
A17: RIO | B17: KIDS | C17: Negro | D17: 12 | E17: 59 | F17: 317 | G17: ='PLAN COLORES'!P4 | H17: =IF(G17=0,0,IF(F17=0,0,ROUND(G17*E17/F17,0)))
A18: RIO | B18: KIDS | C18: Negro | D18: 14 | E18: 41 | F18: 317 | G18: ='PLAN COLORES'!P4 | H18: =IF(G18=0,0,IF(F18=0,0,ROUND(G18*E18/F18,0)))
A19: RIO | B19: KIDS | C19: Negro | D19: 2 | E19: 41 | F19: 317 | G19: ='PLAN COLORES'!P4 | H19: =IF(G19=0,0,IF(F19=0,0,ROUND(G19*E19/F19,0)))
A20: RIO | B20: KIDS | C20: Negro | D20: 4 | E20: 33 | F20: 317 | G20: ='PLAN COLORES'!P4 | H20: =IF(G20=0,0,IF(F20=0,0,ROUND(G20*E20/F20,0)))
A21: RIO | B21: KIDS | C21: Negro | D21: 6 | E21: 39 | F21: 317 | G21: ='PLAN COLORES'!P4 | H21: =IF(G21=0,0,IF(F21=0,0,ROUND(G21*E21/F21,0)))
A22: RIO | B22: KIDS | C22: Negro | D22: 8 | E22: 52 | F22: 317 | G22: ='PLAN COLORES'!P4 | H22: =IF(G22=0,0,IF(F22=0,0,ROUND(G22*E22/F22,0)))
A23: RIO | B23: KIDS | C23: Lila | D23: 10 | E23: 49 | F23: 294 | G23: ='PLAN COLORES'!P5 | H23: =IF(G23=0,0,IF(F23=0,0,ROUND(G23*E23/F23,0)))
A24: RIO | B24: KIDS | C24: Lila | D24: 12 | E24: 41 | F24: 294 | G24: ='PLAN COLORES'!P5 | H24: =IF(G24=0,0,IF(F24=0,0,ROUND(G24*E24/F24,0)))
A25: RIO | B25: KIDS | C25: Lila | D25: 14 | E25: 43 | F25: 294 | G25: ='PLAN COLORES'!P5 | H25: =IF(G25=0,0,IF(F25=0,0,ROUND(G25*E25/F25,0)))
A26: RIO | B26: KIDS | C26: Lila | D26: 2 | E26: 35 | F26: 294 | G26: ='PLAN COLORES'!P5 | H26: =IF(G26=0,0,IF(F26=0,0,ROUND(G26*E26/F26,0)))
A27: RIO | B27: KIDS | C27: Lila | D27: 4 | E27: 42 | F27: 294 | G27: ='PLAN COLORES'!P5 | H27: =IF(G27=0,0,IF(F27=0,0,ROUND(G27*E27/F27,0)))
A28: RIO | B28: KIDS | C28: Lila | D28: 6 | E28: 33 | F28: 294 | G28: ='PLAN COLORES'!P5 | H28: =IF(G28=0,0,IF(F28=0,0,ROUND(G28*E28/F28,0)))
A29: RIO | B29: KIDS | C29: Lila | D29: 8 | E29: 51 | F29: 294 | G29: ='PLAN COLORES'!P5 | H29: =IF(G29=0,0,IF(F29=0,0,ROUND(G29*E29/F29,0)))
A30: RIO | B30: KIDS | C30: Azul Rey | D30: 10 | E30: 46 | F30: 284 | G30: ='PLAN COLORES'!P6 | H30: =IF(G30=0,0,IF(F30=0,0,ROUND(G30*E30/F30,0)))
A31: RIO | B31: KIDS | C31: Azul Rey | D31: 12 | E31: 50 | F31: 284 | G31: ='PLAN COLORES'!P6 | H31: =IF(G31=0,0,IF(F31=0,0,ROUND(G31*E31/F31,0)))
A32: RIO | B32: KIDS | C32: Azul Rey | D32: 14 | E32: 27 | F32: 284 | G32: ='PLAN COLORES'!P6 | H32: =IF(G32=0,0,IF(F32=0,0,ROUND(G32*E32/F32,0)))
A33: RIO | B33: KIDS | C33: Azul Rey | D33: 2 | E33: 33 | F33: 284 | G33: ='PLAN COLORES'!P6 | H33: =IF(G33=0,0,IF(F33=0,0,ROUND(G33*E33/F33,0)))
A34: RIO | B34: KIDS | C34: Azul Rey | D34: 4 | E34: 41 | F34: 284 | G34: ='PLAN COLORES'!P6 | H34: =IF(G34=0,0,IF(F34=0,0,ROUND(G34*E34/F34,0)))
A35: RIO | B35: KIDS | C35: Azul Rey | D35: 6 | E35: 44 | F35: 284 | G35: ='PLAN COLORES'!P6 | H35: =IF(G35=0,0,IF(F35=0,0,ROUND(G35*E35/F35,0)))
A36: RIO | B36: KIDS | C36: Azul Rey | D36: 8 | E36: 43 | F36: 284 | G36: ='PLAN COLORES'!P6 | H36: =IF(G36=0,0,IF(F36=0,0,ROUND(G36*E36/F36,0)))
A37: RIO | B37: KIDS | C37: Rojo | D37: 10 | E37: 31 | F37: 260 | G37: ='PLAN COLORES'!P7 | H37: =IF(G37=0,0,IF(F37=0,0,ROUND(G37*E37/F37,0)))
A38: RIO | B38: KIDS | C38: Rojo | D38: 12 | E38: 31 | F38: 260 | G38: ='PLAN COLORES'!P7 | H38: =IF(G38=0,0,IF(F38=0,0,ROUND(G38*E38/F38,0)))
A39: RIO | B39: KIDS | C39: Rojo | D39: 14 | E39: 33 | F39: 260 | G39: ='PLAN COLORES'!P7 | H39: =IF(G39=0,0,IF(F39=0,0,ROUND(G39*E39/F39,0)))
A40: RIO | B40: KIDS | C40: Rojo | D40: 2 | E40: 34 | F40: 260 | G40: ='PLAN COLORES'!P7 | H40: =IF(G40=0,0,IF(F40=0,0,ROUND(G40*E40/F40,0)))
...

Sheet MAR KIDS
A1: Modelo | B1: Género | C1: Color | D1: Talla | E1: Und máx Excel (mix) | F1: Total color Excel | G1: Und FINAL color | H1: Und talla A PRODUCIR
A2: MAR | B2: KIDS | C2: Blanco | D2: 10 | E2: 67 | F2: 460 | G2: ='PLAN COLORES'!P14 | H2: =IF(G2=0,0,IF(F2=0,0,ROUND(G2*E2/F2,0)))
A3: MAR | B3: KIDS | C3: Blanco | D3: 12 | E3: 73 | F3: 460 | G3: ='PLAN COLORES'!P14 | H3: =IF(G3=0,0,IF(F3=0,0,ROUND(G3*E3/F3,0)))
A4: MAR | B4: KIDS | C4: Blanco | D4: 14 | E4: 77 | F4: 460 | G4: ='PLAN COLORES'!P14 | H4: =IF(G4=0,0,IF(F4=0,0,ROUND(G4*E4/F4,0)))
A5: MAR | B5: KIDS | C5: Blanco | D5: 2 | E5: 53 | F5: 460 | G5: ='PLAN COLORES'!P14 | H5: =IF(G5=0,0,IF(F5=0,0,ROUND(G5*E5/F5,0)))
A6: MAR | B6: KIDS | C6: Blanco | D6: 4 | E6: 53 | F6: 460 | G6: ='PLAN COLORES'!P14 | H6: =IF(G6=0,0,IF(F6=0,0,ROUND(G6*E6/F6,0)))
A7: MAR | B7: KIDS | C7: Blanco | D7: 6 | E7: 71 | F7: 460 | G7: ='PLAN COLORES'!P14 | H7: =IF(G7=0,0,IF(F7=0,0,ROUND(G7*E7/F7,0)))
A8: MAR | B8: KIDS | C8: Blanco | D8: 8 | E8: 66 | F8: 460 | G8: ='PLAN COLORES'!P14 | H8: =IF(G8=0,0,IF(F8=0,0,ROUND(G8*E8/F8,0)))
A9: MAR | B9: KIDS | C9: Azul Marino | D9: 10 | E9: 59 | F9: 410 | G9: ='PLAN COLORES'!P15 | H9: =IF(G9=0,0,IF(F9=0,0,ROUND(G9*E9/F9,0)))
A10: MAR | B10: KIDS | C10: Azul Marino | D10: 12 | E10: 65 | F10: 410 | G10: ='PLAN COLORES'!P15 | H10: =IF(G10=0,0,IF(F10=0,0,ROUND(G10*E10/F10,0)))
A11: MAR | B11: KIDS | C11: Azul Marino | D11: 14 | E11: 69 | F11: 410 | G11: ='PLAN COLORES'!P15 | H11: =IF(G11=0,0,IF(F11=0,0,ROUND(G11*E11/F11,0)))
A12: MAR | B12: KIDS | C12: Azul Marino | D12: 2 | E12: 47 | F12: 410 | G12: ='PLAN COLORES'!P15 | H12: =IF(G12=0,0,IF(F12=0,0,ROUND(G12*E12/F12,0)))
A13: MAR | B13: KIDS | C13: Azul Marino | D13: 4 | E13: 48 | F13: 410 | G13: ='PLAN COLORES'!P15 | H13: =IF(G13=0,0,IF(F13=0,0,ROUND(G13*E13/F13,0)))
A14: MAR | B14: KIDS | C14: Azul Marino | D14: 6 | E14: 63 | F14: 410 | G14: ='PLAN COLORES'!P15 | H14: =IF(G14=0,0,IF(F14=0,0,ROUND(G14*E14/F14,0)))
A15: MAR | B15: KIDS | C15: Azul Marino | D15: 8 | E15: 59 | F15: 410 | G15: ='PLAN COLORES'!P15 | H15: =IF(G15=0,0,IF(F15=0,0,ROUND(G15*E15/F15,0)))
A16: MAR | B16: KIDS | C16: Negro | D16: 10 | E16: 55 | F16: 379 | G16: ='PLAN COLORES'!P16 | H16: =IF(G16=0,0,IF(F16=0,0,ROUND(G16*E16/F16,0)))
A17: MAR | B17: KIDS | C17: Negro | D17: 12 | E17: 60 | F17: 379 | G17: ='PLAN COLORES'!P16 | H17: =IF(G17=0,0,IF(F17=0,0,ROUND(G17*E17/F17,0)))
A18: MAR | B18: KIDS | C18: Negro | D18: 14 | E18: 64 | F18: 379 | G18: ='PLAN COLORES'!P16 | H18: =IF(G18=0,0,IF(F18=0,0,ROUND(G18*E18/F18,0)))
A19: MAR | B19: KIDS | C19: Negro | D19: 2 | E19: 44 | F19: 379 | G19: ='PLAN COLORES'!P16 | H19: =IF(G19=0,0,IF(F19=0,0,ROUND(G19*E19/F19,0)))
A20: MAR | B20: KIDS | C20: Negro | D20: 4 | E20: 44 | F20: 379 | G20: ='PLAN COLORES'!P16 | H20: =IF(G20=0,0,IF(F20=0,0,ROUND(G20*E20/F20,0)))
A21: MAR | B21: KIDS | C21: Negro | D21: 6 | E21: 58 | F21: 379 | G21: ='PLAN COLORES'!P16 | H21: =IF(G21=0,0,IF(F21=0,0,ROUND(G21*E21/F21,0)))
A22: MAR | B22: KIDS | C22: Negro | D22: 8 | E22: 54 | F22: 379 | G22: ='PLAN COLORES'!P16 | H22: =IF(G22=0,0,IF(F22=0,0,ROUND(G22*E22/F22,0)))
A23: MAR | B23: KIDS | C23: Lila | D23: 10 | E23: 37 | F23: 254 | G23: ='PLAN COLORES'!P17 | H23: =IF(G23=0,0,IF(F23=0,0,ROUND(G23*E23/F23,0)))
A24: MAR | B24: KIDS | C24: Lila | D24: 12 | E24: 40 | F24: 254 | G24: ='PLAN COLORES'!P17 | H24: =IF(G24=0,0,IF(F24=0,0,ROUND(G24*E24/F24,0)))
A25: MAR | B25: KIDS | C25: Lila | D25: 14 | E25: 43 | F25: 254 | G25: ='PLAN COLORES'!P17 | H25: =IF(G25=0,0,IF(F25=0,0,ROUND(G25*E25/F25,0)))
A26: MAR | B26: KIDS | C26: Lila | D26: 2 | E26: 29 | F26: 254 | G26: ='PLAN COLORES'!P17 | H26: =IF(G26=0,0,IF(F26=0,0,ROUND(G26*E26/F26,0)))
A27: MAR | B27: KIDS | C27: Lila | D27: 4 | E27: 30 | F27: 254 | G27: ='PLAN COLORES'!P17 | H27: =IF(G27=0,0,IF(F27=0,0,ROUND(G27*E27/F27,0)))
A28: MAR | B28: KIDS | C28: Lila | D28: 6 | E28: 39 | F28: 254 | G28: ='PLAN COLORES'!P17 | H28: =IF(G28=0,0,IF(F28=0,0,ROUND(G28*E28/F28,0)))
A29: MAR | B29: KIDS | C29: Lila | D29: 8 | E29: 36 | F29: 254 | G29: ='PLAN COLORES'!P17 | H29: =IF(G29=0,0,IF(F29=0,0,ROUND(G29*E29/F29,0)))
A30: MAR | B30: KIDS | C30: Aguamarina | D30: 10 | E30: 35 | F30: 242 | G30: ='PLAN COLORES'!P18 | H30: =IF(G30=0,0,IF(F30=0,0,ROUND(G30*E30/F30,0)))
A31: MAR | B31: KIDS | C31: Aguamarina | D31: 12 | E31: 38 | F31: 242 | G31: ='PLAN COLORES'!P18 | H31: =IF(G31=0,0,IF(F31=0,0,ROUND(G31*E31/F31,0)))
A32: MAR | B32: KIDS | C32: Aguamarina | D32: 14 | E32: 41 | F32: 242 | G32: ='PLAN COLORES'!P18 | H32: =IF(G32=0,0,IF(F32=0,0,ROUND(G32*E32/F32,0)))
A33: MAR | B33: KIDS | C33: Aguamarina | D33: 2 | E33: 28 | F33: 242 | G33: ='PLAN COLORES'!P18 | H33: =IF(G33=0,0,IF(F33=0,0,ROUND(G33*E33/F33,0)))
A34: MAR | B34: KIDS | C34: Aguamarina | D34: 4 | E34: 28 | F34: 242 | G34: ='PLAN COLORES'!P18 | H34: =IF(G34=0,0,IF(F34=0,0,ROUND(G34*E34/F34,0)))
A35: MAR | B35: KIDS | C35: Aguamarina | D35: 6 | E35: 37 | F35: 242 | G35: ='PLAN COLORES'!P18 | H35: =IF(G35=0,0,IF(F35=0,0,ROUND(G35*E35/F35,0)))
A36: MAR | B36: KIDS | C36: Aguamarina | D36: 8 | E36: 35 | F36: 242 | G36: ='PLAN COLORES'!P18 | H36: =IF(G36=0,0,IF(F36=0,0,ROUND(G36*E36/F36,0)))
A37: MAR | B37: KIDS | C37: Rojo | D37: 10 | E37: 35 | F37: 240 | G37: ='PLAN COLORES'!P19 | H37: =IF(G37=0,0,IF(F37=0,0,ROUND(G37*E37/F37,0)))
A38: MAR | B38: KIDS | C38: Rojo | D38: 12 | E38: 38 | F38: 240 | G38: ='PLAN COLORES'!P19 | H38: =IF(G38=0,0,IF(F38=0,0,ROUND(G38*E38/F38,0)))
A39: MAR | B39: KIDS | C39: Rojo | D39: 14 | E39: 40 | F39: 240 | G39: ='PLAN COLORES'!P19 | H39: =IF(G39=0,0,IF(F39=0,0,ROUND(G39*E39/F39,0)))
A40: MAR | B40: KIDS | C40: Rojo | D40: 2 | E40: 28 | F40: 240 | G40: ='PLAN COLORES'!P19 | H40: =IF(G40=0,0,IF(F40=0,0,ROUND(G40*E40/F40,0)))
...

Sheet MAR CAB-DAMA
A1: Modelo | B1: Género | C1: Color | D1: Talla | E1: Und máx Excel (mix) | F1: Total color Excel | G1: Und FINAL color | H1: Und talla A PRODUCIR
A2: MAR | B2: CAB | C2: Negro | D2: 2XL | E2: 46 | F2: 555 | G2: ='PLAN COLORES'!P26 | H2: =IF(G2=0,0,IF(F2=0,0,ROUND(G2*E2/F2,0)))
A3: MAR | B3: CAB | C3: Negro | D3: L | E3: 162 | F3: 555 | G3: ='PLAN COLORES'!P26 | H3: =IF(G3=0,0,IF(F3=0,0,ROUND(G3*E3/F3,0)))
A4: MAR | B4: CAB | C4: Negro | D4: M | E4: 169 | F4: 555 | G4: ='PLAN COLORES'!P26 | H4: =IF(G4=0,0,IF(F4=0,0,ROUND(G4*E4/F4,0)))
A5: MAR | B5: CAB | C5: Negro | D5: S | E5: 90 | F5: 555 | G5: ='PLAN COLORES'!P26 | H5: =IF(G5=0,0,IF(F5=0,0,ROUND(G5*E5/F5,0)))
A6: MAR | B6: CAB | C6: Negro | D6: XL | E6: 88 | F6: 555 | G6: ='PLAN COLORES'!P26 | H6: =IF(G6=0,0,IF(F6=0,0,ROUND(G6*E6/F6,0)))
A7: MAR | B7: CAB | C7: Azul Marino | D7: 2XL | E7: 39 | F7: 473 | G7: ='PLAN COLORES'!P27 | H7: =IF(G7=0,0,IF(F7=0,0,ROUND(G7*E7/F7,0)))
A8: MAR | B8: CAB | C8: Azul Marino | D8: L | E8: 138 | F8: 473 | G8: ='PLAN COLORES'!P27 | H8: =IF(G8=0,0,IF(F8=0,0,ROUND(G8*E8/F8,0)))
A9: MAR | B9: CAB | C9: Azul Marino | D9: M | E9: 144 | F9: 473 | G9: ='PLAN COLORES'!P27 | H9: =IF(G9=0,0,IF(F9=0,0,ROUND(G9*E9/F9,0)))
A10: MAR | B10: CAB | C10: Azul Marino | D10: S | E10: 77 | F10: 473 | G10: ='PLAN COLORES'!P27 | H10: =IF(G10=0,0,IF(F10=0,0,ROUND(G10*E10/F10,0)))
A11: MAR | B11: CAB | C11: Azul Marino | D11: XL | E11: 75 | F11: 473 | G11: ='PLAN COLORES'!P27 | H11: =IF(G11=0,0,IF(F11=0,0,ROUND(G11*E11/F11,0)))
A12: MAR | B12: CAB | C12: Blanco | D12: 2XL | E12: 32 | F12: 390 | G12: ='PLAN COLORES'!P28 | H12: =IF(G12=0,0,IF(F12=0,0,ROUND(G12*E12/F12,0)))
A13: MAR | B13: CAB | C13: Blanco | D13: L | E13: 114 | F13: 390 | G13: ='PLAN COLORES'!P28 | H13: =IF(G13=0,0,IF(F13=0,0,ROUND(G13*E13/F13,0)))
A14: MAR | B14: CAB | C14: Blanco | D14: M | E14: 119 | F14: 390 | G14: ='PLAN COLORES'!P28 | H14: =IF(G14=0,0,IF(F14=0,0,ROUND(G14*E14/F14,0)))
A15: MAR | B15: CAB | C15: Blanco | D15: S | E15: 63 | F15: 390 | G15: ='PLAN COLORES'!P28 | H15: =IF(G15=0,0,IF(F15=0,0,ROUND(G15*E15/F15,0)))
A16: MAR | B16: CAB | C16: Blanco | D16: XL | E16: 62 | F16: 390 | G16: ='PLAN COLORES'!P28 | H16: =IF(G16=0,0,IF(F16=0,0,ROUND(G16*E16/F16,0)))
A17: MAR | B17: CAB | C17: Verde Militar | D17: 2XL | E17: 29 | F17: 355 | G17: ='PLAN COLORES'!P29 | H17: =IF(G17=0,0,IF(F17=0,0,ROUND(G17*E17/F17,0)))
A18: MAR | B18: CAB | C18: Verde Militar | D18: L | E18: 104 | F18: 355 | G18: ='PLAN COLORES'!P29 | H18: =IF(G18=0,0,IF(F18=0,0,ROUND(G18*E18/F18,0)))
A19: MAR | B19: CAB | C19: Verde Militar | D19: M | E19: 108 | F19: 355 | G19: ='PLAN COLORES'!P29 | H19: =IF(G19=0,0,IF(F19=0,0,ROUND(G19*E19/F19,0)))
A20: MAR | B20: CAB | C20: Verde Militar | D20: S | E20: 58 | F20: 355 | G20: ='PLAN COLORES'!P29 | H20: =IF(G20=0,0,IF(F20=0,0,ROUND(G20*E20/F20,0)))
A21: MAR | B21: CAB | C21: Verde Militar | D21: XL | E21: 56 | F21: 355 | G21: ='PLAN COLORES'!P29 | H21: =IF(G21=0,0,IF(F21=0,0,ROUND(G21*E21/F21,0)))
A22: MAR | B22: CAB | C22: Azul Lavanda | D22: 2XL | E22: 22 | F22: 268 | G22: ='PLAN COLORES'!P30 | H22: =IF(G22=0,0,IF(F22=0,0,ROUND(G22*E22/F22,0)))
A23: MAR | B23: CAB | C23: Azul Lavanda | D23: L | E23: 78 | F23: 268 | G23: ='PLAN COLORES'!P30 | H23: =IF(G23=0,0,IF(F23=0,0,ROUND(G23*E23/F23,0)))
A24: MAR | B24: CAB | C24: Azul Lavanda | D24: M | E24: 82 | F24: 268 | G24: ='PLAN COLORES'!P30 | H24: =IF(G24=0,0,IF(F24=0,0,ROUND(G24*E24/F24,0)))
A25: MAR | B25: CAB | C25: Azul Lavanda | D25: S | E25: 43 | F25: 268 | G25: ='PLAN COLORES'!P30 | H25: =IF(G25=0,0,IF(F25=0,0,ROUND(G25*E25/F25,0)))
A26: MAR | B26: CAB | C26: Azul Lavanda | D26: XL | E26: 43 | F26: 268 | G26: ='PLAN COLORES'!P30 | H26: =IF(G26=0,0,IF(F26=0,0,ROUND(G26*E26/F26,0)))
A27: MAR | B27: CAB | C27: Azul Rey | D27: 2XL | E27: 17 | F27: 205 | G27: ='PLAN COLORES'!P31 | H27: =IF(G27=0,0,IF(F27=0,0,ROUND(G27*E27/F27,0)))
A28: MAR | B28: CAB | C28: Azul Rey | D28: L | E28: 60 | F28: 205 | G28: ='PLAN COLORES'!P31 | H28: =IF(G28=0,0,IF(F28=0,0,ROUND(G28*E28/F28,0)))
A29: MAR | B29: CAB | C29: Azul Rey | D29: M | E29: 62 | F29: 205 | G29: ='PLAN COLORES'!P31 | H29: =IF(G29=0,0,IF(F29=0,0,ROUND(G29*E29/F29,0)))
A30: MAR | B30: CAB | C30: Azul Rey | D30: S | E30: 33 | F30: 205 | G30: ='PLAN COLORES'!P31 | H30: =IF(G30=0,0,IF(F30=0,0,ROUND(G30*E30/F30,0)))
A31: MAR | B31: CAB | C31: Azul Rey | D31: XL | E31: 33 | F31: 205 | G31: ='PLAN COLORES'!P31 | H31: =IF(G31=0,0,IF(F31=0,0,ROUND(G31*E31/F31,0)))
A32: MAR | B32: CAB | C32: Gris Claro | D32: 2XL | E32: 16 | F32: 191 | G32: ='PLAN COLORES'!P32 | H32: =IF(G32=0,0,IF(F32=0,0,ROUND(G32*E32/F32,0)))
A33: MAR | B33: CAB | C33: Gris Claro | D33: L | E33: 56 | F33: 191 | G33: ='PLAN COLORES'!P32 | H33: =IF(G33=0,0,IF(F33=0,0,ROUND(G33*E33/F33,0)))
A34: MAR | B34: CAB | C34: Gris Claro | D34: M | E34: 58 | F34: 191 | G34: ='PLAN COLORES'!P32 | H34: =IF(G34=0,0,IF(F34=0,0,ROUND(G34*E34/F34,0)))
A35: MAR | B35: CAB | C35: Gris Claro | D35: S | E35: 31 | F35: 191 | G35: ='PLAN COLORES'!P32 | H35: =IF(G35=0,0,IF(F35=0,0,ROUND(G35*E35/F35,0)))
A36: MAR | B36: CAB | C36: Gris Claro | D36: XL | E36: 30 | F36: 191 | G36: ='PLAN COLORES'!P32 | H36: =IF(G36=0,0,IF(F36=0,0,ROUND(G36*E36/F36,0)))
A37: MAR | B37: CAB | C37: Aguamarina | D37: 2XL | E37: 12 | F37: 150 | G37: ='PLAN COLORES'!P33 | H37: =IF(G37=0,0,IF(F37=0,0,ROUND(G37*E37/F37,0)))
A38: MAR | B38: CAB | C38: Aguamarina | D38: L | E38: 44 | F38: 150 | G38: ='PLAN COLORES'!P33 | H38: =IF(G38=0,0,IF(F38=0,0,ROUND(G38*E38/F38,0)))
A39: MAR | B39: CAB | C39: Aguamarina | D39: M | E39: 46 | F39: 150 | G39: ='PLAN COLORES'!P33 | H39: =IF(G39=0,0,IF(F39=0,0,ROUND(G39*E39/F39,0)))
A40: MAR | B40: CAB | C40: Aguamarina | D40: S | E40: 24 | F40: 150 | G40: ='PLAN COLORES'!P33 | H40: =IF(G40=0,0,IF(F40=0,0,ROUND(G40*E40/F40,0)))
...

Sheet RIO CAB-DAMA
A1: Modelo | B1: Género | C1: Color | D1: Talla | E1: Und máx Excel (mix) | F1: Total color Excel | G1: Und FINAL color | H1: Und talla A PRODUCIR
A2: RIO | B2: CAB | C2: Negro | D2: 2XL | E2: 28 | F2: 557 | G2: ='PLAN COLORES'!P49 | H2: =IF(G2=0,0,IF(F2=0,0,ROUND(G2*E2/F2,0)))
A3: RIO | B3: CAB | C3: Negro | D3: L | E3: 181 | F3: 557 | G3: ='PLAN COLORES'!P49 | H3: =IF(G3=0,0,IF(F3=0,0,ROUND(G3*E3/F3,0)))
A4: RIO | B4: CAB | C4: Negro | D4: M | E4: 157 | F4: 557 | G4: ='PLAN COLORES'!P49 | H4: =IF(G4=0,0,IF(F4=0,0,ROUND(G4*E4/F4,0)))
A5: RIO | B5: CAB | C5: Negro | D5: S | E5: 95 | F5: 557 | G5: ='PLAN COLORES'!P49 | H5: =IF(G5=0,0,IF(F5=0,0,ROUND(G5*E5/F5,0)))
A6: RIO | B6: CAB | C6: Negro | D6: XL | E6: 96 | F6: 557 | G6: ='PLAN COLORES'!P49 | H6: =IF(G6=0,0,IF(F6=0,0,ROUND(G6*E6/F6,0)))
A7: RIO | B7: CAB | C7: Blanco | D7: 2XL | E7: 21 | F7: 356 | G7: ='PLAN COLORES'!P50 | H7: =IF(G7=0,0,IF(F7=0,0,ROUND(G7*E7/F7,0)))
A8: RIO | B8: CAB | C8: Blanco | D8: L | E8: 97 | F8: 356 | G8: ='PLAN COLORES'!P50 | H8: =IF(G8=0,0,IF(F8=0,0,ROUND(G8*E8/F8,0)))
A9: RIO | B9: CAB | C9: Blanco | D9: M | E9: 76 | F9: 356 | G9: ='PLAN COLORES'!P50 | H9: =IF(G9=0,0,IF(F9=0,0,ROUND(G9*E9/F9,0)))
A10: RIO | B10: CAB | C10: Blanco | D10: S | E10: 72 | F10: 356 | G10: ='PLAN COLORES'!P50 | H10: =IF(G10=0,0,IF(F10=0,0,ROUND(G10*E10/F10,0)))
A11: RIO | B11: CAB | C11: Blanco | D11: XL | E11: 90 | F11: 356 | G11: ='PLAN COLORES'!P50 | H11: =IF(G11=0,0,IF(F11=0,0,ROUND(G11*E11/F11,0)))
A12: RIO | B12: CAB | C12: Azul Marino | D12: 2XL | E12: 23 | F12: 336 | G12: ='PLAN COLORES'!P51 | H12: =IF(G12=0,0,IF(F12=0,0,ROUND(G12*E12/F12,0)))
A13: RIO | B13: CAB | C13: Azul Marino | D13: L | E13: 45 | F13: 336 | G13: ='PLAN COLORES'!P51 | H13: =IF(G13=0,0,IF(F13=0,0,ROUND(G13*E13/F13,0)))
A14: RIO | B14: CAB | C14: Azul Marino | D14: M | E14: 99 | F14: 336 | G14: ='PLAN COLORES'!P51 | H14: =IF(G14=0,0,IF(F14=0,0,ROUND(G14*E14/F14,0)))
A15: RIO | B15: CAB | C15: Azul Marino | D15: S | E15: 72 | F15: 336 | G15: ='PLAN COLORES'!P51 | H15: =IF(G15=0,0,IF(F15=0,0,ROUND(G15*E15/F15,0)))
A16: RIO | B16: CAB | C16: Azul Marino | D16: XL | E16: 97 | F16: 336 | G16: ='PLAN COLORES'!P51 | H16: =IF(G16=0,0,IF(F16=0,0,ROUND(G16*E16/F16,0)))
A17: RIO | B17: CAB | C17: Azul Rey | D17: 2XL | E17: 32 | F17: 277 | G17: ='PLAN COLORES'!P52 | H17: =IF(G17=0,0,IF(F17=0,0,ROUND(G17*E17/F17,0)))
A18: RIO | B18: CAB | C18: Azul Rey | D18: L | E18: 66 | F18: 277 | G18: ='PLAN COLORES'!P52 | H18: =IF(G18=0,0,IF(F18=0,0,ROUND(G18*E18/F18,0)))
A19: RIO | B19: CAB | C19: Azul Rey | D19: M | E19: 60 | F19: 277 | G19: ='PLAN COLORES'!P52 | H19: =IF(G19=0,0,IF(F19=0,0,ROUND(G19*E19/F19,0)))
A20: RIO | B20: CAB | C20: Azul Rey | D20: S | E20: 58 | F20: 277 | G20: ='PLAN COLORES'!P52 | H20: =IF(G20=0,0,IF(F20=0,0,ROUND(G20*E20/F20,0)))
A21: RIO | B21: CAB | C21: Azul Rey | D21: XL | E21: 61 | F21: 277 | G21: ='PLAN COLORES'!P52 | H21: =IF(G21=0,0,IF(F21=0,0,ROUND(G21*E21/F21,0)))
A22: RIO | B22: CAB | C22: Azul Lavanda | D22: 2XL | E22: 21 | F22: 267 | G22: ='PLAN COLORES'!P53 | H22: =IF(G22=0,0,IF(F22=0,0,ROUND(G22*E22/F22,0)))
A23: RIO | B23: CAB | C23: Azul Lavanda | D23: L | E23: 83 | F23: 267 | G23: ='PLAN COLORES'!P53 | H23: =IF(G23=0,0,IF(F23=0,0,ROUND(G23*E23/F23,0)))
A24: RIO | B24: CAB | C24: Azul Lavanda | D24: M | E24: 61 | F24: 267 | G24: ='PLAN COLORES'!P53 | H24: =IF(G24=0,0,IF(F24=0,0,ROUND(G24*E24/F24,0)))
A25: RIO | B25: CAB | C25: Azul Lavanda | D25: S | E25: 40 | F25: 267 | G25: ='PLAN COLORES'!P53 | H25: =IF(G25=0,0,IF(F25=0,0,ROUND(G25*E25/F25,0)))
A26: RIO | B26: CAB | C26: Azul Lavanda | D26: XL | E26: 62 | F26: 267 | G26: ='PLAN COLORES'!P53 | H26: =IF(G26=0,0,IF(F26=0,0,ROUND(G26*E26/F26,0)))
A27: RIO | B27: CAB | C27: Verde Militar | D27: 2XL | E27: 42 | F27: 245 | G27: ='PLAN COLORES'!P54 | H27: =IF(G27=0,0,IF(F27=0,0,ROUND(G27*E27/F27,0)))
A28: RIO | B28: CAB | C28: Verde Militar | D28: L | E28: 55 | F28: 245 | G28: ='PLAN COLORES'!P54 | H28: =IF(G28=0,0,IF(F28=0,0,ROUND(G28*E28/F28,0)))
A29: RIO | B29: CAB | C29: Verde Militar | D29: M | E29: 46 | F29: 245 | G29: ='PLAN COLORES'!P54 | H29: =IF(G29=0,0,IF(F29=0,0,ROUND(G29*E29/F29,0)))
A30: RIO | B30: CAB | C30: Verde Militar | D30: S | E30: 30 | F30: 245 | G30: ='PLAN COLORES'!P54 | H30: =IF(G30=0,0,IF(F30=0,0,ROUND(G30*E30/F30,0)))
A31: RIO | B31: CAB | C31: Verde Militar | D31: XL | E31: 72 | F31: 245 | G31: ='PLAN COLORES'!P54 | H31: =IF(G31=0,0,IF(F31=0,0,ROUND(G31*E31/F31,0)))
A32: RIO | B32: CAB | C32: Rojo | D32: 2XL | E32: 19 | F32: 227 | G32: ='PLAN COLORES'!P55 | H32: =IF(G32=0,0,IF(F32=0,0,ROUND(G32*E32/F32,0)))
A33: RIO | B33: CAB | C33: Rojo | D33: L | E33: 76 | F33: 227 | G33: ='PLAN COLORES'!P55 | H33: =IF(G33=0,0,IF(F33=0,0,ROUND(G33*E33/F33,0)))
A34: RIO | B34: CAB | C34: Rojo | D34: M | E34: 66 | F34: 227 | G34: ='PLAN COLORES'!P55 | H34: =IF(G34=0,0,IF(F34=0,0,ROUND(G34*E34/F34,0)))
A35: RIO | B35: CAB | C35: Rojo | D35: S | E35: 33 | F35: 227 | G35: ='PLAN COLORES'!P55 | H35: =IF(G35=0,0,IF(F35=0,0,ROUND(G35*E35/F35,0)))
A36: RIO | B36: CAB | C36: Rojo | D36: XL | E36: 33 | F36: 227 | G36: ='PLAN COLORES'!P55 | H36: =IF(G36=0,0,IF(F36=0,0,ROUND(G36*E36/F36,0)))
A37: RIO | B37: CAB | C37: Vinotinto | D37: 2XL | E37: 13 | F37: 183 | G37: ='PLAN COLORES'!P56 | H37: =IF(G37=0,0,IF(F37=0,0,ROUND(G37*E37/F37,0)))
A38: RIO | B38: CAB | C38: Vinotinto | D38: L | E38: 56 | F38: 183 | G38: ='PLAN COLORES'!P56 | H38: =IF(G38=0,0,IF(F38=0,0,ROUND(G38*E38/F38,0)))
A39: RIO | B39: CAB | C39: Vinotinto | D39: M | E39: 52 | F39: 183 | G39: ='PLAN COLORES'!P56 | H39: =IF(G39=0,0,IF(F39=0,0,ROUND(G39*E39/F39,0)))
A40: RIO | B40: CAB | C40: Vinotinto | D40: S | E40: 37 | F40: 183 | G40: ='PLAN COLORES'!P56 | H40: =IF(G40=0,0,IF(F40=0,0,ROUND(G40*E40/F40,0)))
...

Sheet RESUMEN
A1: RESUMEN POR LÍNEA (desde PLAN COLORES)
A3: Línea | B3: Und FINAL | C3: Kg usar
A4: RIO KIDS | B4: =SUMIF('PLAN COLORES'!$B$2:$B$71,"RIO KIDS",'PLAN COLORES'!$P$2:$P$71) | C4: =SUMIF('PLAN COLORES'!$B$2:$B$71,"RIO KIDS",'PLAN COLORES'!$Q$2:$Q$71)
A5: MAR KIDS | B5: =SUMIF('PLAN COLORES'!$B$2:$B$71,"MAR KIDS",'PLAN COLORES'!$P$2:$P$71) | C5: =SUMIF('PLAN COLORES'!$B$2:$B$71,"MAR KIDS",'PLAN COLORES'!$Q$2:$Q$71)
A6: MAR CAB | B6: =SUMIF('PLAN COLORES'!$B$2:$B$71,"MAR CAB",'PLAN COLORES'!$P$2:$P$71) | C6: =SUMIF('PLAN COLORES'!$B$2:$B$71,"MAR CAB",'PLAN COLORES'!$Q$2:$Q$71)
A7: MAR DAMA | B7: =SUMIF('PLAN COLORES'!$B$2:$B$71,"MAR DAMA",'PLAN COLORES'!$P$2:$P$71) | C7: =SUMIF('PLAN COLORES'!$B$2:$B$71,"MAR DAMA",'PLAN COLORES'!$Q$2:$Q$71)
A8: RIO CAB | B8: =SUMIF('PLAN COLORES'!$B$2:$B$71,"RIO CAB",'PLAN COLORES'!$P$2:$P$71) | C8: =SUMIF('PLAN COLORES'!$B$2:$B$71,"RIO CAB",'PLAN COLORES'!$Q$2:$Q$71)
A9: RIO DAMA | B9: =SUMIF('PLAN COLORES'!$B$2:$B$71,"RIO DAMA",'PLAN COLORES'!$P$2:$P$71) | C9: =SUMIF('PLAN COLORES'!$B$2:$B$71,"RIO DAMA",'PLAN COLORES'!$Q$2:$Q$71)
A11: TOTAL | B11: =SUM(P4:P9) | C11: =SUM(C4:C9)
