Workbook

Sheet RESUMEN EJECUTIVO
A1: ANÁLISIS DE CONSUMIBLES — TALLER Y TIENDAS · HISTORIAL 2 MESES
A2: Período analizado: 08/06/2026 al 05/08/2026 (59 días ≈ 8.4 semanas). Objetivo: dimensionar el pedido periódico de consumibles con datos reales de consumo, establecer stock MÍNIMO y MÁXIMO por producto y comparar 3 frecuencias de compra (semanal, quincenal y mensual). Todo el análisis usa EXCLUSIVAMENTE los dos archivos de solicitudes suministrados.
A4: 1 · FUENTES DE DATOS
A5: TALLER | B5: solicitudes_taller_2_meses.xlsx — hoja 'CRECO SOLICITUDES' | I5: 156 solicitudes válidas (09-jun al 05-ago)
A6: TIENDAS | B6: _Solicitudes (TIENDAS) consumibles 2meses.xlsx — 7 tiendas (GRIETA, SAMBIL VALENCIA, GRAND PLAZ, CERRO VERDE, SAMBIL CHACAO, TOLON, MARGARITA) | I6: 418 solicitudes válidas (08-jun al 04-ago)
A7: CATÁLOGO | B7: Hoja 'INVENTARIO DE CONSUMIBLES' del archivo de tiendas | I7: 173 productos con categoría (usada para clasificar)
A9: 2 · INDICADORES CLAVE DE ATENCIÓN
A10: ALCANCE | B10: SOLICITUDES | C10: ATENDIDAS | D10: NO DISPONIBLES | E10: % ATENDIDAS | F10: % NO DISPONIBLES | G10: UNDS SOLICITADAS | H10: UNDS ATENDIDAS | I10: UNDS NO CUBIERTAS | J10: % UNDS ATENDIDAS
A11: TALLER | B11: 156 | C11: 137 | D11: 19 | E11: 0.87820513 | F11: 0.12179487 | G11: 461 | H11: 438 | I11: 23 | J11: 0.95010846
A12: TIENDAS | B12: 418 | C12: 334 | D12: 84 | E12: 0.79904306 | F12: 0.20095694 | G12: 15741 | H12: 15238 | I12: 503 | J12: 0.96804523
A13: UNIFICADO | B13: 574 | C13: 471 | D13: 103 | E13: 0.82055749 | F13: 0.17944251 | G13: 16202 | H13: 15676 | I13: 526 | J13: 0.96753487
A14: ATENDIDA = solicitudes en estado RECIBIDO / ENTREGADO / ENVIADO + SOLICITADO (criterio indicado: 'recibido e incluye solicitado'). NO ATENDIDA = NO DISPONIBLE. Las 12 filas sin estado (SAMBIL VALENCIA 04-ago) se tratan como SOLICITADO. Detalle en la hoja KPI ATENCION.
A16: 3 · COMPRA SUGERIDA SEGÚN FRECUENCIA (UNIFICADO, stock inicial = 0)
A17: OPCIÓN | B17: CICLO (DÍAS) | C17: UNDS A PEDIR (PRIMER PEDIDO) | D17: STOCK MÁXIMO TOTAL | E17: STOCK MÍNIMO TOTAL (PUNTO REORDEN) | F17: LECTURA
A18: OPCIÓN SEMANAL | B18: 7 | C18: =UNIFICADO!Q102 -> 6167 | D18: =UNIFICADO!P102 -> 6167 | E18: =UNIFICADO!N102 -> 4239 | F18: Menor inventario inmovilizado; requiere proveedor ágil cada semana.
A19: OPCIÓN QUINCENAL | B19: 14 | C19: =UNIFICADO!S102 -> 8092 | D19: =UNIFICADO!R102 -> 8092 | E19: =UNIFICADO!N102 -> 4239 | F19: Equilibrio recomendado entre capital y riesgo de quiebre.
A20: OPCIÓN MENSUAL | B20: 30 | C20: =UNIFICADO!U102 -> 12474 | D20: =UNIFICADO!T102 -> 12474 | E20: =UNIFICADO!N102 -> 4239 | F20: Un solo pedido grande; más stock promedio, menor carga administrativa.
A22: 4 · TOP 10 PRODUCTOS POR UNIDADES (UNIFICADO, 2 MESES)
A23: # | B23: PRODUCTO | C23: CATEGORÍA | D23: UNDS 2 MESES | E23: UNDS/SEMANA | F23: % ATENCIÓN
A24: 1 | B24: STICKER DE REGALO | C24: SUMINISTROS | D24: 5200 | E24: 616.9 | F24: 1
A25: 2 | B25: BOLSAS PEQUEÑAS NAVIDAD 2024 | C25: SUMINISTROS | D25: 2770 | E25: 328.6 | F25: 1
A26: 3 | B26: BOLSAS MEDIANAS NAVIDAD 2024 | C26: SUMINISTROS | D26: 2460 | E26: 291.9 | F26: 1
A27: 4 | B27: BOLSAS GRANDES KRAFT | C27: SUMINISTROS | D27: 1210 | E27: 143.6 | F27: 1
A28: 5 | B28: STICKER ADHESIVO DE CIERRE | C28: SUMINISTROS | D28: 800 | E28: 94.9 | F28: 1
A29: 6 | B29: BOLSAS EXTRA PEQUEÑA KRAFT | C29: SUMINISTROS | D29: 550 | E29: 65.3 | F29: 1
A30: 7 | B30: BOLSA DE PAPELERA | C30: LIMPIEZA E HIGIENE | D30: 530 | E30: 62.9 | F30: 0.73584906
A31: 8 | B31: BOLSAS DE BASURA | C31: LIMPIEZA E HIGIENE | D31: 438 | E31: 52 | F31: 0.88584475
A32: 9 | B32: BOLSAS PEQUEÑAS KRAFT | C32: SUMINISTROS | D32: 400 | E32: 47.5 | F32: 1
A33: 10 | B33: BOLSA DE ENVIO MEDIANA | C33: SUMINISTROS | D33: 301 | E33: 35.7 | F33: 0.76744186
A35: 5 · CONCLUSIONES Y RECOMENDACIONES
A36: 1. En 2 meses se registraron 574 solicitudes por 16,202 unidades: 156 del taller (461 unds) y 418 de tiendas (15,741 unds). Las tiendas concentran el grueso del consumo (bolsas, stickers, limpieza).
A37: 2. Atención global: 82.1% de las solicitudes fueron atendidas y 17.9% quedaron NO DISPONIBLES (103 solicitudes, 526 unds no cubiertas). El taller tuvo 87.8% de atención y las tiendas 79.9%.
A38: 3. Productos que más veces quedaron NO DISPONIBLES: SERVILLETAS (13 veces), ESENCIA SPLASH PARA BOLSAS (11 veces), CINTA DOBLE FAZ (10 veces), RESMA DE HOJAS BLANCAS (6 veces), PAÑO AMARILLO (5 veces). Conviene asegurar proveedor/stock de estos ítems primero: son demanda real que hoy se pierde.
A39: 4. La demanda NO cubierta (526 unds) NO está en las cifras de consumo atendido: los MIN/MAX de este archivo se calcularon sobre la demanda SOLICITADA (real), precisamente para corregir ese desabastecimiento.
A40: 5. 33 de 97 productos son de demanda intermitente (≤2 solicitudes y ≤4 unds en 2 meses). Para ellos el MÁXIMO calculado es bajo: evalúe comprarlos solo bajo pedido para no inmovilizar capital.
A41: 6. Frecuencia recomendada: la opción QUINCENAL equilibra capital de trabajo y riesgo de quiebre de stock con proveedores de ~1 semana de lead time. Si el proveedor exige pedido mensual, use la columna PEDIDO MENSUAL; si puede reaccionar semanal, la SEMANAL minimiza inventario. Compare los totales en la sección 3.
A42: 7. Ajuste el LEAD TIME y el z de NIVEL DE SERVICIO por producto (columnas amarillas en TALLER/TIENDAS/UNIFICADO) cuando tenga el dato real del proveedor: MIN/MAX/PEDIDO se recalculan automáticamente. Los productos clase Z (intermitentes) son candidatos a compra bajo pedido.
A43: 8. Mejora de registro: corregir el estado 'ENTRGADO' (typo), registrar el estado en TODAS las solicitudes (12 quedaron vacías el 04-ago) y agregar 'REGLETA' al catálogo de consumibles.
A45: 6 · GUÍA DEL ARCHIVO
A46: METODOLOGIA | B46: Cómo se limpió la data, definiciones y fórmulas del modelo MIN/MAX.
...

Sheet METODOLOGIA
A1: METODOLOGÍA, DEFINICIONES Y SUPUESTOS
B3: 1 · ALCANCE Y FUENTES
B4: Se usaron EXCLUSIVAMENTE los 2 archivos suministrados. Historial completo desde cero: 08/06/2026 al 05/08/2026 (59 días). Taller: 58 días de registro (09-jun al 05-ago); tiendas: 58 días (08-jun al 04-ago).
B5: Cada fila = 1 solicitud de un artículo con su cantidad (unidades según lo registrado: und, paquete, galón, caja…). El análisis se concentra en UNIDADES, tal como se pidió.
B7: 2 · LIMPIEZA DE DATOS
B8: • Se eliminaron 4 filas basura (3 vacías con '.' en TOLON y 1 sin datos en TALLER). Detalle en CALIDAD DE DATOS.
B9: • 'ENTRGADO' (error de tipeo) se normalizó a 'ENTREGADO' (136 filas del taller).
B10: • 12 solicitudes sin estado (SAMBIL VALENCIA, 04-ago, último día del registro) se tratan como SOLICITADO.
B11: • 1 solicitud del taller sin artículo (Kiria Pinto, 30-jun, 3 unds ENTREGADO) cuenta para los KPIs generales pero no puede asignarse a ningún producto.
B12: • Cuando ARTICULO estaba vacío se usó CARACTER ADICIONAL (caso 'REGLETA').
B13: • No hubo cantidades negativas ni cero; todas son enteros positivos. No hubo duplicados reales.
B15: 3 · CLASIFICACIÓN DE ATENCIÓN (KPI PEDIDO)
B16: ATENDIDA = RECIBIDO + ENTREGADO + ENVIADO + SOLICITADO (criterio: 'recibido e incluye solicitado').
... B41: • Productos estacionales (p. ej. 'NAVIDAD 2024') pueden no repetir su demanda fuera de temporada.

Sheet PARAMETROS
A1: PARÁMETROS DEL MODELO (celdas amarillas editables)
A3: PARÁMETRO | B3: VALOR | C3: DESCRIPCIÓN
A4: Días del período — TALLER | B4: 58 | C4: Del 09-jun-2026 al 05-ago-2026 (informativo).
A5: Días del período — TIENDAS | B5: 58 | C5: Del 08-jun-2026 al 04-ago-2026 (informativo).
A6: Días del período — UNIFICADO | B6: 59 | C6: Ventana completa del análisis (informativo).
A7: Lead time por defecto (días) | B7: 7 | C7: Tiempo entre pedir y recibir. Es el valor inicial de la columna LEAD TIME de cada producto (editable allí producto por producto, porque varía por ítem/proveedor).
A8: P — Ciclo SEMANAL (días) | B8: 7 | C8: Días entre pedidos en la opción semanal.
A9: P — Ciclo QUINCENAL (días) | B9: 14 | C9: Días entre pedidos en la opción quincenal.
A10: P — Ciclo MENSUAL (días) | B10: 30 | C10: Días entre pedidos en la opción mensual.
A11: z — Clase X (demanda regular) | B11: 1.65 | C11: 1.65 → 95% de no quedarse sin stock durante el lead time. Se aplica a productos de consumo parejo (CV semanal ≤ 0.5).
A12: z — Clase Y (demanda variable) | B12: 1.28 | C12: 1.28 → 90%. Productos con consumo irregular (CV semanal entre 0.5 y 1).
A13: z — Clase Z (demanda intermitente) | B13: 0.84 | C13: 0.84 → 80%. Productos esporádicos (CV semanal > 1 o ≤2 solicitudes pequeñas). Para ellos considere compra bajo pedido.
A15: Estos valores alimentan las fórmulas de las hojas TALLER, TIENDAS y UNIFICADO: al modificarlos, SS / MIN / MAX / PEDIDO se recalculan automáticamente en todo el libro. El z de cada producto puede sobreescribirse individualmente en su columna amarilla.

Sheet KPI ATENCION
A1: % DE SOLICITUDES ATENDIDAS vs NO DISPONIBLES
A2: ATENDIDA = RECIBIDO/ENTREGADO/ENVIADO + SOLICITADO (criterio indicado). NO ATENDIDA = NO DISPONIBLE. Se muestra por alcance, estado, sucursal, mes y producto, en base a número de solicitudes y a unidades.
A4: POR ALCANCE
A5: ALCANCE | B5: SOLICITUDES | C5: ATENDIDAS | D5: NO DISPONIBLES | E5: % ATENDIDAS | F5: % NO DISPONIBLES | G5: UNDS | H5: UNDS ATENDIDAS | I5: UNDS NO CUBIERTAS | J5: % UNDS ATENDIDAS
A6: TALLER | B6: 156 | C6: 137 | D6: 19 | E6: 0.87820513 | F6: 0.12179487 | G6: 461 | H6: 438 | I6: 23 | J6: 0.95010846
A7: TIENDAS | B7: 418 | C7: 334 | D7: 84 | E7: 0.79904306 | F7: 0.20095694 | G7: 15741 | H7: 15238 | I7: 503 | J7: 0.96804523
A8: UNIFICADO | B8: 574 | C8: 471 | D8: 103 | E8: 0.82055749 | F8: 0.17944251 | G8: 16202 | H8: 15676 | I8: 526 | J8: 0.96753487
A10: POR ESTADO (DETALLE)
A11: ESTADO | B11: TALLER | C11: TIENDAS | D11: TOTAL | E11: CLASIFICACIÓN
A12: RECIBIDO | B12: 0 | C12: 263 | D12: 263 | E12: ATENDIDA
A13: ENTREGADO | B13: 136 | C13: 0 | D13: 136 | E13: ATENDIDA
A14: ENVIADO | B14: 0 | C14: 3 | D14: 3 | E14: ATENDIDA
A15: SOLICITADO | B15: 1 | C15: 56 | D15: 57 | E15: ATENDIDA
A16: SIN ESTADO | B16: 0 | C16: 12 | D16: 12 | E16: ATENDIDA
A17: NO DISPONIBLE | B17: 19 | C17: 84 | D17: 103 | E17: NO ATENDIDA
A19: POR SUCURSAL / SUB-ÁREA
A20: ORIGEN | B20: SUCURSAL | C20: SOLICITUDES | D20: ATENDIDAS | E20: NO DISPONIBLES | F20: % ATENDIDAS | G20: UNDS | H20: UNDS NO CUBIERTAS
A21: TALLER | B21: ALMACEN | C21: 17 | D21: 17 | E21: 0 | F21: 1 | G21: 31 | H21: 0
A22: TALLER | B22: I+D | C22: 26 | D22: 20 | E22: 6 | F22: 0.76923077 | G22: 55 | H22: 8
A23: TALLER | B23: MANTENIMIENTO | C23: 10 | D23: 10 | E23: 0 | F23: 1 | G23: 69 | H23: 0
A24: TALLER | B24: OFICINAS | C24: 1 | D24: 1 | E24: 0 | F24: 1 | G24: 1 | H24: 0
A25: TALLER | B25: RECURSOS HUMANOS | C25: 2 | D25: 1 | E25: 1 | F25: 0.5 | G25: 4 | H25: 1
A26: TALLER | B26: TALLER | C26: 100 | D26: 88 | E26: 12 | F26: 0.88 | G26: 301 | H26: 14
A27: TIENDAS | B27: CERRO VERDE | C27: 54 | D27: 44 | E27: 10 | F27: 0.81481481 | G27: 3349 | H27: 112
A28: TIENDAS | B28: GRAND PLAZ | C28: 21 | D28: 18 | E28: 3 | F28: 0.85714286 | G28: 707 | H28: 6
A29: TIENDAS | B29: GRIETA | C29: 81 | D29: 67 | E29: 14 | F29: 0.82716049 | G29: 4030 | H29: 231
A30: TIENDAS | B30: MARGARITA | C30: 25 | D30: 25 | E30: 0 | F30: 1 | G30: 867 | H30: 0
A31: TIENDAS | B31: SAMBIL CHACAO | C31: 75 | D31: 58 | E31: 17 | F31: 0.77333333 | G31: 2618 | H31: 27
A32: TIENDAS | B32: SAMBIL VALENCIA | C32: 90 | D32: 70 | E32: 20 | F32: 0.77777778 | G32: 3208 | H32: 61
A33: TIENDAS | B33: TOLON | C33: 72 | D33: 52 | E33: 20 | F33: 0.72222222 | G33: 962 | H33: 66
A35: POR MES
A36: MES | B36: SOL. TALLER | C36: % AT. TALLER | D36: SOL. TIENDAS | E36: % AT. TIENDAS | F36: SOL. TOTAL | G36: % AT. TOTAL | H36: UNDS TOTAL
A37: JUNIO | B37: 74 | C37: 0.90540541 | D37: 155 | E37: 0.78709677 | F37: 229 | G37: 0.82532751 | H37: 6611
A38: JULIO | B38: 73 | C38: 0.83561644 | D38: 215 | E38: 0.78139535 | F38: 288 | G38: 0.79513889 | H38: 8724
A39: AGOSTO (PARCIAL) | B39: 9 | C39: 1 | D39: 48 | E39: 0.91666667 | F39: 57 | G39: 0.92982456 | H39: 867
A41: TOP 10 PRODUCTOS CON MÁS 'NO DISPONIBLE' (demanda perdida)
A42: PRODUCTO | B42: VECES NO DISPONIBLE | C42: UNDS NO CUBIERTAS | D42: UNDS SOLICITADAS | E42: % NO CUBIERTO
A43: SERVILLETAS | B43: 13 | C43: 26 | D43: 57 | E43: 0.45614035
A44: ESENCIA SPLASH PARA BOLSAS | B44: 11 | C44: 20 | D44: 46 | E44: 0.43478261
A45: CINTA DOBLE FAZ | B45: 10 | C45: 15 | D45: 18 | E45: 0.83333333
...

Sheet TALLER
A1: TALLER — ANÁLISIS POR PRODUCTO Y PEDIDO (3 OPCIONES)
A2: Una fila por producto. MIN = punto de reorden = D×LT + SS · MAX = stock objetivo = D×(LT+P) + SS (P = 7/14/30 días) · PEDIDO = MAX − stock actual. Celdas amarillas editables (z de servicio, lead time y stock actual): todo se recalcula. CLASE DEMANDA: X regular / Y variable / Z intermitente. La demanda usada es la SOLICITADA (incluye lo que quedó NO DISPONIBLE). Ámbito: solo solicitudes del TALLER (todas sus sub-áreas).
A4: PRODUCTO | B4: CATEGORÍA | C4: Nº SOLICITUDES | D4: UNDS SOLICITADAS (2m) | E4: UNDS ATENDIDAS | F4: UNDS NO DISPONIBLES | G4: % ATENCIÓN (UNDS) | H4: DEMANDA DIARIA (D) | I4: σ SEMANAL | J4: CLASE DEMANDA | K4: z NIVEL SERVICIO ✎ | L4: LEAD TIME (DÍAS) ✎ | M4: STOCK SEGURIDAD (SS) | N4: MIN = PUNTO REORDEN | O4: STOCK ACTUAL ✎ | P4: MAX SEMANAL | Q4: PEDIDO SEMANAL | R4: MAX QUINCENAL | S4: PEDIDO QUINCENAL | T4: MAX MENSUAL | U4: PEDIDO MENSUAL
A5: BOLSAS DE BASURA | B5: LIMPIEZA E HIGIENE | C5: 10 | D5: 52 | E5: 52 | F5: 0 | G5: 1 | H5: 0.8966 | I5: 11.8683 | J5: Z · Intermitente | K5: =IF(LEFT(J5,1)="X",PARAMETROS!$B$11,IF(LEFT(J5,1)="Y",PARAMETROS!$B$12,PARAMETROS!$B$13)) -> 0.84 | L5: =PARAMETROS!$B$7 -> 7 | M5: =ROUND(K5*I5*SQRT(L5/7),2) -> 9.97 | N5: =ROUNDUP(H5*L5+M5,0) -> 17 | O5: 0 | P5: =ROUNDUP(H5*(L5+PARAMETROS!$B$8)+M5,0) -> 23 | Q5: =MAX(0,P5-O5) -> 23 | R5: =ROUNDUP(H5*(L5+PARAMETROS!$B$9)+M5,0) -> 29 | S5: =MAX(0,R5-O5) -> 29 | T5: =ROUNDUP(H5*(L5+PARAMETROS!$B$10)+M5,0) -> 44 | U5: =MAX(0,T5-O5) -> 44
A6: BOLSAS PEQUEÑAS NAVIDAD 2024 | B6: SUMINISTROS | C6: 3 | D6: 50 | E6: 50 | F6: 0 | G6: 1 | H6: 0.8621 | I6: 10.6066 | J6: Z · Intermitente | K6: =IF(LEFT(J6,1)="X",PARAMETROS!$B$11,IF(LEFT(J6,1)="Y",PARAMETROS!$B$12,PARAMETROS!$B$13)) -> 0.84 | L6: =PARAMETROS!$B$7 -> 7 | M6: =ROUND(K6*I6*SQRT(L6/7),2) -> 8.91 | N6: =ROUNDUP(H6*L6+M6,0) -> 15 | O6: 0 | P6: =ROUNDUP(H6*(L6+PARAMETROS!$B$8)+M6,0) -> 21 | Q6: =MAX(0,P6-O6) -> 21 | R6: =ROUNDUP(H6*(L6+PARAMETROS!$B$9)+M6,0) -> 28 | S6: =MAX(0,R6-O6) -> 28 | T6: =ROUNDUP(H6*(L6+PARAMETROS!$B$10)+M6,0) -> 41 | U6: =MAX(0,T6-O6) -> 41
A7: BOLSA DE ENVIO MEDIANA | B7: SUMINISTROS | C7: 2 | D7: 35 | E7: 35 | F7: 0 | G7: 1 | H7: 0.6034 | I7: 8.2104 | J7: Z · Intermitente | K7: =IF(LEFT(J7,1)="X",PARAMETROS!$B$11,IF(LEFT(J7,1)="Y",PARAMETROS!$B$12,PARAMETROS!$B$13)) -> 0.84 | L7: =PARAMETROS!$B$7 -> 7 | M7: =ROUND(K7*I7*SQRT(L7/7),2) -> 6.9 | N7: =ROUNDUP(H7*L7+M7,0) -> 12 | O7: 0 | P7: =ROUNDUP(H7*(L7+PARAMETROS!$B$8)+M7,0) -> 16 | Q7: =MAX(0,P7-O7) -> 16 | R7: =ROUNDUP(H7*(L7+PARAMETROS!$B$9)+M7,0) -> 20 | S7: =MAX(0,R7-O7) -> 20 | T7: =ROUNDUP(H7*(L7+PARAMETROS!$B$10)+M7,0) -> 30 | U7: =MAX(0,T7-O7) -> 30
A8: LAPIZ | B8: OFICINA | C8: 9 | D8: 35 | E8: 33 | F8: 2 | G8: 0.94285714 | H8: 0.6034 | I8: 5.0409 | J8: Z · Intermitente | K8: =IF(LEFT(J8,1)="X",PARAMETROS!$B$11,IF(LEFT(J8,1)="Y",PARAMETROS!$B$12,PARAMETROS!$B$13)) -> 0.84 | L8: =PARAMETROS!$B$7 -> 7 | M8: =ROUND(K8*I8*SQRT(L8/7),2) -> 4.23 | N8: =ROUNDUP(H8*L8+M8,0) -> 9 | O8: 0 | P8: =ROUNDUP(H8*(L8+PARAMETROS!$B$8)+M8,0) -> 13 | Q8: =MAX(0,P8-O8) -> 13 | R8: =ROUNDUP(H8*(L8+PARAMETROS!$B$9)+M8,0) -> 17 | S8: =MAX(0,R8-O8) -> 17 | T8: =ROUNDUP(H8*(L8+PARAMETROS!$B$10)+M8,0) -> 27 | U8: =MAX(0,T8-O8) -> 27
A9: BOLIGRAFOS | B9: OFICINA | C9: 13 | D9: 29 | E9: 29 | F9: 0 | G9: 1 | H9: 0.5 | I9: 3.9641 | J9: Z · Intermitente | K9: =IF(LEFT(J9,1)="X",PARAMETROS!$B$11,IF(LEFT(J9,1)="Y",PARAMETROS!$B$12,PARAMETROS!$B$13)) -> 0.84 | L9: =PARAMETROS!$B$7 -> 7 | M9: =ROUND(K9*I9*SQRT(L9/7),2) -> 3.33 | N9: =ROUNDUP(H9*L9+M9,0) -> 7 | O9: 0 | P9: =ROUNDUP(H9*(L9+PARAMETROS!$B$8)+M9,0) -> 11 | Q9: =MAX(0,P9-O9) -> 11 | R9: =ROUNDUP(H9*(L9+PARAMETROS!$B$9)+M9,0) -> 14 | S9: =MAX(0,R9-O9) -> 14 | T9: =ROUNDUP(H9*(L9+PARAMETROS!$B$10)+M9,0) -> 22 | U9: =MAX(0,T9-O9) -> 22
A10: BOLSA DE PAPELERA | B10: LIMPIEZA E HIGIENE | C10: 1 | D10: 25 | E10: 25 | F10: 0 | G10: 1 | H10: 0.431 | I10: 8.8388 | J10: Z · Intermitente | K10: =IF(LEFT(J10,1)="X",PARAMETROS!$B$11,IF(LEFT(J10,1)="Y",PARAMETROS!$B$12,PARAMETROS!$B$13)) -> 0.84 | L10: =PARAMETROS!$B$7 -> 7 | M10: =ROUND(K10*I10*SQRT(L10/7),2) -> 7.42 | N10: =ROUNDUP(H10*L10+M10,0) -> 11 | O10: 0 | P10: =ROUNDUP(H10*(L10+PARAMETROS!$B$8)+M10,0) -> 14 | Q10: =MAX(0,P10-O10) -> 14 | R10: =ROUNDUP(H10*(L10+PARAMETROS!$B$9)+M10,0) -> 17 | S10: =MAX(0,R10-O10) -> 17 | T10: =ROUNDUP(H10*(L10+PARAMETROS!$B$10)+M10,0) -> 24 | U10: =MAX(0,T10-O10) -> 24
A11: TAPABOCAS | B11: INSUMOS MEDICOS | C11: 3 | D11: 21 | E11: 21 | F11: 0 | G11: 1 | H11: 0.3621 | I11: 5.6805 | J11: Z · Intermitente | K11: =IF(LEFT(J11,1)="X",PARAMETROS!$B$11,IF(LEFT(J11,1)="Y",PARAMETROS!$B$12,PARAMETROS!$B$13)) -> 0.84 | L11: =PARAMETROS!$B$7 -> 7 | M11: =ROUND(K11*I11*SQRT(L11/7),2) -> 4.77 | N11: =ROUNDUP(H11*L11+M11,0) -> 8 | O11: 0 | P11: =ROUNDUP(H11*(L11+PARAMETROS!$B$8)+M11,0) -> 10 | Q11: =MAX(0,P11-O11) -> 10 | R11: =ROUNDUP(H11*(L11+PARAMETROS!$B$9)+M11,0) -> 13 | S11: =MAX(0,R11-O11) -> 13 | T11: =ROUNDUP(H11*(L11+PARAMETROS!$B$10)+M11,0) -> 19 | U11: =MAX(0,T11-O11) -> 19
A12: CINTA DE EMBALAJE | B12: SUMINISTROS | C12: 9 | D12: 20 | E12: 18 | F12: 2 | G12: 0.9 | H12: 0.3448 | I12: 5.5533 | J12: Z · Intermitente | K12: =IF(LEFT(J12,1)="X",PARAMETROS!$B$11,IF(LEFT(J12,1)="Y",PARAMETROS!$B$12,PARAMETROS!$B$13)) -> 0.84 | L12: =PARAMETROS!$B$7 -> 7 | M12: =ROUND(K12*I12*SQRT(L12/7),2) -> 4.66 | N12: =ROUNDUP(H12*L12+M12,0) -> 8 | O12: 0 | P12: =ROUNDUP(H12*(L12+PARAMETROS!$B$8)+M12,0) -> 10 | Q12: =MAX(0,P12-O12) -> 10 | R12: =ROUNDUP(H12*(L12+PARAMETROS!$B$9)+M12,0) -> 12 | S12: =MAX(0,R12-O12) -> 12 | T12: =ROUNDUP(H12*(L12+PARAMETROS!$B$10)+M12,0) -> 18 | U12: =MAX(0,T12-O12) -> 18
A13: TIRRO | B13: OFICINA | C13: 10 | D13: 16 | E13: 13 | F13: 3 | G13: 0.8125 | H13: 0.2759 | I13: 0.7071 | J13: X · Regular | K13: =IF(LEFT(J13,1)="X",PARAMETROS!$B$11,IF(LEFT(J13,1)="Y",PARAMETROS!$B$12,PARAMETROS!$B$13)) -> 1.65 | L13: =PARAMETROS!$B$7 -> 7 | M13: =ROUND(K13*I13*SQRT(L13/7),2) -> 1.17 | N13: =ROUNDUP(H13*L13+M13,0) -> 4 | O13: 0 | P13: =ROUNDUP(H13*(L13+PARAMETROS!$B$8)+M13,0) -> 6 | Q13: =MAX(0,P13-O13) -> 6 | R13: =ROUNDUP(H13*(L13+PARAMETROS!$B$9)+M13,0) -> 7 | S13: =MAX(0,R13-O13) -> 7 | T13: =ROUNDUP(H13*(L13+PARAMETROS!$B$10)+M13,0) -> 12 | U13: =MAX(0,T13-O13) -> 12
A14: CINTA METRICA | B14: SUMINISTROS | C14: 3 | D14: 13 | E14: 10 | F14: 3 | G14: 0.76923077 | H14: 0.2241 | I14: 3.8522 | J14: Z · Intermitente | K14: =IF(LEFT(J14,1)="X",PARAMETROS!$B$11,IF(LEFT(J14,1)="Y",PARAMETROS!$B$12,PARAMETROS!$B$13)) -> 0.84 | L14: =PARAMETROS!$B$7 -> 7 | M14: =ROUND(K14*I14*SQRT(L14/7),2) -> 3.24 | N14: =ROUNDUP(H14*L14+M14,0) -> 5 | O14: 0 | P14: =ROUNDUP(H14*(L14+PARAMETROS!$B$8)+M14,0) -> 7 | Q14: =MAX(0,P14-O14) -> 7 | R14: =ROUNDUP(H14*(L14+PARAMETROS!$B$9)+M14,0) -> 8 | S14: =MAX(0,R14-O14) -> 8 | T14: =ROUNDUP(H14*(L14+PARAMETROS!$B$10)+M14,0) -> 12 | U14: =MAX(0,T14-O14) -> 12
A15: PIQUETAS | B15: SUMINISTROS | C15: 7 | D15: 12 | E15: 12 | F15: 0 | G15: 1 | H15: 0.2069 | I15: 1.7525 | J15: Z · Intermitente | K15: =IF(LEFT(J15,1)="X",PARAMETROS!$B$11,IF(LEFT(J15,1)="Y",PARAMETROS!$B$12,PARAMETROS!$B$13)) -> 0.84 | L15: =PARAMETROS!$B$7 -> 7 | M15: =ROUND(K15*I15*SQRT(L15/7),2) -> 1.47 | N15: =ROUNDUP(H15*L15+M15,0) -> 3 | O15: 0 | P15: =ROUNDUP(H15*(L15+PARAMETROS!$B$8)+M15,0) -> 5 | Q15: =MAX(0,P15-O15) -> 5 | R15: =ROUNDUP(H15*(L15+PARAMETROS!$B$9)+M15,0) -> 6 | S15: =MAX(0,R15-O15) -> 6 | T15: =ROUNDUP(H15*(L15+PARAMETROS!$B$10)+M15,0) -> 10 | U15: =MAX(0,T15-O15) -> 10
A16: BOLSA DE ENVIO GRANDE | B16: SUMINISTROS | C16: 1 | D16: 10 | E16: 10 | F16: 0 | G16: 1 | H16: 0.1724 | I16: 3.5355 | J16: Z · Intermitente | K16: =IF(LEFT(J16,1)="X",PARAMETROS!$B$11,IF(LEFT(J16,1)="Y",PARAMETROS!$B$12,PARAMETROS!$B$13)) -> 0.84 | L16: =PARAMETROS!$B$7 -> 7 | M16: =ROUND(K16*I16*SQRT(L16/7),2) -> 2.97 | N16: =ROUNDUP(H16*L16+M16,0) -> 5 | O16: 0 | P16: =ROUNDUP(H16*(L16+PARAMETROS!$B$8)+M16,0) -> 6 | Q16: =MAX(0,P16-O16) -> 6 | R16: =ROUNDUP(H16*(L16+PARAMETROS!$B$9)+M16,0) -> 7 | S16: =MAX(0,R16-O16) -> 7 | T16: =ROUNDUP(H16*(L16+PARAMETROS!$B$10)+M16,0) -> 10 | U16: =MAX(0,T16-O16) -> 10
... A59: VENSOL | B59: LIMPIEZA E HIGIENE | C59: 1 | D59: 1 | E59: 1 | F59: 0 | G59: 1 | H59: 0.0172 | I59: 0 | J59: Z · Intermitente | K59: =IF(LEFT(J59,1)="X",PARAMETROS!$B$11,IF(LEFT(J59,1)="Y",PARAMETROS!$B$12,PARAMETROS!$B$13)) -> 0.84 | L59: =PARAMETROS!$B$7 -> 7 | M59: =ROUND(K59*I59*SQRT(L59/7),2) -> 0 | N59: =ROUNDUP(H59*L59+M59,0) -> 1 | O59: 0 | P59: =ROUNDUP(H59*(L59+PARAMETROS!$B$8)+M59,0) -> 1 | Q59: =MAX(0,P59-O59) -> 1 | R59: =ROUNDUP(H59*(L59+PARAMETROS!$B$9)+M59,0) -> 1 | S59: =MAX(0,R59-O59) -> 1 | T59: =ROUNDUP(H59*(L59+PARAMETROS!$B$10)+M59,0) -> 1 | U59: =MAX(0,T59-O59) -> 1
A60: TOTAL | C60: =SUM(C5:C59) -> 155 | D60: =SUM(D5:D59) -> 458 | E60: =SUM(E5:E59) -> 435 | F60: =SUM(F5:F59) -> 23 | G60: =E60/D60 -> 0.94978166 | H60: =SUM(H5:H59) -> 7.8966 | N60: =SUM(N5:N59) -> 176 | P60: =SUM(P5:P59) -> 228 | Q60: =SUM(Q5:Q59) -> 228 | R60: =SUM(R5:R59) -> 282 | S60: =SUM(S5:S59) -> 282 | T60: =SUM(T5:T59) -> 405 | U60: =SUM(U5:U59) -> 405
A62: ✎ Celdas amarillas editables: LEAD TIME por producto, z de NIVEL DE SERVICIO y STOCK ACTUAL; SS, MIN, MAX y PEDIDO se recalculan solos. PEDIDO = MAX − STOCK ACTUAL (si el stock es 0, el pedido parte de cero). MIN = D×LT + SS · MAX = D×(LT+P) + SS (P = 7/14/30 días) · SS = z×σ semanal×√(LT/7). CLASE DEMANDA: X regular / Y variable / Z intermitente — define el z inicial (95%/90%/80%, configurable en PARAMETROS). Ítems Z: evaluar compra bajo pedido.

Sheet TIENDAS
A1: TIENDAS — ANÁLISIS POR PRODUCTO Y PEDIDO (3 OPCIONES)
A2: Una fila por producto. MIN = punto de reorden = D×LT + SS · MAX = stock objetivo = D×(LT+P) + SS (P = 7/14/30 días) · PEDIDO = MAX − stock actual. Celdas amarillas editables (z de servicio, lead time y stock actual): todo se recalcula. CLASE DEMANDA: X regular / Y variable / Z intermitente. La demanda usada es la SOLICITADA (incluye lo que quedó NO DISPONIBLE). Ámbito: consolidado de las 7 tiendas.
A4: PRODUCTO | B4: CATEGORÍA | C4: Nº SOLICITUDES | D4: UNDS SOLICITADAS (2m) | E4: UNDS ATENDIDAS | F4: UNDS NO DISPONIBLES | G4: % ATENCIÓN (UNDS) | H4: DEMANDA DIARIA (D) | I4: σ SEMANAL | J4: CLASE DEMANDA | K4: z NIVEL SERVICIO ✎ | L4: LEAD TIME (DÍAS) ✎ | M4: STOCK SEGURIDAD (SS) | N4: MIN = PUNTO REORDEN | O4: STOCK ACTUAL ✎ | P4: MAX SEMANAL | Q4: PEDIDO SEMANAL | R4: MAX QUINCENAL | S4: PEDIDO QUINCENAL | T4: MAX MENSUAL | U4: PEDIDO MENSUAL
A5: STICKER DE REGALO | B5: SUMINISTROS | C5: 22 | D5: 5200 | E5: 5200 | F5: 0 | G5: 1 | H5: 89.6552 | I5: 505.6379 | J5: Y · Variable | K5: =IF(LEFT(J5,1)="X",PARAMETROS!$B$11,IF(LEFT(J5,1)="Y",PARAMETROS!$B$12,PARAMETROS!$B$13)) -> 1.28 | L5: =PARAMETROS!$B$7 -> 7 | M5: =ROUND(K5*I5*SQRT(L5/7),2) -> 647.22 | N5: =ROUNDUP(H5*L5+M5,0) -> 1275 | O5: 0 | P5: =ROUNDUP(H5*(L5+PARAMETROS!$B$8)+M5,0) -> 1903 | Q5: =MAX(0,P5-O5) -> 1903 | R5: =ROUNDUP(H5*(L5+PARAMETROS!$B$9)+M5,0) -> 2530 | S5: =MAX(0,R5-O5) -> 2530 | T5: =ROUNDUP(H5*(L5+PARAMETROS!$B$10)+M5,0) -> 3965 | U5: =MAX(0,T5-O5) -> 3965
A6: BOLSAS PEQUEÑAS NAVIDAD 2024 | B6: SUMINISTROS | C6: 13 | D6: 2720 | E6: 2720 | F6: 0 | G6: 1 | H6: 46.8966 | I6: 307.4318 | J6: Y · Variable | K6: =IF(LEFT(J6,1)="X",PARAMETROS!$B$11,IF(LEFT(J6,1)="Y",PARAMETROS!$B$12,PARAMETROS!$B$13)) -> 1.28 | L6: =PARAMETROS!$B$7 -> 7 | M6: =ROUND(K6*I6*SQRT(L6/7),2) -> 393.51 | N6: =ROUNDUP(H6*L6+M6,0) -> 722 | O6: 0 | P6: =ROUNDUP(H6*(L6+PARAMETROS!$B$8)+M6,0) -> 1051 | Q6: =MAX(0,P6-O6) -> 1051 | R6: =ROUNDUP(H6*(L6+PARAMETROS!$B$9)+M6,0) -> 1379 | S6: =MAX(0,R6-O6) -> 1379 | T6: =ROUNDUP(H6*(L6+PARAMETROS!$B$10)+M6,0) -> 2129 | U6: =MAX(0,T6-O6) -> 2129
A7: BOLSAS MEDIANAS NAVIDAD 2024 | B7: SUMINISTROS | C7: 11 | D7: 2450 | E7: 2450 | F7: 0 | G7: 1 | H7: 42.2414 | I7: 283.3946 | J7: Y · Variable | K7: =IF(LEFT(J7,1)="X",PARAMETROS!$B$11,IF(LEFT(J7,1)="Y",PARAMETROS!$B$12,PARAMETROS!$B$13)) -> 1.28 | L7: =PARAMETROS!$B$7 -> 7 | M7: =ROUND(K7*I7*SQRT(L7/7),2) -> 362.75 | N7: =ROUNDUP(H7*L7+M7,0) -> 659 | O7: 0 | P7: =ROUNDUP(H7*(L7+PARAMETROS!$B$8)+M7,0) -> 955 | Q7: =MAX(0,P7-O7) -> 955 | R7: =ROUNDUP(H7*(L7+PARAMETROS!$B$9)+M7,0) -> 1250 | S7: =MAX(0,R7-O7) -> 1250 | T7: =ROUNDUP(H7*(L7+PARAMETROS!$B$10)+M7,0) -> 1926 | U7: =MAX(0,T7-O7) -> 1926
A8: BOLSAS GRANDES KRAFT | B8: SUMINISTROS | C8: 7 | D8: 1200 | E8: 1200 | F8: 0 | G8: 1 | H8: 20.6897 | I8: 190.8627 | J8: Z · Intermitente | K8: =IF(LEFT(J8,1)="X",PARAMETROS!$B$11,IF(LEFT(J8,1)="Y",PARAMETROS!$B$12,PARAMETROS!$B$13)) -> 0.84 | L8: =PARAMETROS!$B$7 -> 7 | M8: =ROUND(K8*I8*SQRT(L8/7),2) -> 160.32 | N8: =ROUNDUP(H8*L8+M8,0) -> 306 | O8: 0 | P8: =ROUNDUP(H8*(L8+PARAMETROS!$B$8)+M8,0) -> 450 | Q8: =MAX(0,P8-O8) -> 450 | R8: =ROUNDUP(H8*(L8+PARAMETROS!$B$9)+M8,0) -> 595 | S8: =MAX(0,R8-O8) -> 595 | T8: =ROUNDUP(H8*(L8+PARAMETROS!$B$10)+M8,0) -> 926 | U8: =MAX(0,T8-O8) -> 926
A9: STICKER ADHESIVO DE CIERRE | B9: SUMINISTROS | C9: 5 | D9: 800 | E9: 800 | F9: 0 | G9: 1 | H9: 13.7931 | I9: 141.4214 | J9: Z · Intermitente | K9: =IF(LEFT(J9,1)="X",PARAMETROS!$B$11,IF(LEFT(J9,1)="Y",PARAMETROS!$B$12,PARAMETROS!$B$13)) -> 0.84 | L9: =PARAMETROS!$B$7 -> 7 | M9: =ROUND(K9*I9*SQRT(L9/7),2) -> 118.79 | N9: =ROUNDUP(H9*L9+M9,0) -> 216 | O9: 0 | P9: =ROUNDUP(H9*(L9+PARAMETROS!$B$8)+M9,0) -> 312 | Q9: =MAX(0,P9-O9) -> 312 | R9: =ROUNDUP(H9*(L9+PARAMETROS!$B$9)+M9,0) -> 409 | S9: =MAX(0,R9-O9) -> 409 | T9: =ROUNDUP(H9*(L9+PARAMETROS!$B$10)+M9,0) -> 630 | U9: =MAX(0,T9-O9) -> 630
A10: BOLSAS EXTRA PEQUEÑA KRAFT | B10: SUMINISTROS | C10: 4 | D10: 550 | E10: 550 | F10: 0 | G10: 1 | H10: 9.4828 | I10: 109.3814 | J10: Z · Intermitente | K10: =IF(LEFT(J10,1)="X",PARAMETROS!$B$11,IF(LEFT(J10,1)="Y",PARAMETROS!$B$12,PARAMETROS!$B$13)) -> 0.84 | L10: =PARAMETROS!$B$7 -> 7 | M10: =ROUND(K10*I10*SQRT(L10/7),2) -> 91.88 | N10: =ROUNDUP(H10*L10+M10,0) -> 159 | O10: 0 | P10: =ROUNDUP(H10*(L10+PARAMETROS!$B$8)+M10,0) -> 225 | Q10: =MAX(0,P10-O10) -> 225 | R10: =ROUNDUP(H10*(L10+PARAMETROS!$B$9)+M10,0) -> 292 | S10: =MAX(0,R10-O10) -> 292 | T10: =ROUNDUP(H10*(L10+PARAMETROS!$B$10)+M10,0) -> 443 | U10: =MAX(0,T10-O10) -> 443
A11: BOLSA DE PAPELERA | B11: LIMPIEZA E HIGIENE | C11: 18 | D11: 505 | E11: 365 | F11: 140 | G11: 0.72277228 | H11: 8.7069 | I11: 27.0499 | J11: Y · Variable | K11: =IF(LEFT(J11,1)="X",PARAMETROS!$B$11,IF(LEFT(J11,1)="Y",PARAMETROS!$B$12,PARAMETROS!$B$13)) -> 1.28 | L11: =PARAMETROS!$B$7 -> 7 | M11: =ROUND(K11*I11*SQRT(L11/7),2) -> 34.62 | N11: =ROUNDUP(H11*L11+M11,0) -> 96 | O11: 0 | P11: =ROUNDUP(H11*(L11+PARAMETROS!$B$8)+M11,0) -> 157 | Q11: =MAX(0,P11-O11) -> 157 | R11: =ROUNDUP(H11*(L11+PARAMETROS!$B$9)+M11,0) -> 218 | S11: =MAX(0,R11-O11) -> 218 | T11: =ROUNDUP(H11*(L11+PARAMETROS!$B$10)+M11,0) -> 357 | U11: =MAX(0,T11-O11) -> 357
A12: BOLSAS PEQUEÑAS KRAFT | B12: SUMINISTROS | C12: 1 | D12: 400 | E12: 400 | F12: 0 | G12: 1 | H12: 6.8966 | I12: 141.4214 | J12: Z · Intermitente | K12: =IF(LEFT(J12,1)="X",PARAMETROS!$B$11,IF(LEFT(J12,1)="Y",PARAMETROS!$B$12,PARAMETROS!$B$13)) -> 0.84 | L12: =PARAMETROS!$B$7 -> 7 | M12: =ROUND(K12*I12*SQRT(L12/7),2) -> 118.79 | N12: =ROUNDUP(H12*L12+M12,0) -> 168 | O12: 0 | P12: =ROUNDUP(H12*(L12+PARAMETROS!$B$8)+M12,0) -> 216 | Q12: =MAX(0,P12-O12) -> 216 | R12: =ROUNDUP(H12*(L12+PARAMETROS!$B$9)+M12,0) -> 264 | S12: =MAX(0,R12-O12) -> 264 | T12: =ROUNDUP(H12*(L12+PARAMETROS!$B$10)+M12,0) -> 374 | U12: =MAX(0,T12-O12) -> 374
A13: BOLSAS DE BASURA | B13: LIMPIEZA E HIGIENE | C13: 12 | D13: 386 | E13: 336 | F13: 50 | G13: 0.87046632 | H13: 6.6552 | I13: 31.1253 | J13: Y · Variable | K13: =IF(LEFT(J13,1)="X",PARAMETROS!$B$11,IF(LEFT(J13,1)="Y",PARAMETROS!$B$12,PARAMETROS!$B$13)) -> 1.28 | L13: =PARAMETROS!$B$7 -> 7 | M13: =ROUND(K13*I13*SQRT(L13/7),2) -> 39.84 | N13: =ROUNDUP(H13*L13+M13,0) -> 87 | O13: 0 | P13: =ROUNDUP(H13*(L13+PARAMETROS!$B$8)+M13,0) -> 134 | Q13: =MAX(0,P13-O13) -> 134 | R13: =ROUNDUP(H13*(L13+PARAMETROS!$B$9)+M13,0) -> 180 | S13: =MAX(0,R13-O13) -> 180 | T13: =ROUNDUP(H13*(L13+PARAMETROS!$B$10)+M13,0) -> 287 | U13: =MAX(0,T13-O13) -> 287
A14: BOLSA DE ENVIO MEDIANA | B14: SUMINISTROS | C14: 7 | D14: 266 | E14: 196 | F14: 70 | G14: 0.73684211 | H14: 4.5862 | I14: 34.2762 | J14: Z · Intermitente | K14: =IF(LEFT(J14,1)="X",PARAMETROS!$B$11,IF(LEFT(J14,1)="Y",PARAMETROS!$B$12,PARAMETROS!$B$13)) -> 0.84 | L14: =PARAMETROS!$B$7 -> 7 | M14: =ROUND(K14*I14*SQRT(L14/7),2) -> 28.79 | N14: =ROUNDUP(H14*L14+M14,0) -> 61 | O14: 0 | P14: =ROUNDUP(H14*(L14+PARAMETROS!$B$8)+M14,0) -> 93 | Q14: =MAX(0,P14-O14) -> 93 | R14: =ROUNDUP(H14*(L14+PARAMETROS!$B$9)+M14,0) -> 126 | S14: =MAX(0,R14-O14) -> 126 | T14: =ROUNDUP(H14*(L14+PARAMETROS!$B$10)+M14,0) -> 199 | U14: =MAX(0,T14-O14) -> 199
A15: BOLSAS MEDIANAS KRAFT | B15: SUMINISTROS | C15: 1 | D15: 250 | E15: 250 | F15: 0 | G15: 1 | H15: 4.3103 | I15: 88.3883 | J15: Z · Intermitente | K15: =IF(LEFT(J15,1)="X",PARAMETROS!$B$11,IF(LEFT(J15,1)="Y",PARAMETROS!$B$12,PARAMETROS!$B$13)) -> 0.84 | L15: =PARAMETROS!$B$7 -> 7 | M15: =ROUND(K15*I15*SQRT(L15/7),2) -> 74.25 | N15: =ROUNDUP(H15*L15+M15,0) -> 105 | O15: 0 | P15: =ROUNDUP(H15*(L15+PARAMETROS!$B$8)+M15,0) -> 135 | Q15: =MAX(0,P15-O15) -> 135 | R15: =ROUNDUP(H15*(L15+PARAMETROS!$B$9)+M15,0) -> 165 | S15: =MAX(0,R15-O15) -> 165 | T15: =ROUNDUP(H15*(L15+PARAMETROS!$B$10)+M15,0) -> 234 | U15: =MAX(0,T15-O15) -> 234
A16: SOBRES DE BILLETES | B16: OFICINA | C16: 3 | D16: 200 | E16: 200 | F16: 0 | G16: 1 | H16: 3.4483 | I16: 37.2012 | J16: Z · Intermitente | K16: =IF(LEFT(J16,1)="X",PARAMETROS!$B$11,IF(LEFT(J16,1)="Y",PARAMETROS!$B$12,PARAMETROS!$B$13)) -> 0.84 | L16: =PARAMETROS!$B$7 -> 7 | M16: =ROUND(K16*I16*SQRT(L16/7),2) -> 31.25 | N16: =ROUNDUP(H16*L16+M16,0) -> 56 | O16: 0 | P16: =ROUNDUP(H16*(L16+PARAMETROS!$B$8)+M16,0) -> 80 | Q16: =MAX(0,P16-O16) -> 80 | R16: =ROUNDUP(H16*(L16+PARAMETROS!$B$9)+M16,0) -> 104 | S16: =MAX(0,R16-O16) -> 104 | T16: =ROUNDUP(H16*(L16+PARAMETROS!$B$10)+M16,0) -> 159 | U16: =MAX(0,T16-O16) -> 159
... A84: TONER 05A/80A | B84: EQUIPOS DE OFICINA | C84: 1 | D84: 1 | E84: 1 | F84: 0 | G84: 1 | H84: 0.0172 | I84: 0.3536 | J84: Z · Intermitente | K84: =IF(LEFT(J84,1)="X",PARAMETROS!$B$11,IF(LEFT(J84,1)="Y",PARAMETROS!$B$12,PARAMETROS!$B$13)) -> 0.84 | L84: =PARAMETROS!$B$7 -> 7 | M84: =ROUND(K84*I84*SQRT(L84/7),2) -> 0.3 | N84: =ROUNDUP(H84*L84+M84,0) -> 1 | O84: 0 | P84: =ROUNDUP(H84*(L84+PARAMETROS!$B$8)+M84,0) -> 1 | Q84: =MAX(0,P84-O84) -> 1 | R84: =ROUNDUP(H84*(L84+PARAMETROS!$B$9)+M84,0) -> 1 | S84: =MAX(0,R84-O84) -> 1 | T84: =ROUNDUP(H84*(L84+PARAMETROS!$B$10)+M84,0) -> 1 | U84: =MAX(0,T84-O84) -> 1
A85: TOTAL | C85: =SUM(C5:C84) -> 418 | D85: =SUM(D5:D84) -> 15741 | E85: =SUM(E5:E84) -> 15238 | F85: =SUM(F5:F84) -> 503 | G85: =E85/D85 -> 0.96804523 | H85: =SUM(H5:H84) -> 271.3966 | N85: =SUM(N5:N84) -> 4177 | P85: =SUM(P5:P84) -> 6081 | Q85: =SUM(Q5:Q84) -> 6081 | R85: =SUM(R5:R84) -> 7977 | S85: =SUM(S5:S84) -> 7977 | T85: =SUM(T5:T84) -> 12316 | U85: =SUM(U5:U84) -> 12316
A87: ✎ Celdas amarillas editables: LEAD TIME por producto, z de NIVEL DE SERVICIO y STOCK ACTUAL; SS, MIN, MAX y PEDIDO se recalculan solos. PEDIDO = MAX − STOCK ACTUAL (si el stock es 0, el pedido parte de cero). MIN = D×LT + SS · MAX = D×(LT+P) + SS (P = 7/14/30 días) · SS = z×σ semanal×√(LT/7). CLASE DEMANDA: X regular / Y variable / Z intermitente — define el z inicial (95%/90%/80%, configurable en PARAMETROS). Ítems Z: evaluar compra bajo pedido.

Sheet UNIFICADO
A1: UNIFICADO (TALLER + TIENDAS) — PEDIDO CONSOLIDADO POR PRODUCTO
A2: Una fila por producto. MIN = punto de reorden = D×LT + SS · MAX = stock objetivo = D×(LT+P) + SS (P = 7/14/30 días) · PEDIDO = MAX − stock actual. Celdas amarillas editables (z de servicio, lead time y stock actual): todo se recalcula. CLASE DEMANDA: X regular / Y variable / Z intermitente. La demanda usada es la SOLICITADA (incluye lo que quedó NO DISPONIBLE). Esta es la hoja principal para armar el pedido único de consumibles; luego repártalo con las hojas de DISTRIBUCIÓN.
A4: PRODUCTO | B4: CATEGORÍA | C4: Nº SOLICITUDES | D4: UNDS SOLICITADAS (2m) | E4: UNDS ATENDIDAS | F4: UNDS NO DISPONIBLES | G4: % ATENCIÓN (UNDS) | H4: DEMANDA DIARIA (D) | I4: σ SEMANAL | J4: CLASE DEMANDA | K4: z NIVEL SERVICIO ✎ | L4: LEAD TIME (DÍAS) ✎ | M4: STOCK SEGURIDAD (SS) | N4: MIN = PUNTO REORDEN | O4: STOCK ACTUAL ✎ | P4: MAX SEMANAL | Q4: PEDIDO SEMANAL | R4: MAX QUINCENAL | S4: PEDIDO QUINCENAL | T4: MAX MENSUAL | U4: PEDIDO MENSUAL
A5: STICKER DE REGALO | B5: SUMINISTROS | C5: 22 | D5: 5200 | E5: 5200 | F5: 0 | G5: 1 | H5: 88.1356 | I5: 505.6379 | J5: Y · Variable | K5: =IF(LEFT(J5,1)="X",PARAMETROS!$B$11,IF(LEFT(J5,1)="Y",PARAMETROS!$B$12,PARAMETROS!$B$13)) -> 1.28 | L5: =PARAMETROS!$B$7 -> 7 | M5: =ROUND(K5*I5*SQRT(L5/7),2) -> 647.22 | N5: =ROUNDUP(H5*L5+M5,0) -> 1265 | O5: 0 | P5: =ROUNDUP(H5*(L5+PARAMETROS!$B$8)+M5,0) -> 1882 | Q5: =MAX(0,P5-O5) -> 1882 | R5: =ROUNDUP(H5*(L5+PARAMETROS!$B$9)+M5,0) -> 2499 | S5: =MAX(0,R5-O5) -> 2499 | T5: =ROUNDUP(H5*(L5+PARAMETROS!$B$10)+M5,0) -> 3909 | U5: =MAX(0,T5-O5) -> 3909
A6: BOLSAS PEQUEÑAS NAVIDAD 2024 | B6: SUMINISTROS | C6: 16 | D6: 2770 | E6: 2770 | F6: 0 | G6: 1 | H6: 46.9492 | I6: 304.3465 | J6: Y · Variable | K6: =IF(LEFT(J6,1)="X",PARAMETROS!$B$11,IF(LEFT(J6,1)="Y",PARAMETROS!$B$12,PARAMETROS!$B$13)) -> 1.28 | L6: =PARAMETROS!$B$7 -> 7 | M6: =ROUND(K6*I6*SQRT(L6/7),2) -> 389.56 | N6: =ROUNDUP(H6*L6+M6,0) -> 719 | O6: 0 | P6: =ROUNDUP(H6*(L6+PARAMETROS!$B$8)+M6,0) -> 1047 | Q6: =MAX(0,P6-O6) -> 1047 | R6: =ROUNDUP(H6*(L6+PARAMETROS!$B$9)+M6,0) -> 1376 | S6: =MAX(0,R6-O6) -> 1376 | T6: =ROUNDUP(H6*(L6+PARAMETROS!$B$10)+M6,0) -> 2127 | U6: =MAX(0,T6-O6) -> 2127
A7: BOLSAS MEDIANAS NAVIDAD 2024 | B7: SUMINISTROS | C7: 12 | D7: 2460 | E7: 2460 | F7: 0 | G7: 1 | H7: 41.6949 | I7: 284.8935 | J7: Y · Variable | K7: =IF(LEFT(J7,1)="X",PARAMETROS!$B$11,IF(LEFT(J7,1)="Y",PARAMETROS!$B$12,PARAMETROS!$B$13)) -> 1.28 | L7: =PARAMETROS!$B$7 -> 7 | M7: =ROUND(K7*I7*SQRT(L7/7),2) -> 364.66 | N7: =ROUNDUP(H7*L7+M7,0) -> 657 | O7: 0 | P7: =ROUNDUP(H7*(L7+PARAMETROS!$B$8)+M7,0) -> 949 | Q7: =MAX(0,P7-O7) -> 949 | R7: =ROUNDUP(H7*(L7+PARAMETROS!$B$9)+M7,0) -> 1241 | S7: =MAX(0,R7-O7) -> 1241 | T7: =ROUNDUP(H7*(L7+PARAMETROS!$B$10)+M7,0) -> 1908 | U7: =MAX(0,T7-O7) -> 1908
A8: BOLSAS GRANDES KRAFT | B8: SUMINISTROS | C8: 8 | D8: 1210 | E8: 1210 | F8: 0 | G8: 1 | H8: 20.5085 | I8: 192.0147 | J8: Z · Intermitente | K8: =IF(LEFT(J8,1)="X",PARAMETROS!$B$11,IF(LEFT(J8,1)="Y",PARAMETROS!$B$12,PARAMETROS!$B$13)) -> 0.84 | L8: =PARAMETROS!$B$7 -> 7 | M8: =ROUND(K8*I8*SQRT(L8/7),2) -> 161.29 | N8: =ROUNDUP(H8*L8+M8,0) -> 305 | O8: 0 | P8: =ROUNDUP(H8*(L8+PARAMETROS!$B$8)+M8,0) -> 449 | Q8: =MAX(0,P8-O8) -> 449 | R8: =ROUNDUP(H8*(L8+PARAMETROS!$B$9)+M8,0) -> 592 | S8: =MAX(0,R8-O8) -> 592 | T8: =ROUNDUP(H8*(L8+PARAMETROS!$B$10)+M8,0) -> 921 | U8: =MAX(0,T8-O8) -> 921
A9: STICKER ADHESIVO DE CIERRE | B9: SUMINISTROS | C9: 5 | D9: 800 | E9: 800 | F9: 0 | G9: 1 | H9: 13.5593 | I9: 141.4214 | J9: Z · Intermitente | K9: =IF(LEFT(J9,1)="X",PARAMETROS!$B$11,IF(LEFT(J9,1)="Y",PARAMETROS!$B$12,PARAMETROS!$B$13)) -> 0.84 | L9: =PARAMETROS!$B$7 -> 7 | M9: =ROUND(K9*I9*SQRT(L9/7),2) -> 118.79 | N9: =ROUNDUP(H9*L9+M9,0) -> 214 | O9: 0 | P9: =ROUNDUP(H9*(L9+PARAMETROS!$B$8)+M9,0) -> 309 | Q9: =MAX(0,P9-O9) -> 309 | R9: =ROUNDUP(H9*(L9+PARAMETROS!$B$9)+M9,0) -> 404 | S9: =MAX(0,R9-O9) -> 404 | T9: =ROUNDUP(H9*(L9+PARAMETROS!$B$10)+M9,0) -> 621 | U9: =MAX(0,T9-O9) -> 621
A10: BOLSAS EXTRA PEQUEÑA KRAFT | B10: SUMINISTROS | C10: 4 | D10: 550 | E10: 550 | F10: 0 | G10: 1 | H10: 9.322 | I10: 109.3814 | J10: Z · Intermitente | K10: =IF(LEFT(J10,1)="X",PARAMETROS!$B$11,IF(LEFT(J10,1)="Y",PARAMETROS!$B$12,PARAMETROS!$B$13)) -> 0.84 | L10: =PARAMETROS!$B$7 -> 7 | M10: =ROUND(K10*I10*SQRT(L10/7),2) -> 91.88 | N10: =ROUNDUP(H10*L10+M10,0) -> 158 | O10: 0 | P10: =ROUNDUP(H10*(L10+PARAMETROS!$B$8)+M10,0) -> 223 | Q10: =MAX(0,P10-O10) -> 223 | R10: =ROUNDUP(H10*(L10+PARAMETROS!$B$9)+M10,0) -> 288 | S10: =MAX(0,R10-O10) -> 288 | T10: =ROUNDUP(H10*(L10+PARAMETROS!$B$10)+M10,0) -> 437 | U10: =MAX(0,T10-O10) -> 437
A11: BOLSA DE PAPELERA | B11: LIMPIEZA E HIGIENE | C11: 19 | D11: 530 | E11: 390 | F11: 140 | G11: 0.73584906 | H11: 8.9831 | I11: 29.6106 | J11: Y · Variable | K11: =IF(LEFT(J11,1)="X",PARAMETROS!$B$11,IF(LEFT(J11,1)="Y",PARAMETROS!$B$12,PARAMETROS!$B$13)) -> 1.28 | L11: =PARAMETROS!$B$7 -> 7 | M11: =ROUND(K11*I11*SQRT(L11/7),2) -> 37.9 | N11: =ROUNDUP(H11*L11+M11,0) -> 101 | O11: 0 | P11: =ROUNDUP(H11*(L11+PARAMETROS!$B$8)+M11,0) -> 164 | Q11: =MAX(0,P11-O11) -> 164 | R11: =ROUNDUP(H11*(L11+PARAMETROS!$B$9)+M11,0) -> 227 | S11: =MAX(0,R11-O11) -> 227 | T11: =ROUNDUP(H11*(L11+PARAMETROS!$B$10)+M11,0) -> 371 | U11: =MAX(0,T11-O11) -> 371
A12: BOLSAS DE BASURA | B12: LIMPIEZA E HIGIENE | C12: 22 | D12: 438 | E12: 388 | F12: 50 | G12: 0.88584475 | H12: 7.4237 | I12: 29.8795 | J12: Y · Variable | K12: =IF(LEFT(J12,1)="X",PARAMETROS!$B$11,IF(LEFT(J12,1)="Y",PARAMETROS!$B$12,PARAMETROS!$B$13)) -> 1.28 | L12: =PARAMETROS!$B$7 -> 7 | M12: =ROUND(K12*I12*SQRT(L12/7),2) -> 38.25 | N12: =ROUNDUP(H12*L12+M12,0) -> 91 | O12: 0 | P12: =ROUNDUP(H12*(L12+PARAMETROS!$B$8)+M12,0) -> 143 | Q12: =MAX(0,P12-O12) -> 143 | R12: =ROUNDUP(H12*(L12+PARAMETROS!$B$9)+M12,0) -> 195 | S12: =MAX(0,R12-O12) -> 195 | T12: =ROUNDUP(H12*(L12+PARAMETROS!$B$10)+M12,0) -> 313 | U12: =MAX(0,T12-O12) -> 313
A13: BOLSAS PEQUEÑAS KRAFT | B13: SUMINISTROS | C13: 1 | D13: 400 | E13: 400 | F13: 0 | G13: 1 | H13: 6.7797 | I13: 141.4214 | J13: Z · Intermitente | K13: =IF(LEFT(J13,1)="X",PARAMETROS!$B$11,IF(LEFT(J13,1)="Y",PARAMETROS!$B$12,PARAMETROS!$B$13)) -> 0.84 | L13: =PARAMETROS!$B$7 -> 7 | M13: =ROUND(K13*I13*SQRT(L13/7),2) -> 118.79 | N13: =ROUNDUP(H13*L13+M13,0) -> 167 | O13: 0 | P13: =ROUNDUP(H13*(L13+PARAMETROS!$B$8)+M13,0) -> 214 | Q13: =MAX(0,P13-O13) -> 214 | R13: =ROUNDUP(H13*(L13+PARAMETROS!$B$9)+M13,0) -> 262 | S13: =MAX(0,R13-O13) -> 262 | T13: =ROUNDUP(H13*(L13+PARAMETROS!$B$10)+M13,0) -> 370 | U13: =MAX(0,T13-O13) -> 370
A14: BOLSA DE ENVIO MEDIANA | B14: SUMINISTROS | C14: 9 | D14: 301 | E14: 231 | F14: 70 | G14: 0.76744186 | H14: 5.1017 | I14: 32.6144 | J14: Z · Intermitente | K14: =IF(LEFT(J14,1)="X",PARAMETROS!$B$11,IF(LEFT(J14,1)="Y",PARAMETROS!$B$12,PARAMETROS!$B$13)) -> 0.84 | L14: =PARAMETROS!$B$7 -> 7 | M14: =ROUND(K14*I14*SQRT(L14/7),2) -> 27.4 | N14: =ROUNDUP(H14*L14+M14,0) -> 64 | O14: 0 | P14: =ROUNDUP(H14*(L14+PARAMETROS!$B$8)+M14,0) -> 99 | Q14: =MAX(0,P14-O14) -> 99 | R14: =ROUNDUP(H14*(L14+PARAMETROS!$B$9)+M14,0) -> 135 | S14: =MAX(0,R14-O14) -> 135 | T14: =ROUNDUP(H14*(L14+PARAMETROS!$B$10)+M14,0) -> 217 | U14: =MAX(0,T14-O14) -> 217
A15: BOLSAS MEDIANAS KRAFT | B15: SUMINISTROS | C15: 1 | D15: 250 | E15: 250 | F15: 0 | G15: 1 | H15: 4.2373 | I15: 88.3883 | J15: Z · Intermitente | K15: =IF(LEFT(J15,1)="X",PARAMETROS!$B$11,IF(LEFT(J15,1)="Y",PARAMETROS!$B$12,PARAMETROS!$B$13)) -> 0.84 | L15: =PARAMETROS!$B$7 -> 7 | M15: =ROUND(K15*I15*SQRT(L15/7),2) -> 74.25 | N15: =ROUNDUP(H15*L15+M15,0) -> 104 | O15: 0 | P15: =ROUNDUP(H15*(L15+PARAMETROS!$B$8)+M15,0) -> 134 | Q15: =MAX(0,P15-O15) -> 134 | R15: =ROUNDUP(H15*(L15+PARAMETROS!$B$9)+M15,0) -> 164 | S15: =MAX(0,R15-O15) -> 164 | T15: =ROUNDUP(H15*(L15+PARAMETROS!$B$10)+M15,0) -> 232 | U15: =MAX(0,T15-O15) -> 232
A16: SOBRES DE BILLETES | B16: OFICINA | C16: 4 | D16: 210 | E16: 210 | F16: 0 | G16: 1 | H16: 3.5593 | I16: 40.3556 | J16: Z · Intermitente | K16: =IF(LEFT(J16,1)="X",PARAMETROS!$B$11,IF(LEFT(J16,1)="Y",PARAMETROS!$B$12,PARAMETROS!$B$13)) -> 0.84 | L16: =PARAMETROS!$B$7 -> 7 | M16: =ROUND(K16*I16*SQRT(L16/7),2) -> 33.9 | N16: =ROUNDUP(H16*L16+M16,0) -> 59 | O16: 0 | P16: =ROUNDUP(H16*(L16+PARAMETROS!$B$8)+M16,0) -> 84 | Q16: =MAX(0,P16-O16) -> 84 | R16: =ROUNDUP(H16*(L16+PARAMETROS!$B$9)+M16,0) -> 109 | S16: =MAX(0,R16-O16) -> 109 | T16: =ROUNDUP(H16*(L16+PARAMETROS!$B$10)+M16,0) -> 166 | U16: =MAX(0,T16-O16) -> 166
... A101: TONER SAMSUNG 111 | B101: EQUIPOS DE OFICINA | C101: 1 | D101: 1 | E101: 1 | F101: 0 | G101: 1 | H101: 0.0169 | I101: 0.3536 | J101: Z · Intermitente | K101: =IF(LEFT(J101,1)="X",PARAMETROS!$B$11,IF(LEFT(J101,1)="Y",PARAMETROS!$B$12,PARAMETROS!$B$13)) -> 0.84 | L101: =PARAMETROS!$B$7 -> 7 | M101: =ROUND(K101*I101*SQRT(L101/7),2) -> 0.3 | N101: =ROUNDUP(H101*L101+M101,0) -> 1 | O101: 0 | P101: =ROUNDUP(H101*(L101+PARAMETROS!$B$8)+M101,0) -> 1 | Q101: =MAX(0,P101-O101) -> 1 | R101: =ROUNDUP(H101*(L101+PARAMETROS!$B$9)+M101,0) -> 1 | S101: =MAX(0,R101-O101) -> 1 | T101: =ROUNDUP(H101*(L101+PARAMETROS!$B$10)+M101,0) -> 1 | U101: =MAX(0,T101-O101) -> 1
A102: TOTAL | C102: =SUM(C5:C101) -> 573 | D102: =SUM(D5:D101) -> 16199 | E102: =SUM(E5:E101) -> 15673 | F102: =SUM(F5:F101) -> 526 | G102: =E102/D102 -> 0.96752886 | H102: =SUM(H5:H101) -> 274.5593 | N102: =SUM(N5:N101) -> 4239 | P102: =SUM(P5:P101) -> 6167 | Q102: =SUM(Q5:Q101) -> 6167 | R102: =SUM(R5:R101) -> 8092 | S102: =SUM(S5:S101) -> 8092 | T102: =SUM(T5:T101) -> 12474 | U102: =SUM(U5:U101) -> 12474
A104: ✎ Celdas amarillas editables: LEAD TIME por producto, z de NIVEL DE SERVICIO y STOCK ACTUAL; SS, MIN, MAX y PEDIDO se recalculan solos. PEDIDO = MAX − STOCK ACTUAL (si el stock es 0, el pedido parte de cero). MIN = D×LT + SS · MAX = D×(LT+P) + SS (P = 7/14/30 días) · SS = z×σ semanal×√(LT/7). CLASE DEMANDA: X regular / Y variable / Z intermitente — define el z inicial (95%/90%/80%, configurable en PARAMETROS). Ítems Z: evaluar compra bajo pedido.

Sheet DISTRIBUCION TIENDAS
A1: DISTRIBUCIÓN DEL CONSUMO POR TIENDA (UNDS SOLICITADAS, 2 MESES)
A2: Cuántas unidades pidió cada tienda de cada producto. Úsela para repartir el pedido unificado entre las tiendas según su consumo real. La última columna es el total por producto.
A4: PRODUCTO | B4: CERRO VERDE | C4: GRAND PLAZ | D4: GRIETA | E4: MARGARITA | F4: SAMBIL CHACAO | G4: SAMBIL VALENCIA | H4: TOLON | I4: TOTAL
A5: STICKER DE REGALO | B5: 1150 | C5: 0 | D5: 1400 | E5: 0 | F5: 1400 | G5: 700 | H5: 550 | I5: 5200
A6: BOLSAS PEQUEÑAS NAVIDAD 2024 | B6: 700 | C6: 0 | D6: 900 | E6: 0 | F6: 200 | G6: 900 | H6: 20 | I6: 2720
A7: BOLSAS MEDIANAS NAVIDAD 2024 | B7: 750 | C7: 0 | D7: 700 | E7: 0 | F7: 400 | G7: 600 | H7: 0 | I7: 2450
A8: BOLSAS GRANDES KRAFT | B8: 350 | C8: 150 | D8: 200 | E8: 100 | F8: 0 | G8: 400 | H8: 0 | I8: 1200
A9: STICKER ADHESIVO DE CIERRE | B9: 0 | C9: 500 | D9: 0 | E9: 0 | F9: 300 | G9: 0 | H9: 0 | I9: 800
A10: BOLSAS EXTRA PEQUEÑA KRAFT | B10: 0 | C10: 0 | D10: 150 | E10: 50 | F10: 0 | G10: 300 | H10: 50 | I10: 550
A11: BOLSA DE PAPELERA | B11: 50 | C11: 10 | D11: 145 | E11: 30 | F11: 100 | G11: 50 | H11: 120 | I11: 505
A12: BOLSAS PEQUEÑAS KRAFT | B12: 0 | C12: 0 | D12: 0 | E12: 400 | F12: 0 | G12: 0 | H12: 0 | I12: 400
A13: BOLSAS DE BASURA | B13: 80 | C13: 25 | D13: 140 | E13: 0 | F13: 85 | G13: 0 | H13: 56 | I13: 386
A14: BOLSA DE ENVIO MEDIANA | B14: 100 | C14: 0 | D14: 135 | E14: 0 | F14: 0 | G14: 31 | H14: 0 | I14: 266
A15: BOLSAS MEDIANAS KRAFT | B15: 0 | C15: 0 | D15: 0 | E15: 250 | F15: 0 | G15: 0 | H15: 0 | I15: 250
A16: SOBRES DE BILLETES | B16: 0 | C16: 0 | D16: 100 | E16: 0 | F16: 0 | G16: 100 | H16: 0 | I16: 200
... A84: TONER 05A/80A | B84: 0 | C84: 0 | D84: 1 | E84: 0 | F84: 0 | G84: 0 | H84: 0 | I84: 1
A85: TOTAL | B85: =SUM(B5:B84) -> 3349 | C85: =SUM(C5:C84) -> 707 | D85: =SUM(D5:D84) -> 4030 | E85: =SUM(E5:E84) -> 867 | F85: =SUM(F5:F84) -> 2618 | G85: =SUM(G5:G84) -> 3208 | H85: =SUM(H5:H84) -> 962 | I85: =SUM(I5:I84) -> 15741

Sheet DISTRIBUCION TALLER
A1: DISTRIBUCIÓN DEL CONSUMO POR SUB-ÁREA DEL TALLER (UNDS, 2 MESES)
A2: Cuántas unidades pidió cada sub-área (TALLER, I+D, ALMACEN, MANTENIMIENTO, RRHH, OFICINAS) de cada producto, para repartir el pedido del taller.
A4: PRODUCTO | B4: ALMACEN | C4: I+D | D4: MANTENIMIENTO | E4: OFICINAS | F4: RECURSOS HUMANOS | G4: TALLER | H4: TOTAL
A5: BOLSAS DE BASURA | B5: 3 | C5: 0 | D5: 25 | E5: 0 | F5: 0 | G5: 24 | H5: 52
A6: BOLSAS PEQUEÑAS NAVIDAD 2024 | B6: 0 | C6: 0 | D6: 0 | E6: 0 | F6: 0 | G6: 50 | H6: 50
A7: BOLSA DE ENVIO MEDIANA | B7: 0 | C7: 0 | D7: 0 | E7: 0 | F7: 0 | G7: 35 | H7: 35
A8: LAPIZ | B8: 0 | C8: 3 | D8: 0 | E8: 0 | F8: 3 | G8: 29 | H8: 35
A9: BOLIGRAFOS | B9: 4 | C9: 5 | D9: 0 | E9: 0 | F9: 0 | G9: 20 | H9: 29
A10: BOLSA DE PAPELERA | B10: 0 | C10: 0 | D10: 25 | E10: 0 | F10: 0 | G10: 0 | H10: 25
A11: TAPABOCAS | B11: 0 | C11: 0 | D11: 0 | E11: 0 | F11: 0 | G11: 21 | H11: 21
A12: CINTA DE EMBALAJE | B12: 14 | C12: 0 | D12: 0 | E12: 0 | F12: 0 | G12: 6 | H12: 20
A13: TIRRO | B13: 0 | C13: 5 | D13: 0 | E13: 0 | F13: 0 | G13: 11 | H13: 16
A14: CINTA METRICA | B14: 0 | C14: 3 | D14: 0 | E14: 0 | F14: 0 | G14: 10 | H14: 13
A15: PIQUETAS | B15: 1 | C15: 3 | D15: 0 | E15: 0 | F15: 0 | G15: 8 | H15: 12
A16: BOLSA DE ENVIO GRANDE | B16: 0 | C16: 0 | D16: 0 | E16: 0 | F16: 0 | G16: 10 | H16: 10
... A59: VENSOL | B59: 0 | C59: 0 | D59: 0 | E59: 0 | F59: 0 | G59: 1 | H59: 1
A60: TOTAL | B60: =SUM(B5:B59) -> 31 | C60: =SUM(C5:C59) -> 55 | D60: =SUM(D5:D59) -> 69 | E60: =SUM(E5:E59) -> 1 | F60: =SUM(F5:F59) -> 4 | G60: =SUM(G5:G59) -> 298 | H60: =SUM(H5:H59) -> 458

Sheet TENDENCIA SEMANAL
A1: TENDENCIA SEMANAL DE SOLICITUDES Y UNIDADES
A2: Consumo semana a semana (semanas inician en lunes). Sirve para verificar que la demanda es estable y que los promedios usados en el modelo son representativos.
A4: SEMANA (LUNES) | B4: SOL. TALLER | C4: UNDS TALLER | D4: SOL. TIENDAS | E4: UNDS TIENDAS | F4: SOL. TOTAL | G4: UNDS TOTAL
A5: Sem. 08/06 | B5: 37 | C5: 126 | D5: 60 | E5: 2226 | F5: 97 | G5: 2352
A6: Sem. 15/06 | B6: 19 | C6: 54 | D6: 45 | E6: 2491 | F6: 64 | G6: 2545
A7: Sem. 22/06 | B7: 8 | C7: 26 | D7: 47 | E7: 1643 | F7: 55 | G7: 1669
A8: Sem. 29/06 | B8: 19 | C8: 32 | D8: 3 | E8: 29 | F8: 22 | G8: 61
A9: Sem. 06/07 | B9: 25 | C9: 72 | D9: 66 | E9: 3532 | F9: 91 | G9: 3604
A10: Sem. 13/07 | B10: 22 | C10: 100 | D10: 34 | E10: 738 | F10: 56 | G10: 838
A11: Sem. 20/07 | B11: 10 | C11: 24 | D11: 67 | E11: 1903 | F11: 77 | G11: 1927
A12: Sem. 27/07 | B12: 7 | C12: 10 | D12: 48 | E12: 2329 | F12: 55 | G12: 2339
A13: Sem. 03/08 | B13: 9 | C13: 17 | D13: 48 | E13: 850 | F13: 57 | G13: 867
A14: TOTAL | B14: =SUM(B5:B13) -> 156 | C14: =SUM(C5:C13) -> 461 | D14: =SUM(D5:D13) -> 418 | E14: =SUM(E5:E13) -> 15741 | F14: =SUM(F5:F13) -> 574 | G14: =SUM(G5:G13) -> 16202

Sheet GRAFICOS
A1: GRÁFICOS DEL ANÁLISIS
A41: Datos gráfico 1: % atención por alcance | E41: Datos gráfico 2: top 10 unds (unificado) | H41: Datos gráfico 4: top 10 NO DISPONIBLE (unds perdidas)
A42: ALCANCE | B42: % ATENDIDAS | C42: % NO DISPONIBLES | E42: PRODUCTO | F42: UNDS | H42: PRODUCTO | I42: UNDS NO CUBIERTAS
A43: TALLER | B43: 0.87820513 | C43: 0.12179487 | E43: STICKER DE REGALO | F43: 5200 | H43: SERVILLETAS | I43: 26
A44: TIENDAS | B44: 0.79904306 | C44: 0.20095694 | E44: BOLSAS PEQUEÑAS NAVIDAD 2024 | F44: 2770 | H44: ESENCIA SPLASH PARA BOLSAS | I44: 20
A45: UNIFICADO | B45: 0.82055749 | C45: 0.17944251 | E45: BOLSAS MEDIANAS NAVIDAD 2024 | F45: 2460 | H45: CINTA DOBLE FAZ | I45: 15
E46: BOLSAS GRANDES KRAFT | F46: 1210 | H46: RESMA DE HOJAS BLANCAS | I46: 6
E47: STICKER ADHESIVO DE CIERRE | F47: 800 | H47: PAÑO AMARILLO | I47: 12
E48: BOLSAS EXTRA PEQUEÑA KRAFT | F48: 550 | H48: BOLSA DE PAPELERA | I48: 140
E49: BOLSA DE PAPELERA | F49: 530 | H49: AMBIENTADOR GLADE | I49: 7
E50: BOLSAS DE BASURA | F50: 438 | H50: ESPONJA | I50: 6
E51: BOLSAS PEQUEÑAS KRAFT | F51: 400 | H51: POST ITS | I51: 6
E52: BOLSA DE ENVIO MEDIANA | F52: 301 | H52: TIRRO | I52: 5

Sheet DATA TALLER
A1: DATA TALLER
A2: Data limpia y clasificada usada en todos los cálculos. ATENCIÓN = ATENDIDA (recibido/entregado/enviado/solicitado) o NO DISPONIBLE.
A4: FECHA | B4: SEMANA | C4: MES | D4: ORIGEN | E4: SUCURSAL | F4: NOMBRE | G4: ARTICULO | H4: CARACTER ADICIONAL | I4: CATEGORIA | J4: CANTIDAD | K4: ESTADO ORIGINAL | L4: ESTADO | M4: ATENCIÓN | N4: NOTA LIMPIEZA
A5: 46182 | B5: Sem. 08/06 | C5: JUNIO | D5: TALLER | E5: ALMACEN | F5: Hector Zambrano | G5: CINTA DE EMBALAJE | I5: SUMINISTROS | J5: 1 | K5: ENTRGADO | L5: ENTREGADO | M5: ATENDIDA
A6: 46182 | B6: Sem. 08/06 | C6: JUNIO | D6: TALLER | E6: ALMACEN | F6: Hector Zambrano | G6: BOLSAS DE BASURA | I6: LIMPIEZA E HIGIENE | J6: 1 | K6: ENTRGADO | L6: ENTREGADO | M6: ATENDIDA
A7: 46182 | B7: Sem. 08/06 | C7: JUNIO | D7: TALLER | E7: ALMACEN | F7: Hector Zambrano | G7: PIQUETAS | I7: SUMINISTROS | J7: 1 | K7: ENTRGADO | L7: ENTREGADO | M7: ATENDIDA
A8: 46182 | B8: Sem. 08/06 | C8: JUNIO | D8: TALLER | E8: ALMACEN | F8: Hector Zambrano | G8: CINTA DE EMBALAJE | I8: SUMINISTROS | J8: 1 | K8: ENTRGADO | L8: ENTREGADO | M8: ATENDIDA
A9: 46182 | B9: Sem. 08/06 | C9: JUNIO | D9: TALLER | E9: ALMACEN | F9: Hector Zambrano | G9: BOLIGRAFOS | I9: OFICINA | J9: 1 | K9: ENTRGADO | L9: ENTREGADO | M9: ATENDIDA
A10: 46182 | B10: Sem. 08/06 | C10: JUNIO | D10: TALLER | E10: ALMACEN | F10: Hector Zambrano | G10: CUTTERS (EXACTO) | I10: SUMINISTROS | J10: 1 | K10: ENTRGADO | L10: ENTREGADO | M10: ATENDIDA
A11: 46182 | B11: Sem. 08/06 | C11: JUNIO | D11: TALLER | E11: MANTENIMIENTO | F11: Carolina Arteaga | G11: CAFÉ | I11: SUMINISTROS | J11: 3 | K11: ENTRGADO | L11: ENTREGADO | M11: ATENDIDA
A12: 46182 | B12: Sem. 08/06 | C12: JUNIO | D12: TALLER | E12: MANTENIMIENTO | F12: Carolina Arteaga | G12: DESINFECTANTE | I12: LIMPIEZA E HIGIENE | J12: 3 | K12: ENTRGADO | L12: ENTREGADO | M12: ATENDIDA
A13: 46182 | B13: Sem. 08/06 | C13: JUNIO | D13: TALLER | E13: MANTENIMIENTO | F13: Carolina Arteaga | G13: CLORO | I13: LIMPIEZA E HIGIENE | J13: 3 | K13: ENTRGADO | L13: ENTREGADO | M13: ATENDIDA
A14: 46182 | B14: Sem. 08/06 | C14: JUNIO | D14: TALLER | E14: MANTENIMIENTO | F14: Carolina Arteaga | G14: LAVATODO | I14: LIMPIEZA E HIGIENE | J14: 1 | K14: ENTRGADO | L14: ENTREGADO | M14: ATENDIDA
A15: 46182 | B15: Sem. 08/06 | C15: JUNIO | D15: TALLER | E15: MANTENIMIENTO | F15: Carolina Arteaga | G15: PAPEL SANITARIO INDUSTRIAL | I15: LIMPIEZA E HIGIENE | J15: 3 | K15: ENTRGADO | L15: ENTREGADO | M15: ATENDIDA
A16: 46182 | B16: Sem. 08/06 | C16: JUNIO | D16: TALLER | E16: MANTENIMIENTO | F16: Carolina Arteaga | G16: AMBIENTADOR GLADE | I16: LIMPIEZA E HIGIENE | J16: 3 | K16: ENTRGADO | L16: ENTREGADO | M16: ATENDIDA
... A68: 46199 | B68: Sem. 22/06 | C68: JUNIO | D68: TALLER | E68: TALLER | F68: Zelideth Nuñes | G68: MARCADOR PERMANENTE PUNTA FINA | I68: OFICINA | J68: 1 | K68: NO DISPONIBLE | L68: NO DISPONIBLE | M68: NO DISPONIBLE
A69: 46203 | B69: Sem. 29/06 | C69: JUNIO | D69: TALLER | E69: TALLER | F69: Kiria Pinto | G69: (SIN ARTÍCULO) | I69: SIN CATEGORÍA (NO REGISTRADO) | J69: 3 | K69: ENTRGADO | L69: ENTREGADO | M69: ATENDIDA | N69: Sin artículo: solo cuenta para KPIs generales
A70: 46203 | B70: Sem. 29/06 | C70: JUNIO | D70: TALLER | E70: TALLER | F70: Kiria Pinto | G70: BOLIGRAFOS | I70: OFICINA | J70: 2 | K70: ENTRGADO | L70: ENTREGADO | M70: ATENDIDA
A71: 46203 | B71: Sem. 29/06 | C71: JUNIO | D71: TALLER | E71: TALLER | F71: Kiria Pinto | G71: ALCOHOL | I71: LIMPIEZA E HIGIENE | J71: 1 | K71: ENTRGADO | L71: ENTREGADO | M71: ATENDIDA
A72: 46203 | B72: Sem. 29/06 | C72: JUNIO | D72: TALLER | E72: TALLER | F72: Paola Duran | G72: LAPIZ | I72: OFICINA | J72: 2 | K72: NO DISPONIBLE | L72: NO DISPONIBLE | M72: NO DISPONIBLE
A73: 46203 | B73: Sem. 29/06 | C73: JUNIO | D73: TALLER | E73: TALLER | F73: Paola Duran | G73: POST ITS | I73: OFICINA | J73: 1 | K73: ENTRGADO | L73: ENTREGADO | M73: ATENDIDA
A74: 46203 | B74: Sem. 29/06 | C74: JUNIO | D74: TALLER | E74: TALLER | F74: Kiria Pinto | G74: BATERIAS AA | I74: SUMINISTROS | J74: 1 | K74: ENTRGADO | L74: ENTREGADO | M74: ATENDIDA
A75: 46203 | B75: Sem. 29/06 | C75: JUNIO | D75: TALLER | E75: TALLER | F75: Luciana Rodriguez | G75: PIQUETAS | I75: SUMINISTROS | J75: 2 | K75: ENTRGADO | L75: ENTREGADO | M75: ATENDIDA
A76: 46203 | B76: Sem. 29/06 | C76: JUNIO | D76: TALLER | E76: TALLER | F76: Luciana Rodriguez | G76: TIJERAS NUEVAS | I76: OFICINA | J76: 1 | K76: ENTRGADO | L76: ENTREGADO | M76: ATENDIDA
A77: 46203 | B77: Sem. 29/06 | C77: JUNIO | D77: TALLER | E77: TALLER | F77: Sundely Partida | G77: REMOVEDOR VINIL | I77: SUMINISTROS | J77: 1 | K77: ENTRGADO | L77: ENTREGADO | M77: ATENDIDA
A78: 46203 | B78: Sem. 29/06 | C78: JUNIO | D78: TALLER | E78: TALLER | F78: Sundely Partida | G78: CINTA METRICA | I78: SUMINISTROS | J78: 2 | K78: ENTRGADO | L78: ENTREGADO | M78: ATENDIDA
A79: 46204 | B79: Sem. 29/06 | C79: JULIO | D79: TALLER | E79: TALLER | F79: Gabriel Chirinos | G79: TAPABOCAS | I79: INSUMOS MEDICOS | J79: 5 | K79: ENTRGADO | L79: ENTREGADO | M79: ATENDIDA
A80: 46205 | B80: Sem. 29/06 | C80: JULIO | D80: TALLER | E80: TALLER | F80: Yoselin Rojas | G80: RESMA DE HOJAS BLANCAS | I80: OFICINA | J80: 1 | K80: NO DISPONIBLE | L80: NO DISPONIBLE | M80: NO DISPONIBLE
A81: 46205 | B81: Sem. 29/06 | C81: JULIO | D81: TALLER | E81: TALLER | F81: AllieRodriguez | G81: REMOVEDOR VINIL | I81: SUMINISTROS | J81: 1 | K81: ENTRGADO | L81: ENTREGADO | M81: ATENDIDA
... A160: 46239 | B160: Sem. 03/08 | C160: AGOSTO | D160: TALLER | E160: TALLER | F160: ROSMARILYN PINTO | G160: PIQUETAS | I160: SUMINISTROS | J160: 2 | K160: SOLICITADO | L160: SOLICITADO | M160: ATENDIDA

Sheet DATA TIENDAS
A1: DATA TIENDAS
A2: Data limpia y clasificada usada en todos los cálculos. ATENCIÓN = ATENDIDA (recibido/entregado/enviado/solicitado) o NO DISPONIBLE.
A4: FECHA | B4: SEMANA | C4: MES | D4: ORIGEN | E4: SUCURSAL | F4: NOMBRE | G4: ARTICULO | H4: CARACTER ADICIONAL | I4: CATEGORIA | J4: CANTIDAD | K4: ESTADO ORIGINAL | L4: ESTADO | M4: ATENCIÓN | N4: NOTA LIMPIEZA
A5: 46181 | B5: Sem. 08/06 | C5: JUNIO | D5: TIENDAS | E5: CERRO VERDE | F5: PEBBLES VALLENILLA | G5: BOLSA DE ENVIO GRANDE | I5: SUMINISTROS | J5: 100 | K5: NO DISPONIBLE | L5: NO DISPONIBLE | M5: NO DISPONIBLE
A6: 46181 | B6: Sem. 08/06 | C6: JUNIO | D6: TIENDAS | E6: CERRO VERDE | F6: PEBBLES VALLENILLA | G6: BOLSA DE ENVIO MEDIANA | I6: SUMINISTROS | J6: 100 | K6: RECIBIDO | L6: RECIBIDO | M6: ATENDIDA
A7: 46181 | B7: Sem. 08/06 | C7: JUNIO | D7: TIENDAS | E7: CERRO VERDE | F7: PEBBLES VALLENILLA | G7: CAFÉ | I7: SUMINISTROS | J7: 2 | K7: RECIBIDO | L7: RECIBIDO | M7: ATENDIDA
A8: 46181 | B8: Sem. 08/06 | C8: JUNIO | D8: TIENDAS | E8: CERRO VERDE | F8: PEBBLES VALLENILLA | G8: STICKER DE REGALO | I8: SUMINISTROS | J8: 100 | K8: RECIBIDO | L8: RECIBIDO | M8: ATENDIDA
A9: 46181 | B9: Sem. 08/06 | C9: JUNIO | D9: TIENDAS | E9: CERRO VERDE | F9: PEBBLES VALLENILLA | G9: BOLSA DE PAPELERA | I9: LIMPIEZA E HIGIENE | J9: 50 | K9: RECIBIDO | L9: RECIBIDO | M9: ATENDIDA
A10: 46181 | B10: Sem. 08/06 | C10: JUNIO | D10: TIENDAS | E10: CERRO VERDE | F10: PEBBLES VALLENILLA | G10: TIJERAS NUEVAS | I10: OFICINA | J10: 1 | K10: RECIBIDO | L10: RECIBIDO | M10: ATENDIDA
A11: 46181 | B11: Sem. 08/06 | C11: JUNIO | D11: TIENDAS | E11: CERRO VERDE | F11: PEBBLES VALLENILLA | G11: SERVILLETAS | I11: LIMPIEZA E HIGIENE | J11: 2 | K11: RECIBIDO | L11: RECIBIDO | M11: ATENDIDA
A12: 46181 | B12: Sem. 08/06 | C12: JUNIO | D12: TIENDAS | E12: SAMBIL CHACAO | F12: PEBBLES VALLENILLA | G12: SERVILLETAS | I12: LIMPIEZA E HIGIENE | J12: 3 | K12: NO DISPONIBLE | L12: NO DISPONIBLE | M12: NO DISPONIBLE
A13: 46181 | B13: Sem. 08/06 | C13: JUNIO | D13: TIENDAS | E13: SAMBIL CHACAO | F13: PEBBLES VALLENILLA | G13: CAFÉ | I13: SUMINISTROS | J13: 2 | K13: RECIBIDO | L13: RECIBIDO | M13: ATENDIDA
A14: 46181 | B14: Sem. 08/06 | C14: JUNIO | D14: TIENDAS | E14: SAMBIL CHACAO | F14: PEBBLES VALLENILLA | G14: STICKER DE REGALO | I14: SUMINISTROS | J14: 500 | K14: RECIBIDO | L14: RECIBIDO | M14: ATENDIDA
A15: 46181 | B15: Sem. 08/06 | C15: JUNIO | D15: TIENDAS | E15: SAMBIL CHACAO | F15: PEBBLES VALLENILLA | G15: AMBIENTADOR GLADE | I15: LIMPIEZA E HIGIENE | J15: 1 | K15: NO DISPONIBLE | L15: NO DISPONIBLE | M15: NO DISPONIBLE
A16: 46181 | B16: Sem. 08/06 | C16: JUNIO | D16: TIENDAS | E16: SAMBIL CHACAO | F16: PEBBLES VALLENILLA | G16: CINTA TERMICA | I16: SUMINISTROS | J16: 1 | K16: NO DISPONIBLE | L16: NO DISPONIBLE | M16: NO DISPONIBLE
... A23: 46181 | B23: Sem. 08/06 | C23: JUNIO | D23: TIENDAS | E23: TOLON | F23: PEBBLES VALLENILLA | G23: BOLSAS DE BASURA | I23: LIMPIEZA E HIGIENE | J23: 6 | K23: RECIBIDO | L23: RECIBIDO | M23: ATENDIDA
A24: 46181 | B24: Sem. 08/06 | C24: JUNIO | D24: TIENDAS | E24: TOLON | F24: PEBBLES VALLENILLA | G24: DESINFECTANTE | H24: 1 GALON 3.75L | I24: LIMPIEZA E HIGIENE | J24: 1 | K24: RECIBIDO | L24: RECIBIDO | M24: ATENDIDA
A25: 46181 | B25: Sem. 08/06 | C25: JUNIO | D25: TIENDAS | E25: TOLON | F25: PEBBLES VALLENILLA | G25: GRAPAS | H25: CAJA | I25: OFICINA | J25: 1 | K25: RECIBIDO | L25: RECIBIDO | M25: ATENDIDA
A26: 46181 | B26: Sem. 08/06 | C26: JUNIO | D26: TIENDAS | E26: TOLON | F26: PEBBLES VALLENILLA | G26: SERVILLETAS | I26: LIMPIEZA E HIGIENE | J26: 2 | K26: NO DISPONIBLE | L26: NO DISPONIBLE | M26: NO DISPONIBLE
A27: 46181 | B27: Sem. 08/06 | C27: JUNIO | D27: TIENDAS | E27: TOLON | F27: PEBBLES VALLENILLA | G27: COLETO 3 RAYAS | I27: LIMPIEZA E HIGIENE | J27: 1 | K27: NO DISPONIBLE | L27: NO DISPONIBLE | M27: NO DISPONIBLE
A28: 46181 | B28: Sem. 08/06 | C28: JUNIO | D28: TIENDAS | E28: TOLON | F28: PEBBLES VALLENILLA | G28: ESPONJA | I28: LIMPIEZA E HIGIENE | J28: 2 | K28: NO DISPONIBLE | L28: NO DISPONIBLE | M28: NO DISPONIBLE
A29: 46181 | B29: Sem. 08/06 | C29: JUNIO | D29: TIENDAS | E29: TOLON | F29: PEBBLES VALLENILLA | G29: LAVATODO | H29: 1 GALON 3.75L | I29: LIMPIEZA E HIGIENE | J29: 1 | K29: NO DISPONIBLE | L29: NO DISPONIBLE | M29: NO DISPONIBLE
A30: 46182 | B30: Sem. 08/06 | C30: JUNIO | D30: TIENDAS | E30: GRAND PLAZ | F30: PEBBLES VALLENILLA | G30: ESENCIA SPLASH PARA BOLSAS | I30: SUMINISTROS | J30: 3 | K30: RECIBIDO | L30: RECIBIDO | M30: ATENDIDA
A31: 46182 | B31: Sem. 08/06 | C31: JUNIO | D31: TIENDAS | E31: GRAND PLAZ | F31: PEBBLES VALLENILLA | G31: BATERIAS AAA | I31: SUMINISTROS | J31: 1 | K31: RECIBIDO | L31: RECIBIDO | M31: ATENDIDA
A32: 46182 | B32: Sem. 08/06 | C32: JUNIO | D32: TIENDAS | E32: GRAND PLAZ | F32: PEBBLES VALLENILLA | G32: BATERIAS AA | I32: SUMINISTROS | J32: 1 | K32: RECIBIDO | L32: RECIBIDO | M32: ATENDIDA
A33: 46182 | B33: Sem. 08/06 | C33: JUNIO | D33: TIENDAS | E33: GRAND PLAZ | F33: PEBBLES VALLENILLA | G33: BOLSAS GRANDES KRAFT | I33: SUMINISTROS | J33: 150 | K33: RECIBIDO | L33: RECIBIDO | M33: ATENDIDA
A34: 46182 | B34: Sem. 08/06 | C34: JUNIO | D34: TIENDAS | E34: GRAND PLAZ | F34: PEBBLES VALLENILLA | G34: ROLLO DE IMPRESORA FISCAL PAQ 5 UNDS | I34: SUMINISTROS | J34: 1 | K34: RECIBIDO | L34: RECIBIDO | M34: ATENDIDA
A35: 46182 | B35: Sem. 08/06 | C35: JUNIO | D35: TIENDAS | E35: GRAND PLAZ | F35: PEBBLES VALLENILLA | G35: STICKER ADHESIVO DE CIERRE | I35: SUMINISTROS | J35: 200 | K35: RECIBIDO | L35: RECIBIDO | M35: ATENDIDA
A36: 46182 | B36: Sem. 08/06 | C36: JUNIO | D36: TIENDAS | E36: GRIETA | F36: PEBBLES VALLENILLA | G36: BOLSAS PEQUEÑAS NAVIDAD 2024 | I36: SUMINISTROS | J36: 200 | K36: RECIBIDO | L36: RECIBIDO | M36: ATENDIDA
A37: 46182 | B37: Sem. 08/06 | C37: JUNIO | D37: TIENDAS | E37: GRIETA | F37: PEBBLES VALLENILLA | G37: CLORO | H37: 1 GALON 3.75L | I37: LIMPIEZA E HIGIENE | J37: 1 | K37: RECIBIDO | L37: RECIBIDO | M37: ATENDIDA
A38: 46182 | B38: Sem. 08/06 | C38: JUNIO | D38: TIENDAS | E38: GRIETA | F38: PEBBLES VALLENILLA | G38: DESINFECTANTE | H38: 1 GALON 3.75L | I38: LIMPIEZA E HIGIENE | J38: 1 | K38: RECIBIDO | L38: RECIBIDO | M38: ATENDIDA
