Workbook

Sheet Supuestos
A1: Modelo de Capacidad — Taller CÚADRO (v4)
A2: Base de medición: Operaciones_Por_Linea (2). Celdas AMARILLAS editables. v4: los 2 overlock de los escenarios B, C y D son DE APOYO (posición nueva en L1 y en L2), no reemplazo del overlock de Unión / Montaje.
A4: Parámetro | B4: Valor | C4: Unidad | D4: Origen / nota
A5: Días laborables por mes | B5: 20 | C5: días | D5: Convención del taller
A6: Operaciones por pieza — Modelo 1 | B6: 8.9 | C6: ops/pza | D6: Convención del propio archivo de medición: 2.940 ops ÷ 367,5 pzas = 8,00
A7: Stock de seguridad | B7: 0.1 | C7: % | D7: Instrucción de Gerencia
A8: Tasa de reproceso — Actual (sobre OPERACIONES) | B8: 0.0576 | C8: % | D8: MEDIDO: 3.391 ops de reproceso / 58.880 ops. NO usar aquí el 16,14%: ese es el % de PIEZAS rechazadas, no de operaciones.
A9: Tasa de reproceso — Escenario A | B9: 0.048 | C9: % | D9: SUPUESTO. Se renuevan 4 de 18 posiciones
A10: Tasa de reproceso — Escenario B | B10: 0.04 | C10: % | D10: SUPUESTO. Se renuevan 7 posiciones averiadas o inactivas (6 collareteras de ruedo + el overlock de L2). Los 2 overlock de apoyo son posiciones nuevas, no renovación, por eso la tasa no baja más.
A11: Tasa de reproceso — Escenario C | B11: 0.04 | C11: % | D11: SUPUESTO. Igual que B (la collaretera de L5 no toca las líneas 1-4)
A12: Tasa de reproceso — Escenario D | B12: 0.035 | C12: % | D12: SUPUESTO. 7 posiciones renovadas, 2 overlock de apoyo y una línea 100% nueva
A13: Ganancia por máquina electrónica | B13: 0.08 | C13: % | D13: SUPUESTO (rango 2%-8%). Corta-hilo + alza-pie sobre SAM de 2,30 min
A14: Capacidad de L3 cedida a la Línea 5 | B14: 0.1 | C14: % | D14: DATO DE PRODUCCIÓN. Se recupera en los escenarios C y D
A15: Demanda mes regular | B15: 4145 | C15: pzas | D15: Dato de Gerencia
A16: Demanda diciembre | B16: 9434 | C16: pzas | D16: Dato de Gerencia
... A23: Ops de COLLARET RUEDO por pieza | B23: 1 | C23: ops | D23: MEDIDO: estudio de tiempos Clásica Algodón
A25: Coherencia de la estructura de operaciones
A26: Suma de ops por tipo (overlock + cuello + ruedo) | B26: =Supuestos!$B$21+Supuestos!$B$22+Supuestos!$B$23
A27: ATENCIÓN: si esta suma no coincide con las 'Operaciones por pieza — Modelo 1', los dos modelos describen piezas distintas. Reconciliar antes de presentar.
A29: Cambio de la versión 3 a la versión 4
A30: v3: el escenario B compraba 2 overlock para reemplazar el de Unión / Montaje de L1 y el de L2. Reemplazar una máquina sana solo aporta el 8% de ganancia electrónica, así que el techo del taller casi no se movía.
A31: v4: esos 2 overlock son DE APOYO. Se instalan como posición 6 de L1 y de L2 y suman una máquina completa de capacidad a cada línea. El overlock averiado de L2 se sigue reponiendo, porque eso ya venía en el escenario A.
A32: Overlock por lo tanto pasa de 2 a 3 máquinas en B (1 reposición + 2 de apoyo) y la inversión de B sube de US$ 20.800 a US$ 22.200.
A33: Como el overlock es la restricción activa del taller en todos los escenarios, este cambio es el que más mueve la capacidad de todo el modelo.

Sheet Mediciones
A1: Mediciones base por posición de línea
A2: Transcripción literal de Operaciones_Por_Linea (2), hoja 'Operaciones - Taller Diario'. Única fuente de capacidad de este modelo.
A4: Línea | B4: Posición | C4: Máquina | D4: Operación | E4: Cap. teórica | F4: Estatus | G4: Cap. real
A5: Línea 1 | B5: 1 | C5: Overlock | D5: Unión / Montaje | E5: 190 | F5: Disponible | G5: 190
A6: Línea 1 | B6: 2 | C6: Collaret | D6: Recubrir Cuello | E6: 196 | F6: Disponible | G6: 196
A7: Línea 1 | B7: 3 | C7: Overlock | D7: Montaje / Cierre | E7: 198 | F7: Disponible | G7: 198
A8: Línea 1 | B8: 4 | C8: Collaret | D8: Ruedo | E8: 101 | F8: Disponible | G8: 101
A9: Línea 2 | B9: 1 | C9: Overlock | D9: Unión / Montaje | E9: 190 | F9: 80 % | G9: 150
A10: Línea 2 | B10: 2 | C10: Collaret | D10: Recubrir Cuello | E10: 196 | F10: Disponible | G10: 196
A11: Línea 2 | B11: 3 | C11: Overlock | D11: Montaje / Cierre | E11: 198 | F11: Disponible | G11: 198
A12: Línea 2 | B12: 4 | C12: Collaret | D12: Ruedo | E12: 101 | F12: Disponible | G12: 101
A13: Línea 3 | B13: 1 | C13: Overlock | D13: Unión / Montaje | E13: 190 | F13: Disponible | G13: 190
A14: Línea 3 | B14: 2 | C14: Collaret | D14: Recubrir Cuello | E14: 196 | F14: Disponible | G14: 196
A15: Línea 3 | B15: 3 | C15: Overlock | D15: Montaje / Cierre | E15: 198 | F15: Disponible | G15: 198
A16: Línea 3 | B16: 4 | C16: Collaret | D16: Ruedo | E16: 101 | F16: 50 % | G16: 50.5
... A22: Línea 4 | B22: 5 | C22: Collaret | D22: Ruedo | E22: 100 | F22: Inactiva | G22: 0
A23: TOTAL | E23: =SUM(E5:E22) | G23: =SUM(G5:G22)
A24: Pérdida por fallas (ops/día) | G24: =E23-G23

Sheet Lineas por Escenario
A1: Cómo queda cada línea en cada escenario
A2: Posición por posición. Verde = máquina nueva. Naranja = máquina averiada que sigue en servicio. Las nuevas rinden nominal × (1 + ganancia electrónica).
A4: Línea | B4: Pos. | C4: Máquina | D4: Operación | E4: Nominal | F4: Actual — estado | G4: Actual — ops/día | H4: A — estado | I4: A — ops/día | J4: B — estado | K4: B — ops/día | L4: C — estado | M4: C — ops/día | N4: D — estado | O4: D — ops/día
A5: Línea 1 | B5: 1 | C5: Overlock | D5: Unión / Montaje | E5: 190 | F5: Disponible | G5: 190 | H5: Disponible | I5: 190 | J5: Disponible | K5: 190 | L5: Disponible | M5: 190 | N5: Disponible | O5: 190
A6: Línea 1 | B6: 2 | C6: Collaret | D6: Recubrir Cuello | E6: 196 | F6: Disponible | G6: 196 | H6: Disponible | I6: 196 | J6: Disponible | K6: 196 | L6: Disponible | M6: 196 | N6: Disponible | O6: 196
A7: Línea 1 | B7: 3 | C7: Overlock | D7: Montaje / Cierre | E7: 198 | F7: Disponible | G7: 198 | H7: Disponible | I7: 198 | J7: Disponible | K7: 198 | L7: Disponible | M7: 198 | N7: Disponible | O7: 198
A8: Línea 1 | B8: 4 | C8: Collaret | D8: Ruedo | E8: 101 | F8: Disponible | G8: 101 | H8: Disponible | I8: 101 | J8: Disponible | K8: 101 | L8: Disponible | M8: 101 | N8: Disponible | O8: 101
A9: Línea 2 | B9: 1 | C9: Overlock | D9: Unión / Montaje | E9: 190 | F9: 80 % | G9: 150 | H9: NUEVA | I9: =$E9*(1+Supuestos!$B$13) | J9: NUEVA | K9: =$E9*(1+Supuestos!$B$13) | L9: NUEVA | M9: =$E9*(1+Supuestos!$B$13) | N9: NUEVA | O9: =$E9*(1+Supuestos!$B$13)
A10: Línea 2 | B10: 2 | C10: Collaret | D10: Recubrir Cuello | E10: 196 | F10: Disponible | G10: 196 | H10: Disponible | I10: 196 | J10: Disponible | K10: 196 | L10: Disponible | M10: 196 | N10: Disponible | O10: 196
A11: Línea 2 | B11: 3 | C11: Overlock | D11: Montaje / Cierre | E11: 198 | F11: Disponible | G11: 198 | H11: Disponible | I11: 198 | J11: Disponible | K11: 198 | L11: Disponible | M11: 198 | N11: Disponible | O11: 198
A12: Línea 2 | B12: 4 | C12: Collaret | D12: Ruedo | E12: 101 | F12: Disponible | G12: 101 | H12: Disponible | I12: 101 | J12: Disponible | K12: 101 | L12: Disponible | M12: 101 | N12: Disponible | O12: 101
A13: Línea 3 | B13: 1 | C13: Overlock | D13: Unión / Montaje | E13: 190 | F13: Disponible | G13: 190 | H13: Disponible | I13: 190 | J13: Disponible | K13: 190 | L13: Disponible | M13: 190 | N13: Disponible | O13: 190
A14: Línea 3 | B14: 2 | C14: Collaret | D14: Recubrir Cuello | E14: 196 | F14: Disponible | G14: 196 | H14: Disponible | I14: 196 | J14: Disponible | K14: 196 | L14: Disponible | M14: 196 | N14: Disponible | O14: 196
A15: Línea 3 | B15: 3 | C15: Overlock | D15: Montaje / Cierre | E15: 198 | F15: Disponible | G15: 198 | H15: Disponible | I15: 198 | J15: Disponible | K15: 198 | L15: Disponible | M15: 198 | N15: Disponible | O15: 198
A16: Línea 3 | B16: 4 | C16: Collaret | D16: Ruedo | E16: 101 | F16: 50 % | G16: 50.5 | H16: NUEVA | I16: =$E16*(1+Supuestos!$B$13) | J16: NUEVA | K16: =$E16*(1+Supuestos!$B$13) | L16: NUEVA | M16: =$E16*(1+Supuestos!$B$13) | N16: NUEVA | O16: =$E16*(1+Supuestos!$B$13)
A17: Línea 3 | B17: 5 | C17: Collaret | D17: Ruedo | E17: 100 | F17: Inactiva | G17: 0 | H17: NUEVA | I17: =$E17*(1+Supuestos!$B$13) | J17: NUEVA | K17: =$E17*(1+Supuestos!$B$13) | L17: NUEVA | M17: =$E17*(1+Supuestos!$B$13) | N17: NUEVA | O17: =$E17*(1+Supuestos!$B$13)
A18: Línea 4 | B18: 1 | C18: Overlock | D18: Unión / Montaje | E18: 190 | F18: Disponible | G18: 190 | H18: Disponible | I18: 190 | J18: Disponible | K18: 190 | L18: Disponible | M18: 190 | N18: Disponible | O18: 190
A19: Línea 4 | B19: 2 | C19: Collaret | D19: Recubrir Cuello | E19: 196 | F19: Disponible | G19: 196 | H19: Disponible | I19: 196 | J19: Disponible | K19: 196 | L19: Disponible | M19: 196 | N19: Disponible | O19: 196
A20: Línea 4 | B20: 3 | C20: Overlock | D20: Montaje / Cierre | E20: 198 | F20: Disponible | G20: 198 | H20: Disponible | I20: 198 | J20: Disponible | K20: 198 | L20: Disponible | M20: 198 | N20: Disponible | O20: 198
A21: Línea 4 | B21: 4 | C21: Collaret | D21: Ruedo | E21: 101 | F21: Disponible | G21: 101 | H21: Disponible | I21: 101 | J21: NUEVA | K21: =$E21*(1+Supuestos!$B$13) | L21: NUEVA | M21: =$E21*(1+Supuestos!$B$13) | N21: NUEVA | O21: =$E21*(1+Supuestos!$B$13)
A22: Línea 4 | B22: 5 | C22: Collaret | D22: Ruedo | E22: 100 | F22: Inactiva | G22: 0 | H22: NUEVA | I22: =$E22*(1+Supuestos!$B$13) | J22: NUEVA | K22: =$E22*(1+Supuestos!$B$13) | L22: NUEVA | M22: =$E22*(1+Supuestos!$B$13) | N22: NUEVA | O22: =$E22*(1+Supuestos!$B$13)
A23: Línea 1 | B23: 5 | C23: Collaret | D23: Ruedo | E23: 100 | F23: No existe | G23: 0 | H23: No existe | I23: 0 | J23: NUEVA | K23: =$E23*(1+Supuestos!$B$13) | L23: NUEVA | M23: =$E23*(1+Supuestos!$B$13) | N23: NUEVA | O23: =$E23*(1+Supuestos!$B$13)
A24: Línea 2 | B24: 5 | C24: Collaret | D24: Ruedo | E24: 100 | F24: No existe | G24: 0 | H24: No existe | I24: 0 | J24: NUEVA | K24: =$E24*(1+Supuestos!$B$13) | L24: NUEVA | M24: =$E24*(1+Supuestos!$B$13) | N24: NUEVA | O24: =$E24*(1+Supuestos!$B$13)
A25: Línea 1 | B25: 6 | C25: Overlock | D25: Apoyo Unión / Montaje | E25: 190 | F25: No existe | G25: 0 | H25: No existe | I25: 0 | J25: NUEVA (apoyo) | K25: =$E25*(1+Supuestos!$B$13) | L25: NUEVA (apoyo) | M25: =$E25*(1+Supuestos!$B$13) | N25: NUEVA (apoyo) | O25: =$E25*(1+Supuestos!$B$13)
A26: Línea 2 | B26: 6 | C26: Overlock | D26: Apoyo Unión / Montaje | E26: 190 | F26: No existe | G26: 0 | H26: No existe | I26: 0 | J26: NUEVA (apoyo) | K26: =$E26*(1+Supuestos!$B$13) | L26: NUEVA (apoyo) | M26: =$E26*(1+Supuestos!$B$13) | N26: NUEVA (apoyo) | O26: =$E26*(1+Supuestos!$B$13)
A27: Línea 6 | B27: 1 | C27: Overlock | D27: Unión / Montaje | E27: 190 | F27: No existe | G27: 0 | H27: No existe | I27: 0 | J27: No existe | K27: 0 | L27: No existe | M27: 0 | N27: NUEVA | O27: =$E27*(1+Supuestos!$B$13)
A28: Línea 6 | B28: 2 | C28: Collaret | D28: Recubrir Cuello | E28: 196 | F28: No existe | G28: 0 | H28: No existe | I28: 0 | J28: No existe | K28: 0 | L28: No existe | M28: 0 | N28: NUEVA | O28: =$E28*(1+Supuestos!$B$13)
A29: Línea 6 | B29: 3 | C29: Overlock | D29: Montaje / Cierre | E29: 198 | F29: No existe | G29: 0 | H29: No existe | I29: 0 | J29: No existe | K29: 0 | L29: No existe | M29: 0 | N29: NUEVA | O29: =$E29*(1+Supuestos!$B$13)
A30: Línea 6 | B30: 4 | C30: Collaret | D30: Ruedo | E30: 101 | F30: No existe | G30: 0 | H30: No existe | I30: 0 | J30: No existe | K30: 0 | L30: No existe | M30: 0 | N30: NUEVA | O30: =$E30*(1+Supuestos!$B$13)
A31: Línea 6 | B31: 5 | C31: Collaret | D31: Ruedo | E31: 100 | F31: No existe | G31: 0 | H31: No existe | I31: 0 | J31: No existe | K31: 0 | L31: No existe | M31: 0 | N31: NUEVA | O31: =$E31*(1+Supuestos!$B$13)
A33: TOTAL OPS/DÍA POR LÍNEA (ya descontada la cesión de L3 a la Línea 5)
A34: Línea | F34: Actual ops/día | H34: A ops/día | J34: B ops/día | L34: C ops/día | N34: D ops/día
A35: Línea 1 | F35: =(G5+G6+G7+G8+G23+G25) | H35: =(I5+I6+I7+I8+I23+I25) | J35: =(K5+K6+K7+K8+K23+K25) | L35: =(M5+M6+M7+M8+M23+M25) | N35: =(O5+O6+O7+O8+O23+O25)
A36: Línea 2 | F36: =(G9+G10+G11+G12+G24+G26) | H36: =(I9+I10+I11+I12+I24+I26) | J36: =(K9+K10+K11+K12+K24+K26) | L36: =(M9+M10+M11+M12+M24+M26) | N36: =(O9+O10+O11+O12+O24+O26)
A37: Línea 3 | F37: =(G13+G14+G15+G16+G17)*(1-Supuestos!$B$14) | H37: =(I13+I14+I15+I16+I17)*(1-Supuestos!$B$14) | J37: =(K13+K14+K15+K16+K17)*(1-Supuestos!$B$14) | L37: =(M13+M14+M15+M16+M17) | N37: =(O13+O14+O15+O16+O17)
A38: Línea 4 | F38: =(G18+G19+G20+G21+G22) | H38: =(I18+I19+I20+I21+I22) | J38: =(K18+K19+K20+K21+K22) | L38: =(M18+M19+M20+M21+M22) | N38: =(O18+O19+O20+O21+O22)
A39: Línea 6 | F39: =(G27+G28+G29+G30+G31) | H39: =(I27+I28+I29+I30+I31) | J39: =(K27+K28+K29+K30+K31) | L39: =(M27+M28+M29+M30+M31) | N39: =(O27+O28+O29+O30+O31)
A40: TOTAL TALLER | F40: =SUM(F35:F39) | H40: =SUM(H35:H39) | J40: =SUM(J35:J39) | L40: =SUM(L35:L39) | N40: =SUM(N35:N39)
A42: La Línea 3 aparece con su capacidad neta: en Actual, A y B se le descuenta el 10% que presta a la Línea 5. En C y D ese descuento desaparece porque la Línea 5 recibe collaretera propia.
A43: La collaretera de la Línea 5 del escenario C no figura en esta tabla porque la Línea 5 no forma parte del techo de las líneas 1-4; su efecto se ve en la recuperación de la Línea 3.
...

Sheet Escenarios
A1: En qué consiste cada escenario
A2: Descripción operativa de las cuatro alternativas de inversión
A4: Escenario | B4: Qué se compra | C4: En qué consiste / qué problema resuelve | D4: Nº máq. | E4: Inversión US$
A5: A — Reposición estricta | B5: 3 collareteras de ruedo (2 para L3, 1 para L4) + 1 overlock (L2) | C5: Comprar exactamente lo que hoy está averiado, ni una máquina más. Reemplaza el overlock de Unión/Montaje de L2 (hoy al 80%), la collaretera de ruedo de L3 (al 50%), la collaretera de ruedo inactiva de L3 y la collaretera de ruedo inactiva de L4. Restituye las 290,5 ops/día perdidas y devuelve el taller a su techo teórico de 2.940 ops/día. No agrega ninguna posición nueva: la estructura de las líneas queda igual a la de hoy. | D5: 4 | E5: =Inversion!$H$5
A6: B — Propuesta de Producción | B6: 6 collareteras de ruedo + 1 overlock de reposición (L2) + 2 overlock DE APOYO (1 en L1 y 1 en L2) | C6: Además de reponer lo averiado, iguala las cuatro líneas y refuerza el cuello de botella. Hoy L3 y L4 tienen dos posiciones de ruedo y L1 y L2 solo una: se reemplazan las cuatro collareteras de L3 y L4 y se agrega una quinta posición de ruedo a L1 y otra a L2. Los 2 overlock NO son reemplazo: entran como máquinas de apoyo en una sexta posición de L1 y de L2, de modo que cada una de esas líneas gana una máquina completa de Unión / Montaje. El overlock averiado de L2 se repone igual que en A. Overlock es la restricción activa del taller, así que estas dos máquinas de apoyo son las que realmente levantan el techo. | D6: 9 | E6: =Inversion!$H$6
A7: C — B + Línea 5 autónoma | B7: Todo lo de B + 1 collaretera para la Línea 5 | C7: Corrige un préstamo de capacidad que hoy no aparece en ningún reporte: algunos modelos de la Línea 5 necesitan la Línea 3 para manufacturar su parte interna y consumen el 10% de su capacidad mensual. Al dotar a la Línea 5 de collaretera propia, la Línea 3 recupera ese 10% para producción propia y deja de relentizarse en simultáneo con L5. | D7: 10 | E7: =Inversion!$H$7
A8: D — C + línea nueva | B8: Todo lo de C + una Línea 6 completa: 2 overlock + 1 collaret de cuello + 2 collaret de ruedo | C8: Suma una quinta línea de confección con la estructura de 5 máquinas de las líneas 3 y 4: 2 overlock + 1 collaret de cuello + 2 collaret de ruedo. Es el único escenario que amplía la planta en lugar de repararla o reequilibrarla, y el único que alcanza a cubrir el promedio mensual de la zafra. Requiere dotación de personal para la línea nueva, costo no incluido en la cifra de inversión. | D8: 15 | E8: =Inversion!$H$8
A10: Los escenarios son acumulativos: A ⊂ B ⊂ C ⊂ D. Comprar A no invalida pasar después a B, C o D. B incluye la reposición del overlock de L2 que ya venía en A.

Sheet Capacidad
A1: Capacidad instalada por escenario
A2: Modelo 1 = conversión por operaciones. Modelo 2 = balance de estaciones (criterio de planificación).
A4: Capacidad neta por tipo (ops/día) | B4: Actual | C4: A | D4: B | E4: C | F4: D | G4: Ops/pza
A5: Overlock | B5: ='Lineas por Escenario'!G5+'Lineas por Escenario'!G7+'Lineas por Escenario'!G9+'Lineas por Escenario'!G11+'Lineas por Escenario'!G13*(1-Supuestos!$B$14)+'Lineas por Escenario'!G15*(1-Supuestos!$B$14)+'Lineas por Escenario'!G18+'Lineas por Escenario'!G20+'Lineas por Escenario'!G25+'Lineas por Escenario'!G26+'Lineas por Escenario'!G27+'Lineas por Escenario'!G29 | C5: ='Lineas por Escenario'!I5+'Lineas por Escenario'!I7+'Lineas por Escenario'!I9+'Lineas por Escenario'!I11+'Lineas por Escenario'!I13*(1-Supuestos!$B$14)+'Lineas por Escenario'!I15*(1-Supuestos!$B$14)+'Lineas por Escenario'!I18+'Lineas por Escenario'!I20+'Lineas por Escenario'!I25+'Lineas por Escenario'!I26+'Lineas por Escenario'!I27+'Lineas por Escenario'!I29 | D5: ='Lineas por Escenario'!K5+'Lineas por Escenario'!K7+'Lineas por Escenario'!K9+'Lineas por Escenario'!K11+'Lineas por Escenario'!K13*(1-Supuestos!$B$14)+'Lineas por Escenario'!K15*(1-Supuestos!$B$14)+'Lineas por Escenario'!K18+'Lineas por Escenario'!K20+'Lineas por Escenario'!K25+'Lineas por Escenario'!K26+'Lineas por Escenario'!K27+'Lineas por Escenario'!K29 | E5: ='Lineas por Escenario'!M5+'Lineas por Escenario'!M7+'Lineas por Escenario'!M9+'Lineas por Escenario'!M11+'Lineas por Escenario'!M13+'Lineas por Escenario'!M15+'Lineas por Escenario'!M18+'Lineas por Escenario'!M20+'Lineas por Escenario'!M25+'Lineas por Escenario'!M26+'Lineas por Escenario'!M27+'Lineas por Escenario'!M29 | F5: ='Lineas por Escenario'!O5+'Lineas por Escenario'!O7+'Lineas por Escenario'!O9+'Lineas por Escenario'!O11+'Lineas por Escenario'!O13+'Lineas por Escenario'!O15+'Lineas por Escenario'!O18+'Lineas por Escenario'!O20+'Lineas por Escenario'!O25+'Lineas por Escenario'!O26+'Lineas por Escenario'!O27+'Lineas por Escenario'!O29 | G5: =Supuestos!$B$21
A6: Collaret Cuello | B6: ='Lineas por Escenario'!G6+'Lineas por Escenario'!G10+'Lineas por Escenario'!G14*(1-Supuestos!$B$14)+'Lineas por Escenario'!G19+'Lineas por Escenario'!G28 | C6: ='Lineas por Escenario'!I6+'Lineas por Escenario'!I10+'Lineas por Escenario'!I14*(1-Supuestos!$B$14)+'Lineas por Escenario'!I19+'Lineas por Escenario'!I28 | D6: ='Lineas por Escenario'!K6+'Lineas por Escenario'!K10+'Lineas por Escenario'!K14*(1-Supuestos!$B$14)+'Lineas por Escenario'!K19+'Lineas por Escenario'!K28 | E6: ='Lineas por Escenario'!M6+'Lineas por Escenario'!M10+'Lineas por Escenario'!M14+'Lineas por Escenario'!M19+'Lineas por Escenario'!M28 | F6: ='Lineas por Escenario'!O6+'Lineas por Escenario'!O10+'Lineas por Escenario'!O14+'Lineas por Escenario'!O19+'Lineas por Escenario'!O28 | G6: =Supuestos!$B$22
A7: Collaret Ruedo | B7: ='Lineas por Escenario'!G8+'Lineas por Escenario'!G12+'Lineas por Escenario'!G16*(1-Supuestos!$B$14)+'Lineas por Escenario'!G17*(1-Supuestos!$B$14)+'Lineas por Escenario'!G21+'Lineas por Escenario'!G22+'Lineas por Escenario'!G23+'Lineas por Escenario'!G24+'Lineas por Escenario'!G30+'Lineas por Escenario'!G31 | C7: ='Lineas por Escenario'!I8+'Lineas por Escenario'!I12+'Lineas por Escenario'!I16*(1-Supuestos!$B$14)+'Lineas por Escenario'!I17*(1-Supuestos!$B$14)+'Lineas por Escenario'!I21+'Lineas por Escenario'!I22+'Lineas por Escenario'!I23+'Lineas por Escenario'!I24+'Lineas por Escenario'!I30+'Lineas por Escenario'!I31 | D7: ='Lineas por Escenario'!K8+'Lineas por Escenario'!K12+'Lineas por Escenario'!K16*(1-Supuestos!$B$14)+'Lineas por Escenario'!K17*(1-Supuestos!$B$14)+'Lineas por Escenario'!K21+'Lineas por Escenario'!K22+'Lineas por Escenario'!K23+'Lineas por Escenario'!K24+'Lineas por Escenario'!K30+'Lineas por Escenario'!K31 | E7: ='Lineas por Escenario'!M8+'Lineas por Escenario'!M12+'Lineas por Escenario'!M16+'Lineas por Escenario'!M17+'Lineas por Escenario'!M21+'Lineas por Escenario'!M22+'Lineas por Escenario'!M23+'Lineas por Escenario'!M24+'Lineas por Escenario'!M30+'Lineas por Escenario'!M31 | F7: ='Lineas por Escenario'!O8+'Lineas por Escenario'!O12+'Lineas por Escenario'!O16+'Lineas por Escenario'!O17+'Lineas por Escenario'!O21+'Lineas por Escenario'!O22+'Lineas por Escenario'!O23+'Lineas por Escenario'!O24+'Lineas por Escenario'!O30+'Lineas por Escenario'!O31 | G7: =Supuestos!$B$23
A8: TOTAL ops/día | B8: =SUM(B5:B7) | C8: =SUM(C5:C7) | D8: =SUM(D5:D7) | E8: =SUM(E5:E7) | F8: =SUM(F5:F7)
A10: MODELO 1 — Conversión por operaciones
A11: Concepto | B11: Actual | C11: A | D11: B | E11: C | F11: D
A12: Ops/mes | B12: =B8*Supuestos!$B$5 | C12: =C8*Supuestos!$B$5 | D12: =D8*Supuestos!$B$5 | E12: =E8*Supuestos!$B$5 | F12: =F8*Supuestos!$B$5
A13: Ops/mes netas de reproceso | B13: =B12*(1-Supuestos!$B$8) | C13: =C12*(1-Supuestos!$B$9) | D13: =D12*(1-Supuestos!$B$10) | E13: =E12*(1-Supuestos!$B$11) | F13: =F12*(1-Supuestos!$B$12)
A14: PIEZAS/MES bruto | B14: =B12/Supuestos!$B$6 | C14: =C12/Supuestos!$B$6 | D14: =D12/Supuestos!$B$6 | E14: =E12/Supuestos!$B$6 | F14: =F12/Supuestos!$B$6
A15: PIEZAS/MES netas de reproceso | B15: =B13/Supuestos!$B$6 | C15: =C13/Supuestos!$B$6 | D15: =D13/Supuestos!$B$6 | E15: =E13/Supuestos!$B$6 | F15: =F13/Supuestos!$B$6
A17: MODELO 2 — Balance de estaciones (criterio de planificación)
A18: Restricción activa = la estación que menos piezas habilita. Comprar fuera de la restricción no aumenta la producción.
A19: Concepto | B19: Actual | C19: A | D19: B | E19: C | F19: D
A20: Piezas/día que habilita Overlock | B20: =B5/$G$5 | C20: =C5/$G$5 | D20: =D5/$G$5 | E20: =E5/$G$5 | F20: =F5/$G$5
A21: Piezas/día que habilita Collaret Cuello | B21: =B6/$G$6 | C21: =C6/$G$6 | D21: =D6/$G$6 | E21: =E6/$G$6 | F21: =F6/$G$6
A22: Piezas/día que habilita Collaret Ruedo | B22: =B7/$G$7 | C22: =C7/$G$7 | D22: =D7/$G$7 | E22: =E7/$G$7 | F22: =F7/$G$7
A23: PIEZAS/DÍA (restricción activa) | B23: =MIN(B20:B22) | C23: =MIN(C20:C22) | D23: =MIN(D20:D22) | E23: =MIN(E20:E22) | F23: =MIN(F20:F22)
A24: Restricción activa | B24: =INDEX({"Overlock";"Collaret Cuello";"Collaret Ruedo"},MATCH(B23,B20:B22,0)) | C24: =INDEX({"Overlock";"Collaret Cuello";"Collaret Ruedo"},MATCH(C23,C20:C22,0)) | D24: =INDEX({"Overlock";"Collaret Cuello";"Collaret Ruedo"},MATCH(D23,D20:D22,0)) | E24: =INDEX({"Overlock";"Collaret Cuello";"Collaret Ruedo"},MATCH(E23,E20:E22,0)) | F24: =INDEX({"Overlock";"Collaret Cuello";"Collaret Ruedo"},MATCH(F23,F20:F22,0))
A25: PIEZAS/MES bruto | B25: =B23*Supuestos!$B$5 | C25: =C23*Supuestos!$B$5 | D25: =D23*Supuestos!$B$5 | E25: =E23*Supuestos!$B$5 | F25: =F23*Supuestos!$B$5
A26: PIEZAS/MES netas de reproceso | B26: =B23*Supuestos!$B$5*(1-Supuestos!$B$8) | C26: =C23*Supuestos!$B$5*(1-Supuestos!$B$9) | D26: =D23*Supuestos!$B$5*(1-Supuestos!$B$10) | E26: =E23*Supuestos!$B$5*(1-Supuestos!$B$11) | F26: =F23*Supuestos!$B$5*(1-Supuestos!$B$12)

Sheet Demanda y Deficit
A1: Demanda y déficit por escenario
A2: Capacidad comparada = Modelo 2 (balance de estaciones), piezas/mes netas de reproceso
A4: Escenario de demanda | B4: Piezas/mes (con SS) | C4: Actual | D4: A | E4: B | F4: C | G4: D
A5: 1. Mes regular | B5: =Supuestos!$B$15*(1+Supuestos!$B$7) | C5: =Capacidad!B$26-$B5 | D5: =Capacidad!C$26-$B5 | E5: =Capacidad!D$26-$B5 | F5: =Capacidad!E$26-$B5 | G5: =Capacidad!F$26-$B5
A6: 2. Diciembre como mes aislado | B6: =Supuestos!$B$16*(1+Supuestos!$B$7) | C6: =Capacidad!B$26-$B6 | D6: =Capacidad!C$26-$B6 | E6: =Capacidad!D$26-$B6 | F6: =Capacidad!E$26-$B6 | G6: =Capacidad!F$26-$B6
A7: 3. Zafra Oct-Dic (promedio mensual) | B7: =(Supuestos!$B$15*2+Supuestos!$B$16)*(1+Supuestos!$B$7)/3 | C7: =Capacidad!B$26-$B7 | D7: =Capacidad!C$26-$B7 | E7: =Capacidad!D$26-$B7 | F7: =Capacidad!E$26-$B7 | G7: =Capacidad!F$26-$B7
A8: 4. Zafra + 1 tienda nueva (fin 2026) | B8: =((Supuestos!$B$15*2+Supuestos!$B$16)*(1+Supuestos!$B$19/Supuestos!$B$18)+Supuestos!$B$17*Supuestos!$B$19)*(1+Supuestos!$B$7)/3 | C8: =Capacidad!B$26-$B8 | D8: =Capacidad!C$26-$B8 | E8: =Capacidad!D$26-$B8 | F8: =Capacidad!E$26-$B8 | G8: =Capacidad!F$26-$B8
A9: 5. Mes regular 2027 (red completa) | B9: =Supuestos!$B$15*((Supuestos!$B$18+Supuestos!$B$19+Supuestos!$B$20)/Supuestos!$B$18)*(1+Supuestos!$B$7) | C9: =Capacidad!B$26-$B9 | D9: =Capacidad!C$26-$B9 | E9: =Capacidad!D$26-$B9 | F9: =Capacidad!E$26-$B9 | G9: =Capacidad!F$26-$B9
A10: 6. Zafra 2027 + 3 tiendas | B10: =((Supuestos!$B$15*2+Supuestos!$B$16)*((Supuestos!$B$18+Supuestos!$B$19+Supuestos!$B$20)/Supuestos!$B$18)+Supuestos!$B$17*Supuestos!$B$20)*(1+Supuestos!$B$7)/3 | C10: =Capacidad!B$26-$B10 | D10: =Capacidad!C$26-$B10 | E10: =Capacidad!D$26-$B10 | F10: =Capacidad!E$26-$B10 | G10: =Capacidad!F$26-$B10
A12: Capacidad de referencia (piezas/mes) | C12: =Capacidad!B26 | D12: =Capacidad!C26 | E12: =Capacidad!D26 | F12: =Capacidad!E26 | G12: =Capacidad!F26
A14: Positivo = superávit · Negativo (rojo) = déficit de piezas por mes

Sheet Inversion
A1: Lista de compra por escenario
A2: Precios: presupuesto La Máquina 2005 (JACK), 23-abr-2026 — revalidar antes de la orden
A3: Precio unit. US$ | B3: 3000 | C3: 1900 | D3: 1400
A4: Escenario | B4: K7-35AC ruedo | C4: W5E/ULT cuello | D4: C7-4 overlock | E4: US$ ruedo | F4: US$ cuello | G4: US$ overlock | H4: TOTAL US$
A5: A | B5: 3 | C5: 0 | D5: 1 | E5: =B5*B$3 | F5: =C5*C$3 | G5: =D5*D$3 | H5: =SUM(E5:G5)
A6: B | B6: 6 | C6: 0 | D6: 3 | E6: =B6*B$3 | F6: =C6*C$3 | G6: =D6*D$3 | H6: =SUM(E6:G6)
A7: C | B7: 7 | C7: 0 | D7: 3 | E7: =B7*B$3 | F7: =C7*C$3 | G7: =D7*D$3 | H7: =SUM(E7:G7)
A8: D | B8: 9 | C8: 1 | D8: 5 | E8: =B8*B$3 | F8: =C8*C$3 | G8: =D8*D$3 | H8: =SUM(E8:G8)
A10: Costo incremental frente al escenario anterior
A11: A vs hoy | B11: =H5
A12: B vs A | B12: =H6-H5
A13: C vs B | B13: =H7-H6
A14: D vs C | B14: =H8-H7
A16: El escenario D no incluye el costo de la dotación de personal de la línea nueva. B, C y D incluyen los 2 overlock de apoyo además del overlock de reposición de L2.

Sheet Cambio v3 a v4
A1: Qué cambió de la v3 a la v4
A2: Los 2 overlock de los escenarios B, C y D pasan de reemplazo en L1 y L2 a máquinas de apoyo (posición nueva en cada línea). Capacidad comparada = Modelo 2, balance de estaciones.
A4: Concepto | B4: v3 — reemplazo | C4: v4 — de apoyo | D4: Diferencia | E4: Por qué
A5: ESCENARIO B
A6: Overlock — capacidad neta (ops/día) | B6: 1543.6 | C6: =Capacidad!D5 | D6: =C6-B6 | E6: Las 2 máquinas de apoyo suman posición nueva en vez de mejorar una existente
A7: Piezas/día (restricción activa) | B7: 220.51429 | C7: =Capacidad!D23 | D7: =C7-B7 | E7: Overlock es la restricción activa: al ampliarla sube la producción
A8: Piezas/mes netas de reproceso | B8: 4233.8743 | C8: =Capacidad!D26 | D8: =C8-B8 | E8: 20 días laborables, netas de reproceso
A9: Déficit / superávit — mes regular | B9: -325.62571 | C9: ='Demanda y Deficit'!E5 | D9: =C9-B9 | E9: Contra 4.559 pzas/mes con stock de seguridad
A10: Máquinas a comprar | B10: 8 | C10: =Escenarios!D6 | D10: =C10-B10 | E10: Un overlock más: 3 en total (1 de reposición en L2 + 2 de apoyo) en vez de 2
A11: Inversión US$ | B11: 20800 | C11: =Inversion!H6 | D11: =C11-B11 | E11: El overlock adicional cuesta US$ 1.400
A13: ESCENARIO C
A14: Overlock — capacidad neta (ops/día) | B14: 1582.4 | C14: =Capacidad!E5 | D14: =C14-B14 | E14: Las 2 máquinas de apoyo suman posición nueva en vez de mejorar una existente
A15: Piezas/día (restricción activa) | B15: 226.05714 | C15: =Capacidad!E23 | D15: =C15-B15 | E15: Overlock es la restricción activa: al ampliarla sube la producción
A16: Piezas/mes netas de reproceso | B16: 4340.2971 | C16: =Capacidad!E26 | D16: =C16-B16 | E16: 20 días laborables, netas de reproceso
A17: Déficit / superávit — mes regular | B17: -219.20286 | C17: ='Demanda y Deficit'!F5 | D17: =C17-B17 | E17: Contra 4.559 pzas/mes con stock de seguridad
A18: Máquinas a comprar | B18: 9 | C18: =Escenarios!D7 | D18: =C18-B18 | E18: Un overlock más: 3 en total (1 de reposición en L2 + 2 de apoyo) en vez de 2
A19: Inversión US$ | B19: 23800 | C19: =Inversion!H7 | D19: =C19-B19 | E19: El overlock adicional cuesta US$ 1.400
A21: ESCENARIO D
A22: Overlock — capacidad neta (ops/día) | B22: 2001.44 | C22: =Capacidad!F5 | D22: =C22-B22 | E22: Las 2 máquinas de apoyo suman posición nueva en vez de mejorar una existente
A23: Piezas/día (restricción activa) | B23: 285.92 | C23: =Capacidad!F23 | D23: =C23-B23 | E23: Overlock es la restricción activa: al ampliarla sube la producción
A24: Piezas/mes netas de reproceso | B24: 5518.256 | C24: =Capacidad!F26 | D24: =C24-B24 | E24: 20 días laborables, netas de reproceso
A25: Déficit / superávit — mes regular | B25: 958.756 | C25: ='Demanda y Deficit'!G5 | D25: =C25-B25 | E25: Contra 4.559 pzas/mes con stock de seguridad
A26: Máquinas a comprar | B26: 14 | C26: =Escenarios!D8 | D26: =C26-B26 | E26: Un overlock más: 3 en total (1 de reposición en L2 + 2 de apoyo) en vez de 2
A27: Inversión US$ | B27: 34500 | C27: =Inversion!H8 | D27: =C27-B27 | E27: El overlock adicional cuesta US$ 1.400
A29: El escenario A no cambia: sigue siendo reposición estricta de las 4 máquinas averiadas, US$ 10.400.
A30: La estructura de L1 y L2 en B, C y D queda con 6 posiciones: 2 overlock de línea + 1 overlock de apoyo + 1 collaret de cuello + 2 collaret de ruedo.
